Workbook
Name _polarion_4: OFFSET(_polarion_options_start,MATCH(CONCATENATE(_polarion_type,":","PRD-Section"),_polarion_options_types,0),1,COUNTIF(_polarion_options_types,CONCATENATE(_polarion_type,":","PRD-Section")),1)
Name _polarion_info: #REF!
Name _polarion_info: #REF!
Name _polarion_info: #REF!
Name _polarion_info: #REF!
Name _polarion_info: #REF!
Name _polarion_options_start: [1]!_polarion_options[[#Headers],[Type]]
Name _polarion_options_types: [1]!_polarion_options[Type]
Name _polarion_project: IF(ISBLANK('Bypass - Architecture'!_polarion_info),"PrimaryProtectionSystem",LEFT('Bypass - Architecture'!_polarion_info,SEARCH("/",'Bypass - Architecture'!_polarion_info,1)-1))
Name _polarion_project: IF(ISBLANK('MVAr - Architecture'!_polarion_info),"PrimaryProtectionSystem",LEFT('MVAr - Architecture'!_polarion_info,SEARCH("/",'MVAr - Architecture'!_polarion_info,1)-1))
Name _polarion_project: IF(ISBLANK('Scores '!_polarion_info),"PrimaryProtectionSystem",LEFT('Scores '!_polarion_info,SEARCH("/",'Scores '!_polarion_info,1)-1))
Name _polarion_project: IF(ISBLANK(Title!_polarion_info),"PrimaryProtectionSystem",LEFT(Title!_polarion_info,SEARCH("/",Title!_polarion_info,1)-1))
Name _polarion_project: IF(ISBLANK(_polarion_info),"PrimaryProtectionSystem",LEFT(_polarion_info,SEARCH("/",_polarion_info,1)-1))
Name _polarion_type: CONCATENATE('Bypass - Architecture'!_polarion_project,"/",IF(ISBLANK(#REF!),"requirement",#REF!))
Name _polarion_type: CONCATENATE('MVAr - Architecture'!_polarion_project,"/",IF(ISBLANK(#REF!),"requirement",#REF!))
Name _polarion_type: CONCATENATE('Scores '!_polarion_project,"/",IF(ISBLANK(#REF!),"requirement",#REF!))
Name _polarion_type: CONCATENATE(Title!_polarion_project,"/",IF(ISBLANK(#REF!),"requirement",#REF!))
Name _polarion_type: CONCATENATE(_polarion_project,"/",IF(ISBLANK(#REF!),"requirement",#REF!))
Name a: OFFSET(_polarion_options_start,MATCH(CONCATENATE(_polarion_type,":","PRD-Section"),_polarion_options_types,0),1,COUNTIF(_polarion_options_types,CONCATENATE(_polarion_type,":","PRD-Section")),1)
Name abc: #N/A
Name abc: OFFSET(_polarion_options_start,MATCH(CONCATENATE(_polarion_type,":","PRD-Section"),_polarion_options_types,0),1,COUNTIF(_polarion_options_types,CONCATENATE(_polarion_type,":","PRD-Section")),1)
Name ValidPPDPhase: #REF!
Name ValidPPDPhase: #REF!
Name ValidPPDPhase: #REF!
Name ValidPPDPhase: #REF!

Sheet Title
B3: Title: | C3: SmartValve 10-1800 v1.04 - iiSC Board Rev5 (P111191) Potential Failure Mode and Effects Analysis (Design FMECA)
B4: Project: | C4: SmartValve v1.04
B6: PS19 QPI | C6: PS19 Technical Experts | D6: Smart Wires Reviewer
B7: Saad Ullah, Waqas, Jawad | C7: Zain, Imran Mirza, Imad khan | D7: Austin

Sheet Revision History
B2: Revision History
B3: Date | C3: Version | D3: Description
B4: 44188 | C4: 1 | D4: Initial draft based on Rev1 schematic.
B6: 44253 | C6: 1.1 | D6: Updated FMECA based on the Rev1 schematic done by PS19 QPI team.
B7: 44592 | C7: 1.2 | D7: Updated FMECA based on the Rev3 schematic done by PS19 QPI team.
B8: 44600 | C8: 1.3 | D8: Updated FMECA based on the Rev4 schematic done by PS19 QPI team.
B9: 44676 | C9: 1.4 | D9: Reviewed and updated by PS19 Hardware team for the changes done based on the Rev3 schematic
B10: 44694 | C10: 1.5 | D10: Updated the FMECA based on the feedback received from PS19 Hardware team for the improvements by PS19 QPI team.
B11: 44764 | C11: 1.6 | D11: Reviewed and updated by PS19 Hardware team for the changes done based on the Rev4 schematic
B12: 44785 | C12: 1.7 | D12: Updated the FMECA based on the feedback received from PS19 Hardware team for the improvements by PS19 QPI team.
B13: 44792 | C13: 1.8 | D13: Updated FMECA based on the Rev5 schematic done by PS19 QPI team.
B14: 44806 | C14: 1.9 | D14: Reviewed and updated by PS19 Hardware team for the changes done based on the Rev5 schematic
B15: 44812 | C15: 2 | D15: Updated the FMECA based on the feedback received from PS19 Hardware team for the improvements by PS19 QPI team.
B16: 44839 | C16: 2.1 | D16: Reviewed and updated by PS19 Hardware team for improvement based on the Rev5 schematic
... B22: 45104 | C22: 2.7 | D22: Updated the FMECA based on the feedback received from Hardware team for improvement by PS19 QPI Team.

Sheet Definitions-Terms
B2: Definitions / Terms / Acronyms
B3: Term | C3: Description | D3: Term | E3: Description
B4: A-K | C4: Anode-to-Cathode | D4: LCB | E4: Liquid Cooling Block
B5: BF | C5: Bypass Filter | D5: PHT | E5: Power Harvesting Transformer
B6: CTP | C6: Current Transformer for Power | D6: ETP | E6: Electrical Test Procedure
B7: DCCT | C7: DC current transducer | D7: IP | E7: Intrusion Protection
B8: DCE | C8: Digital Computational Engine | D8: MES | E8: Manufacturing Execution System
B9: EFT | C9: Electrical Fast Transient | D9: CTQ | E9: Critical To Quality
B10: EMS | C10: Energy Management System | D10: CLB | E10: Convertor Level ByPass
B11: EOL | C11: End Of Line
B12: FCS | C12: Fault Current Sensor
B13: FO | C13: Fiber Optic
B14: FR | C14: Flame Retardant
B15: G-K | C15: Gate-to-Cathode
B16: HALT | C16: Highly-Accelerated Life Testing
B17: HASS | C17: High accelerated stress screening
B18: HCT | C18: High Current Testing
B19: LCB | C19: Liquid Cooling Block
B20: LCS | C20: Line Current Sensor
B21: OVP | C21: Over-Voltage Protection
B22: PCB | C22: Printed Circuit Board
... B37: TBR | C37: To be Reviewed

Sheet Design Tracebility
B2: Design Traceability
B3: Sr. | C3: Design Artifact | D3: Rev | E3: Link
B5: 1 | C5: SmartValve 10-1800 v1.04 - Wiring Drawing - Bypass, MVAr Section Harnesses Diagram, PHT Shorting and Capacitor Voltage Measurement Blocks | D5: 4 | E5: Box Link
B6: 2 | C6: SmartValve 10-1800 v1.04 - Wiring Drawing - Power Supply Scheme Gen2-v2-FAI | D6: v2 | E6: Box Link
B7: 3 | C7: SmartValve 10-1800 v1.04 - PCBAs - iiSC Board Schematic | D7: 5 | E7: Box Link
B8: 4 | C8: SmartValve 10-1800 v1.04 - PCBAs - iiSC Board Functional Block Diagram | D8: 5 | E8: Box Link
B9: 5 | C9: SmartValve 10-1800 v1.04 - PCBAs - iiSC Board Design Document | D9: A | E9: Box Link

Sheet Scores 
D2: Risk Factor (S x O) Scores | L2: SmartValve v1.04 Risk Factor (S x O) Counts
B4: Occurrence | C4: 5 | D4: =$C$4*D9 -> 5 | E4: =$C$4*E9 -> 10 | F4: =$C$4*F9 -> 15 | G4: =$C$4*G9 -> 20 | H4: =$C$4*H9 -> 25 | K4: Occurrence | L4: 5 | M4: {=SUMPRODUCT(--(DFMECA!J6:J2194=1),--(DFMECA!M6:M2194=5))} -> 0 | N4: {=SUMPRODUCT(--(DFMECA!J6:J2194=2),--(DFMECA!M6:M2194=5))} -> 0 | O4: {=SUMPRODUCT(--(DFMECA!J6:J2194=3),--(DFMECA!M6:M2194=5))} -> 0 | P4: {=SUMPRODUCT(--(DFMECA!J6:J2194=4),--(DFMECA!M6:M2194=5))} -> 0 | Q4: {=SUMPRODUCT(--(DFMECA!J6:J2194=5),--(DFMECA!M6:M2194=5))} -> 0
C5: 4 | D5: =$C$5*D9 -> 4 | E5: =$C$5*E9 -> 8 | F5: =$C$5*F9 -> 12 | G5: =$C$5*G9 -> 16 | H5: =$C$5*H9 -> 20 | L5: 4 | M5: {=SUMPRODUCT(--(DFMECA!J6:J2194=1),--(DFMECA!M6:M2194=4))} -> 0 | N5: {=SUMPRODUCT(--(DFMECA!J6:J2194=2),--(DFMECA!M6:M2194=4))} -> 0 | O5: {=SUMPRODUCT(--(DFMECA!J6:J2194=3),--(DFMECA!M6:M2194=4))} -> 0 | P5: {=SUMPRODUCT(--(DFMECA!J6:J2194=4),--(DFMECA!M6:M2194=4))} -> 0 | Q5: {=SUMPRODUCT(--(DFMECA!J6:J2194=5),--(DFMECA!M6:M2194=4))} -> 0
C6: 3 | D6: =$C$6*D9 -> 3 | E6: =$C$6*E9 -> 6 | F6: =$C$6*F9 -> 9 | G6: =$C$6*G9 -> 12 | H6: =$C$6*H9 -> 15 | L6: 3 | M6: {=SUMPRODUCT(--(DFMECA!J6:J2194=1),--(DFMECA!M6:M2194=3))} -> 0 | N6: {=SUMPRODUCT(--(DFMECA!J6:J2194=2),--(DFMECA!M6:M2194=3))} -> 3 | O6: {=SUMPRODUCT(--(DFMECA!J6:J2194=3),--(DFMECA!M6:M2194=3))} -> 4 | P6: {=SUMPRODUCT(--(DFMECA!J6:J2194=4),--(DFMECA!M6:M2194=3))} -> 0 | Q6: {=SUMPRODUCT(--(DFMECA!J6:J2194=5),--(DFMECA!M6:M2194=3))} -> 0
C7: 2 | D7: =$C$7*D9 -> 2 | E7: =$C$7*E9 -> 4 | F7: =$C$7*F9 -> 6 | G7: =$C$7*G9 -> 8 | H7: =$C$7*H9 -> 10 | L7: 2 | M7: {=SUMPRODUCT(--(DFMECA!J6:J2194=1),--(DFMECA!M6:M2194=2))} -> 129 | N7: {=SUMPRODUCT(--(DFMECA!J6:J2194=2),--(DFMECA!M6:M2194=2))} -> 79 | O7: {=SUMPRODUCT(--(DFMECA!J6:J2194=3),--(DFMECA!M6:M2194=2))} -> 295 | P7: {=SUMPRODUCT(--(DFMECA!J6:J2194=4),--(DFMECA!M6:M2194=2))} -> 8 | Q7: {=SUMPRODUCT(--(DFMECA!J6:J2194=5),--(DFMECA!M6:M2194=2))} -> 0
C8: 1 | D8: =$C$8*D9 -> 1 | E8: =$C$8*E9 -> 2 | F8: =$C$8*F9 -> 3 | G8: =$C$8*G9 -> 4 | H8: =$C$8*H9 -> 5 | L8: 1 | M8: {=SUMPRODUCT(--(DFMECA!J6:J2194=1),--(DFMECA!M6:M2194=1))} -> 861 | N8: {=SUMPRODUCT(--(DFMECA!J6:J2194=2),--(DFMECA!M6:M2194=1))} -> 238 | O8: {=SUMPRODUCT(--(DFMECA!J6:J2194=3),--(DFMECA!M6:M2194=1))} -> 518 | P8: {=SUMPRODUCT(--(DFMECA!J6:J2194=4),--(DFMECA!M6:M2194=1))} -> 5 | Q8: {=SUMPRODUCT(--(DFMECA!J6:J2194=5),--(DFMECA!M6:M2194=1))} -> 0
D9: 1 | E9: 2 | F9: 3 | G9: 4 | H9: 5 | M9: 1 | N9: 2 | O9: 3 | P9: 4 | Q9: 5
D10: Severity | M10: Severity
M12: Total risks: | Q12: =SUM(M4:M8)+SUM(N4:N8)+SUM(O4:O8)+SUM(P4:P8)+SUM(Q4:Q8) -> 2140
M13: Total risks require mitigation based on S x O: | Q13: =SUM(N4:N5)+SUM(O4:O6)+SUM(P4:P7)+SUM(Q4:Q8) -> 12
C17: Risk Priority Number (S x O x D) Scores | L17: SmartValve v1.04 RPN (S x O x D) Counts
B19: Severity x Occurrence (S x O) | C19: 25 | D19: =C19*$D$44 -> 25 | E19: =C19*$E$44 -> 50 | F19: =C19*$F$44 -> 75 | G19: =C19*$G$44 -> 100 | H19: =C19*$H$44 -> 125 | K19: Severity x Occurrence (S x O) | L19: 25 | M19: {=SUMPRODUCT(--(DFMECA!N6:N2194=25),--(DFMECA!Q6:Q2194=1))} -> 0 | N19: {=SUMPRODUCT(--(DFMECA!N6:N2194=25),--(DFMECA!Q6:Q2194=2))} -> 0 | O19: {=SUMPRODUCT(--(DFMECA!N6:N2194=25),--(DFMECA!Q6:Q2194=3))} -> 0 | P19: {=SUMPRODUCT(--(DFMECA!N6:N2194=25),--(DFMECA!Q6:Q2194=4))} -> 0 | Q19: {=SUMPRODUCT(--(DFMECA!N6:N2194=25),--(DFMECA!Q6:Q2194=5))} -> 0
C20: 24 | D20: =C20*$D$44 -> 24 | E20: =C20*$E$44 -> 48 | F20: =C20*$F$44 -> 72 | G20: =C20*$G$44 -> 96 | H20: =C20*$H$44 -> 120 | L20: 24 | M20: {=SUMPRODUCT(--(DFMECA!N6:N2194=24),--(DFMECA!Q6:Q2194=1))} -> 0 | N20: {=SUMPRODUCT(--(DFMECA!N6:N2194=24),--(DFMECA!Q6:Q2194=2))} -> 0 | O20: {=SUMPRODUCT(--(DFMECA!N6:N2194=24),--(DFMECA!Q6:Q2194=3))} -> 0 | P20: {=SUMPRODUCT(--(DFMECA!N6:N2194=24),--(DFMECA!Q6:Q2194=4))} -> 0 | Q20: {=SUMPRODUCT(--(DFMECA!N6:N2194=24),--(DFMECA!Q6:Q2194=5))} -> 0
C21: 23 | D21: =C21*$D$44 -> 23 | E21: =C21*$E$44 -> 46 | F21: =C21*$F$44 -> 69 | G21: =C21*$G$44 -> 92 | H21: =C21*$H$44 -> 115 | L21: 23 | M21: {=SUMPRODUCT(--(DFMECA!N6:N2194=23),--(DFMECA!Q6:Q2194=1))} -> 0 | N21: {=SUMPRODUCT(--(DFMECA!N6:N2194=23),--(DFMECA!Q6:Q2194=2))} -> 0 | O21: {=SUMPRODUCT(--(DFMECA!N6:N2194=23),--(DFMECA!Q6:Q2194=3))} -> 0 | P21: {=SUMPRODUCT(--(DFMECA!N6:N2194=23),--(DFMECA!Q6:Q2194=4))} -> 0 | Q21: {=SUMPRODUCT(--(DFMECA!N6:N2194=23),--(DFMECA!Q6:Q2194=5))} -> 0
C22: 22 | D22: =C22*$D$44 -> 22 | E22: =C22*$E$44 -> 44 | F22: =C22*$F$44 -> 66 | G22: =C22*$G$44 -> 88 | H22: =C22*$H$44 -> 110 | L22: 22 | M22: {=SUMPRODUCT(--(DFMECA!N6:N2194=22),--(DFMECA!Q6:Q2194=1))} -> 0 | N22: {=SUMPRODUCT(--(DFMECA!N6:N2194=22),--(DFMECA!Q6:Q2194=2))} -> 0 | O22: {=SUMPRODUCT(--(DFMECA!N6:N2194=22),--(DFMECA!Q6:Q2194=3))} -> 0 | P22: {=SUMPRODUCT(--(DFMECA!N6:N2194=22),--(DFMECA!Q6:Q2194=4))} -> 0 | Q22: {=SUMPRODUCT(--(DFMECA!N6:N2194=22),--(DFMECA!Q6:Q2194=5))} -> 0
C23: 21 | D23: =C23*$D$44 -> 21 | E23: =C23*$E$44 -> 42 | F23: =C23*$F$44 -> 63 | G23: =C23*$G$44 -> 84 | H23: =C23*$H$44 -> 105 | L23: 21 | M23: {=SUMPRODUCT(--(DFMECA!N6:N2194=21),--(DFMECA!Q6:Q2194=1))} -> 0 | N23: {=SUMPRODUCT(--(DFMECA!N6:N2194=21),--(DFMECA!Q6:Q2194=2))} -> 0 | O23: {=SUMPRODUCT(--(DFMECA!N6:N2194=21),--(DFMECA!Q6:Q2194=3))} -> 0 | P23: {=SUMPRODUCT(--(DFMECA!N6:N2194=21),--(DFMECA!Q6:Q2194=4))} -> 0 | Q23: {=SUMPRODUCT(--(DFMECA!N6:N2194=21),--(DFMECA!Q6:Q2194=5))} -> 0
C24: 20 | D24: =C24*$D$44 -> 20 | E24: =C24*$E$44 -> 40 | F24: =C24*$F$44 -> 60 | G24: =C24*$G$44 -> 80 | H24: =C24*$H$44 -> 100 | L24: 20 | M24: {=SUMPRODUCT(--(DFMECA!N6:N2194=20),--(DFMECA!Q6:Q2194=1))} -> 0 | N24: {=SUMPRODUCT(--(DFMECA!N6:N2194=20),--(DFMECA!Q6:Q2194=2))} -> 0 | O24: {=SUMPRODUCT(--(DFMECA!N6:N2194=20),--(DFMECA!Q6:Q2194=3))} -> 0 | P24: {=SUMPRODUCT(--(DFMECA!N6:N2194=20),--(DFMECA!Q6:Q2194=4))} -> 0 | Q24: {=SUMPRODUCT(--(DFMECA!N6:N2194=20),--(DFMECA!Q6:Q2194=5))} -> 0
C25: 19 | D25: =C25*$D$44 -> 19 | E25: =C25*$E$44 -> 38 | F25: =C25*$F$44 -> 57 | G25: =C25*$G$44 -> 76 | H25: =C25*$H$44 -> 95 | L25: 19 | M25: {=SUMPRODUCT(--(DFMECA!N6:N2194=19),--(DFMECA!Q6:Q2194=1))} -> 0 | N25: {=SUMPRODUCT(--(DFMECA!N6:N2194=19),--(DFMECA!Q6:Q2194=2))} -> 0 | O25: {=SUMPRODUCT(--(DFMECA!N6:N2194=19),--(DFMECA!Q6:Q2194=3))} -> 0 | P25: {=SUMPRODUCT(--(DFMECA!N6:N2194=19),--(DFMECA!Q6:Q2194=4))} -> 0 | Q25: {=SUMPRODUCT(--(DFMECA!N6:N2194=19),--(DFMECA!Q6:Q2194=5))} -> 0
C26: 18 | D26: =C26*$D$44 -> 18 | E26: =C26*$E$44 -> 36 | F26: =C26*$F$44 -> 54 | G26: =C26*$G$44 -> 72 | H26: =C26*$H$44 -> 90 | L26: 18 | M26: {=SUMPRODUCT(--(DFMECA!N6:N2194=18),--(DFMECA!Q6:Q2194=1))} -> 0 | N26: {=SUMPRODUCT(--(DFMECA!N6:N2194=18),--(DFMECA!Q6:Q2194=2))} -> 0 | O26: {=SUMPRODUCT(--(DFMECA!N6:N2194=18),--(DFMECA!Q6:Q2194=3))} -> 0 | P26: {=SUMPRODUCT(--(DFMECA!N6:N2194=18),--(DFMECA!Q6:Q2194=4))} -> 0 | Q26: {=SUMPRODUCT(--(DFMECA!N6:N2194=18),--(DFMECA!Q6:Q2194=5))} -> 0
C27: 17 | D27: =C27*$D$44 -> 17 | E27: =C27*$E$44 -> 34 | F27: =C27*$F$44 -> 51 | G27: =C27*$G$44 -> 68 | H27: =C27*$H$44 -> 85 | L27: 17 | M27: {=SUMPRODUCT(--(DFMECA!N6:N2194=17),--(DFMECA!Q6:Q2194=1))} -> 0 | N27: {=SUMPRODUCT(--(DFMECA!N6:N2194=17),--(DFMECA!Q6:Q2194=2))} -> 0 | O27: {=SUMPRODUCT(--(DFMECA!N6:N2194=17),--(DFMECA!Q6:Q2194=3))} -> 0 | P27: {=SUMPRODUCT(--(DFMECA!N6:N2194=17),--(DFMECA!Q6:Q2194=4))} -> 0 | Q27: {=SUMPRODUCT(--(DFMECA!N6:N2194=17),--(DFMECA!Q6:Q2194=5))} -> 0
C28: 16 | D28: =C28*$D$44 -> 16 | E28: =C28*$E$44 -> 32 | F28: =C28*$F$44 -> 48 | G28: =C28*$G$44 -> 64 | H28: =C28*$H$44 -> 80 | L28: 16 | M28: {=SUMPRODUCT(--(DFMECA!N6:N2194=16),--(DFMECA!Q6:Q2194=1))} -> 0 | N28: {=SUMPRODUCT(--(DFMECA!N6:N2194=16),--(DFMECA!Q6:Q2194=2))} -> 0 | O28: {=SUMPRODUCT(--(DFMECA!N6:N2194=16),--(DFMECA!Q6:Q2194=3))} -> 0 | P28: {=SUMPRODUCT(--(DFMECA!N6:N2194=16),--(DFMECA!Q6:Q2194=4))} -> 0 | Q28: {=SUMPRODUCT(--(DFMECA!N6:N2194=16),--(DFMECA!Q6:Q2194=5))} -> 0
C29: 15 | D29: =C29*$D$44 -> 15 | E29: =C29*$E$44 -> 30 | F29: =C29*$F$44 -> 45 | G29: =C29*$G$44 -> 60 | H29: =C29*$H$44 -> 75 | L29: 15 | M29: {=SUMPRODUCT(--(DFMECA!N6:N2194=15),--(DFMECA!Q6:Q2194=1))} -> 0 | N29: {=SUMPRODUCT(--(DFMECA!N6:N2194=15),--(DFMECA!Q6:Q2194=2))} -> 0 | O29: {=SUMPRODUCT(--(DFMECA!N6:N2194=15),--(DFMECA!Q6:Q2194=3))} -> 0 | P29: {=SUMPRODUCT(--(DFMECA!N6:N2194=15),--(DFMECA!Q6:Q2194=4))} -> 0 | Q29: {=SUMPRODUCT(--(DFMECA!N6:N2194=15),--(DFMECA!Q6:Q2194=5))} -> 0
C30: 14 | D30: =C30*$D$44 -> 14 | E30: =C30*$E$44 -> 28 | F30: =C30*$F$44 -> 42 | G30: =C30*$G$44 -> 56 | H30: =C30*$H$44 -> 70 | L30: 14 | M30: {=SUMPRODUCT(--(DFMECA!N6:N2194=14),--(DFMECA!Q6:Q2194=1))} -> 0 | N30: {=SUMPRODUCT(--(DFMECA!N6:N2194=14),--(DFMECA!Q6:Q2194=2))} -> 0 | O30: {=SUMPRODUCT(--(DFMECA!N6:N2194=14),--(DFMECA!Q6:Q2194=3))} -> 0 | P30: {=SUMPRODUCT(--(DFMECA!N6:N2194=14),--(DFMECA!Q6:Q2194=4))} -> 0 | Q30: {=SUMPRODUCT(--(DFMECA!N6:N2194=14),--(DFMECA!Q6:Q2194=5))} -> 0
C31: 13 | D31: =C31*$D$44 -> 13 | E31: =C31*$E$44 -> 26 | F31: =C31*$F$44 -> 39 | G31: =C31*$G$44 -> 52 | H31: =C31*$H$44 -> 65 | L31: 13 | M31: {=SUMPRODUCT(--(DFMECA!N6:N2194=13),--(DFMECA!Q6:Q2194=1))} -> 0 | N31: {=SUMPRODUCT(--(DFMECA!N6:N2194=13),--(DFMECA!Q6:Q2194=2))} -> 0 | O31: {=SUMPRODUCT(--(DFMECA!N6:N2194=13),--(DFMECA!Q6:Q2194=3))} -> 0 | P31: {=SUMPRODUCT(--(DFMECA!N6:N2194=13),--(DFMECA!Q6:Q2194=4))} -> 0 | Q31: {=SUMPRODUCT(--(DFMECA!N6:N2194=13),--(DFMECA!Q6:Q2194=5))} -> 0
C32: 12 | D32: =C32*$D$44 -> 12 | E32: =C32*$E$44 -> 24 | F32: =C32*$F$44 -> 36 | G32: =C32*$G$44 -> 48 | H32: =C32*$H$44 -> 60 | L32: 12 | M32: {=SUMPRODUCT(--(DFMECA!N6:N2194=12),--(DFMECA!Q6:Q2194=1))} -> 0 | N32: {=SUMPRODUCT(--(DFMECA!N6:N2194=12),--(DFMECA!Q6:Q2194=2))} -> 0 | O32: {=SUMPRODUCT(--(DFMECA!N6:N2194=12),--(DFMECA!Q6:Q2194=3))} -> 0 | P32: {=SUMPRODUCT(--(DFMECA!N6:N2194=12),--(DFMECA!Q6:Q2194=4))} -> 0 | Q32: {=SUMPRODUCT(--(DFMECA!N6:N2194=12),--(DFMECA!Q6:Q2194=5))} -> 0
C33: 11 | D33: =C33*$D$44 -> 11 | E33: =C33*$E$44 -> 22 | F33: =C33*$F$44 -> 33 | G33: =C33*$G$44 -> 44 | H33: =C33*$H$44 -> 55 | L33: 11 | M33: {=SUMPRODUCT(--(DFMECA!N6:N2194=11),--(DFMECA!Q6:Q2194=1))} -> 0 | N33: {=SUMPRODUCT(--(DFMECA!N6:N2194=11),--(DFMECA!Q6:Q2194=2))} -> 0 | O33: {=SUMPRODUCT(--(DFMECA!N6:N2194=11),--(DFMECA!Q6:Q2194=3))} -> 0 | P33: {=SUMPRODUCT(--(DFMECA!N6:N2194=11),--(DFMECA!Q6:Q2194=4))} -> 0 | Q33: {=SUMPRODUCT(--(DFMECA!N6:N2194=11),--(DFMECA!Q6:Q2194=5))} -> 0
C34: 10 | D34: =C34*$D$44 -> 10 | E34: =C34*$E$44 -> 20 | F34: =C34*$F$44 -> 30 | G34: =C34*$G$44 -> 40 | H34: =C34*$H$44 -> 50 | L34: 10 | M34: {=SUMPRODUCT(--(DFMECA!N6:N2194=10),--(DFMECA!Q6:Q2194=1))} -> 0 | N34: {=SUMPRODUCT(--(DFMECA!N6:N2194=10),--(DFMECA!Q6:Q2194=2))} -> 0 | O34: {=SUMPRODUCT(--(DFMECA!N6:N2194=10),--(DFMECA!Q6:Q2194=3))} -> 0 | P34: {=SUMPRODUCT(--(DFMECA!N6:N2194=10),--(DFMECA!Q6:Q2194=4))} -> 0 | Q34: {=SUMPRODUCT(--(DFMECA!N6:N2194=10),--(DFMECA!Q6:Q2194=5))} -> 0
C35: 9 | D35: =C35*$D$44 -> 9 | E35: =C35*$E$44 -> 18 | F35: =C35*$F$44 -> 27 | G35: =C35*$G$44 -> 36 | H35: =C35*$H$44 -> 45 | L35: 9 | M35: {=SUMPRODUCT(--(DFMECA!N6:N2194=9),--(DFMECA!Q6:Q2194=1))} -> 0 | N35: {=SUMPRODUCT(--(DFMECA!N6:N2194=9),--(DFMECA!Q6:Q2194=2))} -> 3 | O35: {=SUMPRODUCT(--(DFMECA!N6:N2194=9),--(DFMECA!Q6:Q2194=3))} -> 0 | P35: {=SUMPRODUCT(--(DFMECA!N6:N2194=9),--(DFMECA!Q6:Q2194=4))} -> 0 | Q35: {=SUMPRODUCT(--(DFMECA!N6:N2194=9),--(DFMECA!Q6:Q2194=5))} -> 1
C36: 8 | D36: =C36*$D$44 -> 8 | E36: =C36*$E$44 -> 16 | F36: =C36*$F$44 -> 24 | G36: =C36*$G$44 -> 32 | H36: =C36*$H$44 -> 40 | L36: 8 | M36: {=SUMPRODUCT(--(DFMECA!N6:N2194=8),--(DFMECA!Q6:Q2194=1))} -> 0 | N36: {=SUMPRODUCT(--(DFMECA!N6:N2194=8),--(DFMECA!Q6:Q2194=2))} -> 6 | O36: {=SUMPRODUCT(--(DFMECA!N6:N2194=8),--(DFMECA!Q6:Q2194=3))} -> 0 | P36: {=SUMPRODUCT(--(DFMECA!N6:N2194=8),--(DFMECA!Q6:Q2194=4))} -> 1 | Q36: {=SUMPRODUCT(--(DFMECA!N6:N2194=8),--(DFMECA!Q6:Q2194=5))} -> 1
C37: 7 | D37: =C37*$D$44 -> 7 | E37: =C37*$E$44 -> 14 | F37: =C37*$F$44 -> 21 | G37: =C37*$G$44 -> 28 | H37: =C37*$H$44 -> 35 | L37: 7 | M37: {=SUMPRODUCT(--(DFMECA!N6:N2194=7),--(DFMECA!Q6:Q2194=1))} -> 0 | N37: {=SUMPRODUCT(--(DFMECA!N6:N2194=7),--(DFMECA!Q6:Q2194=2))} -> 0 | O37: {=SUMPRODUCT(--(DFMECA!N6:N2194=7),--(DFMECA!Q6:Q2194=3))} -> 0 | P37: {=SUMPRODUCT(--(DFMECA!N6:N2194=7),--(DFMECA!Q6:Q2194=4))} -> 0 | Q37: {=SUMPRODUCT(--(DFMECA!N6:N2194=7),--(DFMECA!Q6:Q2194=5))} -> 0
C38: 6 | D38: =C38*$D$44 -> 6 | E38: =C38*$E$44 -> 12 | F38: =C38*$F$44 -> 18 | G38: =C38*$G$44 -> 24 | H38: =C38*$H$44 -> 30 | L38: 6 | M38: {=SUMPRODUCT(--(DFMECA!N6:N2194=6),--(DFMECA!Q6:Q2194=1))} -> 0 | N38: {=SUMPRODUCT(--(DFMECA!N6:N2194=6),--(DFMECA!Q6:Q2194=2))} -> 126 | O38: {=SUMPRODUCT(--(DFMECA!N6:N2194=6),--(DFMECA!Q6:Q2194=3))} -> 136 | P38: {=SUMPRODUCT(--(DFMECA!N6:N2194=6),--(DFMECA!Q6:Q2194=4))} -> 0 | Q38: {=SUMPRODUCT(--(DFMECA!N6:N2194=6),--(DFMECA!Q6:Q2194=5))} -> 36
C39: 5 | D39: =C39*$D$44 -> 5 | E39: =C39*$E$44 -> 10 | F39: =C39*$F$44 -> 15 | G39: =C39*$G$44 -> 20 | H39: =C39*$H$44 -> 25 | L39: 5 | M39: {=SUMPRODUCT(--(DFMECA!N6:N2194=5),--(DFMECA!Q6:Q2194=1))} -> 0 | N39: {=SUMPRODUCT(--(DFMECA!N6:N2194=5),--(DFMECA!Q6:Q2194=2))} -> 0 | O39: {=SUMPRODUCT(--(DFMECA!N6:N2194=5),--(DFMECA!Q6:Q2194=3))} -> 0 | P39: {=SUMPRODUCT(--(DFMECA!N6:N2194=5),--(DFMECA!Q6:Q2194=4))} -> 0 | Q39: {=SUMPRODUCT(--(DFMECA!N6:N2194=5),--(DFMECA!Q6:Q2194=5))} -> 0
C40: 4 | D40: =C40*$D$44 -> 4 | E40: =C40*$E$44 -> 8 | F40: =C40*$F$44 -> 12 | G40: =C40*$G$44 -> 16 | H40: =C40*$H$44 -> 20 | L40: 4 | M40: {=SUMPRODUCT(--(DFMECA!N6:N2194=4),--(DFMECA!Q6:Q2194=1))} -> 0 | N40: {=SUMPRODUCT(--(DFMECA!N6:N2194=4),--(DFMECA!Q6:Q2194=2))} -> 24 | O40: {=SUMPRODUCT(--(DFMECA!N6:N2194=4),--(DFMECA!Q6:Q2194=3))} -> 13 | P40: {=SUMPRODUCT(--(DFMECA!N6:N2194=4),--(DFMECA!Q6:Q2194=4))} -> 0 | Q40: {=SUMPRODUCT(--(DFMECA!N6:N2194=4),--(DFMECA!Q6:Q2194=5))} -> 46
C41: 3 | D41: =C41*$D$44 -> 3 | E41: =C41*$E$44 -> 6 | F41: =C41*$F$44 -> 9 | G41: =C41*$G$44 -> 12 | H41: =C41*$H$44 -> 15 | L41: 3 | M41: {=SUMPRODUCT(--(DFMECA!N6:N2194=3),--(DFMECA!Q6:Q2194=1))} -> 2 | N41: {=SUMPRODUCT(--(DFMECA!N6:N2194=3),--(DFMECA!Q6:Q2194=2))} -> 235 | O41: {=SUMPRODUCT(--(DFMECA!N6:N2194=3),--(DFMECA!Q6:Q2194=3))} -> 175 | P41: {=SUMPRODUCT(--(DFMECA!N6:N2194=3),--(DFMECA!Q6:Q2194=4))} -> 0 | Q41: {=SUMPRODUCT(--(DFMECA!N6:N2194=3),--(DFMECA!Q6:Q2194=5))} -> 106
C42: 2 | D42: =C42*$D$44 -> 2 | E42: =C42*$E$44 -> 4 | F42: =C42*$F$44 -> 6 | G42: =C42*$G$44 -> 8 | H42: =C42*$H$44 -> 10 | L42: 2 | M42: {=SUMPRODUCT(--(DFMECA!N6:N2194=2),--(DFMECA!Q6:Q2194=1))} -> 0 | N42: {=SUMPRODUCT(--(DFMECA!N6:N2194=2),--(DFMECA!Q6:Q2194=2))} -> 92 | O42: {=SUMPRODUCT(--(DFMECA!N6:N2194=2),--(DFMECA!Q6:Q2194=3))} -> 34 | P42: {=SUMPRODUCT(--(DFMECA!N6:N2194=2),--(DFMECA!Q6:Q2194=4))} -> 0 | Q42: {=SUMPRODUCT(--(DFMECA!N6:N2194=2),--(DFMECA!Q6:Q2194=5))} -> 240
C43: 1 | D43: =C43*$D$44 -> 1 | E43: =C43*$E$44 -> 2 | F43: =C43*$F$44 -> 3 | G43: =C43*$G$44 -> 4 | H43: =C43*$H$44 -> 5 | L43: 1 | M43: {=SUMPRODUCT(--(DFMECA!N6:N2194=1),--(DFMECA!Q6:Q2194=1))} -> 0 | N43: {=SUMPRODUCT(--(DFMECA!N6:N2194=1),--(DFMECA!Q6:Q2194=2))} -> 131 | O43: {=SUMPRODUCT(--(DFMECA!N6:N2194=1),--(DFMECA!Q6:Q2194=3))} -> 59 | P43: {=SUMPRODUCT(--(DFMECA!N6:N2194=1),--(DFMECA!Q6:Q2194=4))} -> 2 | Q43: {=SUMPRODUCT(--(DFMECA!N6:N2194=1),--(DFMECA!Q6:Q2194=5))} -> 669
D44: 1 | E44: 2 | F44: 3 | G44: 4 | H44: 5 | M44: 1 | N44: 2 | O44: 3 | P44: 4 | Q44: 5
D45: Detection | M45: Detection
L47: Total risks: | Q47: =SUM(M19:M43)+SUM(N19:N43)+SUM(O19:O43)+SUM(P19:P43)+SUM(Q19:Q43) -> 2138
L48: Total risks require mitigation based on S x O x D: | Q48: =N19+SUM(O19:O27)+SUM(P19:P31)+SUM(Q19:Q34) -> 0

Sheet S-O-D Definitions
B2: Severity, or Consequence Evaluation Criteria: Worst Case Evaluation of Failure Mode | G2: Occurrence: Probability of occurrence within the product life based on the design as is exists today
B3: Score | C3: Criteria | D3: Notes | E3: Example | G3: Score | H3: Notes | I3: Probability Description | J3: Probability
B4: 5 | C4: Failure causes death or causes transmission line open circuit, full or partial fault protection compromised. | D4: Extremely hazardous failure, threatening to business continuity. | E4: Fault detection mechanism failure . IGBT shorting the capacitor bank. Power to one or more SCR driver boards discontinued while unit is in injection mode. Mechanical failure causing line to open. | G4: 5 | H4: Very high probability | I4: 1 in 10 or greater | J4: 0.1 ≤ Po
B5: 4 | C5: Failure causes severe injury to personnel requiring hospitalization, severe property damage such as damage to a structure, transmission line damage, major damage to system other than transmission line requiring immediate interruption of line service, loss of control of SmartValve v1.04 when in Injection Mode, device is forced to monitoring mode, with reduced fault protection (i.e. redundancy compromised). | D5: Highly hazardous failure, threatening to business reputation. | E5: iiDCE RF communication loss in injection mode. iiDCE losing control of SCRs. | G5: 4 | H5: High probability | I5: 1 in 100 or greater | J5: 0.01 ≤ Po < 0.1
B6: 3 | C6: Failure causes minor injury to personnel requiring out-patient treatment, moderate property damage not involving a structure, moderate system damage other than transmission line that requires future interruption of line service to repair, loss of control of SmartValve v1.04 when in Monitoring Mode, device is forced to monitoring mode with full fault protection available. | D6: Moderately hazardous failure, threatening to product reputation. | E6: iiDCE RF communication loss in monitoring mode. Any control boards' failure, forcing device to monitoring mode. Mechanical failure causing enclosure temperature to rise, forcing device to stay in monitoring mode. | G6: 3 | H6: Moderate probability | I6: 1 in 1,000 or greater | J6: 0.001 ≤ Po < 0.01
B7: 2 | C7: Failure causes minor property damage, minor system damage other than primary conductor or loss of SmartValve v1.04 such as loss of performance, unit forced into Monitoring Mode, or significant impact on unit life | D7: Minor hazard, minor consequence. | E7: Rise in on-board power losses, impacting components' life, Clamp board feedback not available. | G7: 2 | H7: Low probability | I7: 1 in 10,000 or greater | J7: 0.0001 ≤ Po < 0.001
B8: 1 | C8: Failure causes unscheduled maintenance, no immediate loss of performance. | D8: No hazard. | E8: On-board noise filtration compromised. One of many bolts failure. | G8: 1 | H8: Remote probability | I8: Less than 1 in 10,000 | J8: Po < 0.0001
B10: Detection: Likelihood of failure mode detection by design | I10: Target product life for the purposes of this FMECA is 40 years.
B11: Score | C11: Description | D11: Criteria | E11: Definition
B12: 5 | C12: Very remote probability to absolute uncertainty of detection | D12: Design will not and/or cannot detect the potential cause/mechanism or subsequent failure mode, or the likelihood of detection is very remote. | E12: PD < 0.1 | G12: RPN Conditions | H12: Color
B13: 4 | C13: Very low to remote probability of detection | D13: Design has a very low to remote likelihood of detecting the potential cause/mechanism or subsequent failure mode. | E13: 0.1 ≤ PD < 0.5 | G13: Value ≥ 70
B14: 3 | C14: Moderate to low probability of detection | D14: Design has a moderate to low likelihood of detecting the potential cause/mechanism or subsequent failure mode. | E14: 0.5 ≤ PD < 0.95 | G14: 70 > Value ≥ 60
B15: 2 | C15: High to moderately high probability of detection | D15: Design has a high to moderately high likelihood of detecting the potential cause/mechanism or subsequent failure mode. | E15: 0.95 ≤ PD < 0.995 | G15: 60 > Value ≥ 50
B16: 1 | C16: Almost certain to very high probability of detection | D16: Design has an almost certain chance of detecting the potential cause/mechanism or subsequent failure mode or the likelihood of detection is very high. | E16: 0.995 ≤ PD | G16: Value < 50
C50: Review Status
C51: Approved
C52: Reviewed by QA
C53: Review Pending

Sheet Bypass - Architecture

Sheet MVAr - Architecture

Sheet Functional Block Diagram

Sheet DFMECA
A1: ID. | B1: Component | C1: Reference Designator | D1: Functional Testing. Requirement | E1: Potential Failure Mode | F1: Potential Effect(s) of Failure | J1: Severity Score | K1: Potential Causes / Triggers of Failure | L1: Failure Safeguards | M1: Occurrence Score | N1: S x O | O1: Existing Conditions | R1: RPN (S x O x D) | S1: Telemetry | T1: Alert Message | U1: Alert Code | V1: Recommended Action(s) / Remarks | W1: Reporting Team Member | X1: Target Completion Date | Y1: Action Results | AD1: Status
F2: Local - Effect at the sub assembly or component level | G2: Higher Level - Effect at SmartValve v1.04 | H2: Potential Effect on CLB State | I2: End - Effect at System Level | O2: Verification & Validation Method | P2: Detection Method | Q2: Detection Score | Y2: Actions Taken | Z2: Severity Score | AA2: Occurrence Score | AB2: Detection Score | AC2: New RPN
B3: iiSC Board Rev5 (P111191) | AF3: =VALUE(RIGHT((IF(A3="",0,A3)),5)) -> 0
B4: iiSC Board - Power Supply Section | AF4: =VALUE(RIGHT((IF(A4="",0,A4)),5)) -> 0
B5: EMC Filter - HV_ISO & UPSB Board Interface | AF5: =VALUE(RIGHT((IF(A5="",0,A5)),5)) -> 0
A6: SV104-1749 | B6: Input connectors. | C6: J8, J14 | D6: Input power connector. | E6: Cable breaks for 24 VDC from one of the two input connectors. | F6: Power will be available from the redundant connector. iiSC sensing of "Line Current" and "DC link's Voltages" will be affected. | G6: Device will keep working normally if it is in Injection. If the device is in Monitoring mode, the iiSC will shut down and will be declared offline. | H6: Heartbeat of iiSC board to CLB board will stop. | I6: Affected device and its associated group of devices will keep injecting at 90 % of rated capacity. System will keep working normally with slightly reduced capability. | J6: 3 | K6: Connector issue. Cable failure. | L6: Usage of over-rated components. Using components with industrial grade scale. Choosing components with enough FIT rate to fulfil the product life requirements. | M6: 2 | N6: =J6*M6 -> 6 | O6: Functional Testing. Thermal and Relative Humidity Testing. Condensed Humidity Testing. EFT Testing. Vibration Testing. ATM Testing. MVAr Testing. Pre-Cosure Testing. EOL Testing. | P6: Loss of communication between iiDCE and iiSC. | Q6: 3 | R6: =J6*M6*Q6 -> 18 | AC6: =Z6*AA6*AB6 -> 0 | AD6: Reviewed by QA | AF6: =VALUE(RIGHT((IF(A6="",0,A6)),5)) -> -1749
A7: SV104-1750 | E7: Cables break for 24 VDC from both input connectors. | F7: No power will be available for iiSC._x000D_ _x000D_ iiSC sensing of "Line Current" and "DC link's Voltages" will be affected. | G7: Device will transit to monitoring state. | H7: Heartbeat of iiSC board to CLB board will stop. | I7: Affected device and its associated group of devices will transit to monitoring mode._x000D_ _x000D_ System will keep working with reduced injection capability._x000D_ | J7: 3 | K7: DE soldering issue due to vibration. Degradation of solder joint. Assembly issue. | L7: Usage of over-rated components. Using components with industrial grade scale. Choosing components with enough FIT rate to fulfil the product life requirements. | M7: 1 | N7: =J7*M7 -> 3 | O7: Functional Testing. Thermal and Relative Humidity Testing. Condensed Humidity Testing. EFT Testing. Vibration Testing. ATM Testing. MVAr Testing. Pre-Cosure Testing. EOL Testing. | P7: Loss of communication between iiDCE and iiSC. | Q7: 3 | R7: =J7*M7*Q7 -> 9 | AF7: =VALUE(RIGHT((IF(A7="",0,A7)),5)) -> -1750
A8: SV104-12412 | B8: Ring terminal to ground connector. | C8: J11 | D8: To provide ground the shield on IDC cables. | E8: Harness/connector failure. | F8: Grounding will be affected. | G8: Device will keep working normally. | H8: CLB will have no effect | I8: System will keep working normally. | J8: 1 | K8: Cable breaks or connector disengaged. | L8: None. | M8: 2 | N8: =J8*M8 -> 2 | O8: Functional Testing. Thermal and Relative Humidity Testing. Condensed Humidity Testing. EFT Testing. Vibration Testing. ATM Testing. MVAr Testing. Pre-Cosure Testing. EOL Testing. | P8: None. | Q8: 5 | R8: =J8*M8*Q8 -> 10 | AC8: =Z8*AA8*AB8 -> 0 | AF8: =VALUE(RIGHT((IF(A8="",0,A8)),5)) -> 12412
A9: SV104-12413 | B9: Incoming Supply from HVT - TVS Diode. | C9: D70 | D9: Protection from transients. | E9: TVS diode fails-short. | F9: Input from HV_ISO board RAIL1_A will be shorted to RAIL1B. If in monitoring mode then no power will be available for iiSC board. | G9: Device will keep working normally if it is in Injection. If the device is in Monitoring mode, the iiSC will shut down and will be declared offline. | H9: Heartbeat of iiSC board to CLB board will stop. | I9: Affected device and its associated group of devices will keep injecting at 90 % of rated capacity. System will keep working normally with slightly reduced capability. | J9: 3 | K9: Over voltage. De-gradation of components. | L9: Usage of over-rated components. Using components with industrial grade scale. Choosing components with enough FIT rate to fulfil the product life requirements. | M9: 2 | N9: =J9*M9 -> 6 | O9: Functional Testing. Thermal and Relative Humidity Testing. Condensed Humidity Testing. EFT Testing. Vibration Testing. ATM Testing. MVAr Testing. Pre-Cosure Testing. EOL Testing. | P9: Loss of communication between iiDCE and iiSC. | Q9: 3 | R9: =J9*M9*Q9 -> 18 | AF9: =VALUE(RIGHT((IF(A9="",0,A9)),5)) -> 12413
A10: SV104 - 14650 | F10: Input from HV_ISO board RAIL1_A will be shorted to RAIL1B. If in injection mode , UPSB board will power the iiSC board from 24V supply | G10: Device will keep working normally. | H10: CLB will have no effect | I10: System will keep working normally. | J10: 2 | K10: Over voltage. De-gradation of components. | L10: Usage of over-rated components. Using components with industrial grade scale. Choosing components with enough FIT rate to fulfil the product life requirements. | M10: 2 | N10: =J10*M10 -> 4 | O10: Functional Testing. Thermal and Relative Humidity Testing. Condensed Humidity Testing. EFT Testing. Vibration Testing. ATM Testing. MVAr Testing. Pre-Cosure Testing. EOL Testing. | P10: Loss of communication between iiDCE and iiSC. | Q10: 3 | R10: =J10*M10*Q10 -> 12 | AF10: =VALUE(RIGHT((IF(A10="",0,A10)),5)) -> 14650
A11: SV104-12414 | E11: TVS diode fails-open. | F11: Transient protection will be compromised. No immediate effect will be observed. | G11: Device will keep working normally. | H11: CLB will have no effect | I11: System will keep working normally. | J11: 2 | K11: Over voltage. De-gradation of components. | L11: Usage of over-rated components. Using components with industrial grade scale. Choosing components with enough FIT rate to fulfil the product life requirements. | M11: 2 | N11: =J11*M11 -> 4 | O11: Functional Testing. Thermal and Relative Humidity Testing. Condensed Humidity Testing. EFT Testing. Vibration Testing. ATM Testing. MVAr Testing. Pre-Cosure Testing. EOL Testing. | P11: None. | Q11: 5 | R11: =J11*M11*Q11 -> 20 | AF11: =VALUE(RIGHT((IF(A11="",0,A11)),5)) -> 12414
A12: SV104-12415 | B12: Incoming Supply from UPSB - TVS Diode. | C12: D71 | D12: Protection from transients. | E12: TVS diode fails-short. | F12: Input from UPSB board RAIL1_A will be shorted to RAIL1B. Power will be available from the HV_ISO board. No immediate effect will be observed. | G12: Device will keep working normally. | H12: CLB will have no effect | I12: System will keep working normally. | J12: 2 | K12: Over voltage. De-gradation of components. | L12: Usage of over-rated components. Using components with industrial grade scale. Choosing components with enough FIT rate to fulfil the product life requirements. | M12: 2 | N12: =J12*M12 -> 4 | O12: Functional Testing. Thermal and Relative Humidity Testing. Condensed Humidity Testing. EFT Testing. Vibration Testing. ATM Testing. MVAr Testing. Pre-Cosure Testing. EOL Testing. | P12: None. | Q12: 5 | R12: =J12*M12*Q12 -> 20 | AF12: =VALUE(RIGHT((IF(A12="",0,A12)),5)) -> 12415
A13: SV104-12416 | E13: TVS diode fails-open. | F13: Transient protection will be compromised. No immediate effect will be observed. | G13: Device will keep working normally. | H13: CLB will have no effect | I13: System will keep working normally. | J13: 2 | K13: Over voltage. De-gradation of components. | L13: Usage of over-rated components. Using components with industrial grade scale. Choosing components with enough FIT rate to fulfil the product life requirements. | M13: 2 | N13: =J13*M13 -> 4 | O13: Functional Testing. Thermal and Relative Humidity Testing. Condensed Humidity Testing. EFT Testing. Vibration Testing. ATM Testing. MVAr Testing. Pre-Cosure Testing. EOL Testing. | P13: None. | Q13: 5 | R13: =J13*M13*Q13 -> 20 | AF13: =VALUE(RIGHT((IF(A13="",0,A13)),5)) -> 12416
A14: SV104 - 5905 | B14: Incoming Supply from HVT - On-board LED Indication and resistor. | C14: D66, R553, R554 | D14: To provide on-board LED indication. | E14: Resistor fails-open. | F14: Overall resistance of path will be increased. LED may get slightly dimmer. No immediate effect will be observed. | G14: Device will keep working normally. | H14: CLB will have no effect | I14: System will keep working normally. | J14: 1 | K14: Over voltage. De-gradation of components. | L14: Usage of over-rated components. Using components with industrial grade scale. Choosing components with enough FIT rate to fulfil the product life requirements. | M14: 1 | N14: =J14*M14 -> 1 | O14: Functional Testing. Thermal and Relative Humidity Testing. Condensed Humidity Testing. EFT Testing. Vibration Testing. ATM Testing. MVAr Testing. Pre-Cosure Testing. EOL Testing. | P14: None. | Q14: 5 | R14: =J14*M14*Q14 -> 5 | AF14: =VALUE(RIGHT((IF(A14="",0,A14)),5)) -> 5905
A15: SV104 - 5906 | E15: Resistor fails-short. | F15: Over-current will eventually cause resistor to fail-open. Overall resistance of path will be increased. LED may get slightly dimmer. No immediate effect will be observed. | G15: Device will keep working normally. | H15: CLB will have no effect | I15: System will keep working normally. | J15: 1 | K15: Over voltage. De-gradation of components. | L15: Usage of over-rated components. Using components with industrial grade scale. Choosing components with enough FIT rate to fulfil the product life requirements. | M15: 1 | N15: =J15*M15 -> 1 | O15: Functional Testing. Thermal and Relative Humidity Testing. Condensed Humidity Testing. EFT Testing. Vibration Testing. ATM Testing. MVAr Testing. Pre-Cosure Testing. EOL Testing. | P15: None. | Q15: 5 | R15: =J15*M15*Q15 -> 5 | AF15: =VALUE(RIGHT((IF(A15="",0,A15)),5)) -> 5906
A16: SV104 - 5907 | E16: LED fails-open. | F16: LED will not light-up. No immediate effect will be observed. | G16: Device will keep working normally. | H16: CLB will have no effect | I16: System will keep working normally. | J16: 1 | K16: Over voltage. De-gradation of components. | L16: Usage of over-rated components. Using components with industrial grade scale. Choosing components with enough FIT rate to fulfil the product life requirements. | M16: 1 | N16: =J16*M16 -> 1 | O16: Functional Testing. Thermal and Relative Humidity Testing. Condensed Humidity Testing. EFT Testing. Vibration Testing. ATM Testing. MVAr Testing. Pre-Cosure Testing. EOL Testing. | P16: None. | Q16: 5 | R16: =J16*M16*Q16 -> 5 | AF16: =VALUE(RIGHT((IF(A16="",0,A16)),5)) -> 5907
A17: SV104 - 5908 | E17: LED fails-short. | F17: Over-current will eventually cause LED to fail-open. LED will not light-up. No immediate effect will be observed. | G17: Device will keep working normally. | H17: CLB will have no effect | I17: System will keep working normally. | J17: 1 | K17: Over voltage. De-gradation of components. | L17: Usage of over-rated components. Using components with industrial grade scale. Choosing components with enough FIT rate to fulfil the product life requirements. | M17: 1 | N17: =J17*M17 -> 1 | O17: Functional Testing. Thermal and Relative Humidity Testing. Condensed Humidity Testing. EFT Testing. Vibration Testing. ATM Testing. MVAr Testing. Pre-Cosure Testing. EOL Testing. | P17: None. | Q17: 5 | R17: =N17*Q17 -> 5 | AF17: =VALUE(RIGHT((IF(A17="",0,A17)),5)) -> 5908
A18: SV104-12417 | B18: Incoming Supply from UPSB - On-board LED Indication and resistor. | C18: D67, R555, R556 | D18: To provide on-board LED indication. | E18: Resistor fails-open. | F18: Overall resistance of path will be increased. LED may get slightly dimmer. No immediate effect will be observed. | G18: Device will keep working normally. | H18: CLB will have no effect | I18: System will keep working normally. | J18: 1 | K18: Over voltage. De-gradation of components. | L18: Usage of over-rated components. Using components with industrial grade scale. Choosing components with enough FIT rate to fulfil the product life requirements. | M18: 1 | N18: =J18*M18 -> 1 | O18: Functional Testing. Thermal and Relative Humidity Testing. Condensed Humidity Testing. EFT Testing. Vibration Testing. ATM Testing. MVAr Testing. Pre-Cosure Testing. EOL Testing. | P18: None. | Q18: 5 | R18: =N18*Q18 -> 5 | AF18: =VALUE(RIGHT((IF(A18="",0,A18)),5)) -> 12417
A19: SV104-12418 | E19: Resistor fails-short. | F19: Over-current will eventually cause resistor to fail-open. Overall resistance of path will be increased. LED may get slightly dimmer. No immediate effect will be observed. | G19: Device will keep working normally. | H19: CLB will have no effect | I19: System will keep working normally. | J19: 1 | K19: Over voltage. De-gradation of components. | L19: Usage of over-rated components. Using components with industrial grade scale. Choosing components with enough FIT rate to fulfil the product life requirements. | M19: 1 | N19: =J19*M19 -> 1 | O19: Functional Testing. Thermal and Relative Humidity Testing. Condensed Humidity Testing. EFT Testing. Vibration Testing. ATM Testing. MVAr Testing. Pre-Cosure Testing. EOL Testing. | P19: None. | Q19: 5 | R19: =N19*Q19 -> 5 | AF19: =VALUE(RIGHT((IF(A19="",0,A19)),5)) -> 12418
A20: SV104-12419 | E20: LED fails-open. | F20: LED will not light-up. No immediate effect will be observed. | G20: Device will keep working normally. | H20: CLB will have no effect | I20: System will keep working normally. | J20: 1 | K20: Over voltage. De-gradation of components. | L20: Usage of over-rated components. Using components with industrial grade scale. Choosing components with enough FIT rate to fulfil the product life requirements. | M20: 1 | N20: =J20*M20 -> 1 | O20: Functional Testing. Thermal and Relative Humidity Testing. Condensed Humidity Testing. EFT Testing. Vibration Testing. ATM Testing. MVAr Testing. Pre-Cosure Testing. EOL Testing. | P20: None. | Q20: 5 | R20: =N20*Q20 -> 5 | AF20: =VALUE(RIGHT((IF(A20="",0,A20)),5)) -> 12419
A21: SV104-12420 | E21: LED fails-short. | F21: Over-current will eventually cause LED to fail-open. LED will not light-up. No immediate effect will be observed. | G21: Device will keep working normally. | H21: CLB will have no effect | I21: System will keep working normally. | J21: 1 | K21: Over voltage. De-gradation of components. | L21: Usage of over-rated components. Using components with industrial grade scale. Choosing components with enough FIT rate to fulfil the product life requirements. | M21: 1 | N21: =J21*M21 -> 1 | O21: Functional Testing. Thermal and Relative Humidity Testing. Condensed Humidity Testing. EFT Testing. Vibration Testing. ATM Testing. MVAr Testing. Pre-Cosure Testing. EOL Testing. | P21: None. | Q21: 5 | R21: =N21*Q21 -> 5 | AF21: =VALUE(RIGHT((IF(A21="",0,A21)),5)) -> 12420
A22: SV104-1599 | B22: Common mode choke. (L8, L29) | C22: L8, L29 | D22: To filter noise. | E22: Winding of HV_ISO common mode chokes fails-open when system is in monitoring mode. | F22: 1) if in monitoring mode then no power will be available for iiSC board. | G22: Device will remain in monitoring state and will be unable to move to injection mode. | H22: Heartbeat of iiSC board to CLB board will stop. | I22: Affected device and its associated group of devices will transit to monitoring mode._x000D_ _x000D_ System will keep working with reduced injection capability._x000D_ | J22: 3 | K22: DE soldering issue due to vibration. Degradation of solder joint. Assembly issue. | L22: Usage of over-rated components. Using components with industrial grade scale. Choosing components with enough FIT rate to fulfil the product life requirements. | M22: 2 | N22: =J22*M22 -> 6 | O22: Functional Testing. Thermal and Relative Humidity Testing. Condensed Humidity Testing. EFT Testing. Vibration Testing. ATM Testing. MVAr Testing. Pre-Cosure Testing. EOL Testing. | P22: Loss of communication between iiDCE and iiSC. | Q22: 2 | R22: =J22*M22*Q22 -> 12 | AC22: =Z22*AA22*AB22 -> 0 | AF22: =VALUE(RIGHT((IF(A22="",0,A22)),5)) -> -1599
A23: SV104-11391 | E23: Winding of HV_ISO common mode chokes fails-open when system is in Injection mode. | F23: 2) if in injection mode , UPSB board will power the iiSC board from 24V supply | G23: Device will keep working normally. | H23: CLB will have no effect | I23: System will keep working normally. | J23: 2 | K23: DE soldering issue due to vibration. Degradation of solder joint. Assembly issue. | L23: Redundant input power supply paths. Followed assembly verification process. | M23: 2 | N23: 6 | O23: Functional Testing. Thermal and Relative Humidity Testing. Condensed Humidity Testing. EFT Testing. Vibration Testing. ATM Testing. MVAr Testing. Pre-Cosure Testing. EOL Testing. | P23: None. | Q23: 5 | R23: =Q23*N23 -> 30 | AF23: =VALUE(RIGHT((IF(A23="",0,A23)),5)) -> 11391
A24: SV104-11392 | E24: Winding of UPSB common mode choke fails open | F24: Power will be available from the redundant supply path in both monitoring mode and injection mode. No immediate effect at iiSC, but it will lose redundant input power supply. | G24: Device will keep working normally. | H24: CLB will have no effect | I24: System will keep working normally. | J24: 2 | K24: DE soldering issue due to vibration. Degradation of solder joint. Assembly issue. | L24: Redundant input power supply paths. Followed assembly verification process. | M24: 1 | N24: 6 | O24: Functional Testing. Thermal and Relative Humidity Testing. Condensed Humidity Testing. EFT Testing. Vibration Testing. ATM Testing. MVAr Testing. Pre-Cosure Testing. EOL Testing. | P24: None. | Q24: 5 | R24: =Q24*N24 -> 30 | AF24: =VALUE(RIGHT((IF(A24="",0,A24)),5)) -> 11392
A25: SV104-1600 | E25: Winding of both of common mode chokes fail-open. | F25: No power will be available for iiSC._x000D_ _x000D_ All iiGD boards will switch to safe state. | G25: Device will transit to monitoring state. | H25: Heartbeat of iiSC board to CLB board will stop. | I25: Affected device and its associated group of devices will transit to monitoring mode._x000D_ _x000D_ System will keep working with reduced injection capability._x000D_ | J25: 3 | K25: DE soldering issue due to vibration. Degradation of solder joint. Assembly issue. | L25: Usage of over-rated components. Using components with industrial grade scale. Choosing components with enough FIT rate to fulfil the product life requirements. | M25: 1 | N25: =J25*M25 -> 3 | O25: Functional Testing. Thermal and Relative Humidity Testing. Condensed Humidity Testing. EFT Testing. Vibration Testing. ATM Testing. MVAr Testing. Pre-Cosure Testing. EOL Testing. | P25: Loss of communication between iiDCE and iiSC. | Q25: 3 | R25: =J25*M25*Q25 -> 9 | AC25: =Z25*AA25*AB25 -> 0 | AF25: =VALUE(RIGHT((IF(A25="",0,A25)),5)) -> -1600
A26: SV104-1601 | E26: Winding of common mode choke of supply from HV_ISO board fails-short. | F26: Supply from HV_ISO board will be shorted. No power will be available for iiSC in monitoring mode. All iiGD boards will switch to off safe state. | G26: Device will transit to monitoring state. | H26: Heartbeat of iiSC board to CLB board will stop. | I26: Affected device and its associated group of devices will transit to monitoring mode._x000D_ _x000D_ System will keep working with reduced injection capability._x000D_ | J26: 3 | K26: Degradation of winding insulation. Degradation of solder joint. | L26: Usage of over-rated components. Using components with industrial grade scale. Choosing components with enough FIT rate to fulfil the product life requirements. | M26: 2 | N26: =J26*M26 -> 6 | O26: Functional Testing. Thermal and Relative Humidity Testing. Condensed Humidity Testing. EFT Testing. Vibration Testing. ATM Testing. MVAr Testing. Pre-Cosure Testing. EOL Testing. | P26: Loss of communication between iiDCE and iiSC. | Q26: 3 | R26: =J26*M26*Q26 -> 18 | V26: Input required from Power team. | AC26: =Z26*AA26*AB26 -> 0 | AF26: =VALUE(RIGHT((IF(A26="",0,A26)),5)) -> -1601
A27: SV104-9818 | E27: Winding of common mode choke of supply from UPSB board fails-short. | F27: Supply from UPSB board will be shorted. No redundant power will be available for iiSC in injection mode. | G27: Device will keep working normally with reduced injection capability as long as power from HV_ISO is available. | H27: CLB will have no effect | I27: System will keep working normally. | J27: 2 | K27: Degradation of winding insulation. Degradation of solder joint. | L27: Supply from HV_ISO board will be available. | M27: 1 | N27: =J27*M27 -> 2 | O27: Functional Testing. Thermal and Relative Humidity Testing. Condensed Humidity Testing. EFT Testing. Vibration Testing. ATM Testing. MVAr Testing. Pre-Cosure Testing. EOL Testing. | P27: None. | Q27: 5 | R27: =J27*M27*Q27 -> 10 | AF27: =VALUE(RIGHT((IF(A27="",0,A27)),5)) -> -9818
A28: SV104-1602 | E28: Winding of both of common mode chokes fail-short. | F28: No power will be available for iiSC. All iiGD boards will switch to safe off state. | G28: Device will transit to monitoring state. | H28: Heartbeat of iiSC board to CLB board will stop. | I28: Affected device and its associated group of devices will transit to monitoring mode._x000D_ _x000D_ System will keep working with reduced injection capability._x000D_ | J28: 3 | K28: Degradation of winding insulation. Degradation of solder joint. | L28: Usage of over-rated components. Using components with industrial grade scale. Choosing components with enough FIT rate to fulfil the product life requirements. | M28: 1 | N28: =J28*M28 -> 3 | O28: Functional Testing. Thermal and Relative Humidity Testing. Condensed Humidity Testing. EFT Testing. Vibration Testing. ATM Testing. MVAr Testing. Pre-Cosure Testing. EOL Testing. | P28: Loss of communication between iiDCE and iiSC. | Q28: 3 | R28: =J28*M28*Q28 -> 9 | V28: Input required from Power team. | AC28: =Z28*AA28*AB28 -> 0 | AF28: =VALUE(RIGHT((IF(A28="",0,A28)),5)) -> -1602
A29: SV104-12421 | B29: Incoming Supply from HVT board - Inductor | C29: L7 | D29: To Suppress the in-rush current. | E29: Inductor fails-short. | F29: Transient protection will be compromised. No immediate effect will be observed. | G29: Device will keep working normally. | H29: CLB will have no effect | I29: System will keep working normally. | J29: 1 | K29: Over voltage. De-gradation of components. | L29: Usage of over-rated components. Using components with industrial grade scale. Choosing components with enough FIT rate to fulfil the product life requirements. | M29: 1 | N29: =J29*M29 -> 1 | O29: Functional Testing. Thermal and Relative Humidity Testing. Condensed Humidity Testing. EFT Testing. Vibration Testing. ATM Testing. MVAr Testing. Pre-Cosure Testing. EOL Testing. | P29: None. | Q29: 5 | R29: =J29*M29*Q29 -> 5 | AF29: =VALUE(RIGHT((IF(A29="",0,A29)),5)) -> 12421
A30: SV104-12422 | E30: Inductor fails-open. | F30: HVT supply path will be broken. Power will not be available if system s in monitoring mode. | G30: Device will transit to monitoring state. | H30: Heartbeat of iiSC board to CLB board will stop. | I30: Affected device and its associated group of devices will transit to monitoring mode._x000D_ _x000D_ System will keep working with reduced injection capability._x000D_ | J30: 3 | K30: Degradation of winding insulation. Degradation of solder joint. | L30: Usage of over-rated components. Using components with industrial grade scale. Choosing components with enough FIT rate to fulfil the product life requirements. | M30: 1 | N30: =J30*M30 -> 3 | O30: Functional Testing. Thermal and Relative Humidity Testing. Condensed Humidity Testing. EFT Testing. Vibration Testing. ATM Testing. MVAr Testing. Pre-Cosure Testing. EOL Testing. | P30: Loss of communication between iiDCE and iiSC. | Q30: 3 | R30: =J30*M30*Q30 -> 9 | AF30: =VALUE(RIGHT((IF(A30="",0,A30)),5)) -> 12422
A31: SV104-12423 | B31: Incoming Supply from UPSB board - Inductor | C31: L28 | D31: To Suppress the in-rush current. | E31: Inductor fails-short. | F31: Transient protection will be compromised. No immediate effect will be observed. | G31: Device will keep working normally. | H31: CLB will have no effect | I31: System will keep working normally. | J31: 1 | K31: Electrical overstress._x000D_ _x000D_ Bad magnet wire insulation._x000D_ | L31: Usage of over-rated components. Using components with industrial grade scale. Choosing components with enough FIT rate to fulfil the product life requirements. | M31: 1 | N31: =J31*M31 -> 1 | O31: Functional Testing. Thermal and Relative Humidity Testing. Condensed Humidity Testing. EFT Testing. Vibration Testing. ATM Testing. MVAr Testing. Pre-Cosure Testing. EOL Testing. | P31: Loss of communication between iiDCE and iiSC. | Q31: 3 | R31: =J31*M31*Q31 -> 3 | AF31: =VALUE(RIGHT((IF(A31="",0,A31)),5)) -> 12423
A32: SV104-12424 | E32: Inductor fails-open. | F32: UPSB supply path will be broken. Power will be available from HVT supply Board. No immediate affect. | G32: Device will keep working normally. | H32: CLB will have no effect | I32: System will keep working normally. | J32: 2 | K32: Over current._x000D_ _x000D_ Thermal stress_x000D_ _x000D_ Corrosion/bad internal solder joints._x000D_ | L32: Usage of over-rated components. Using components with industrial grade scale. Choosing components with enough FIT rate to fulfil the product life requirements. | M32: 1 | N32: =J32*M32 -> 2 | O32: Functional Testing. Thermal and Relative Humidity Testing. Condensed Humidity Testing. EFT Testing. Vibration Testing. ATM Testing. MVAr Testing. Pre-Cosure Testing. EOL Testing. | P32: Loss of communication between iiDCE and iiSC. | Q32: 3 | R32: =J32*M32*Q32 -> 6 | AF32: =VALUE(RIGHT((IF(A32="",0,A32)),5)) -> 12424
A33: SV104-12425 | B33: Incoming Supply from HVT board - Capacitor grounding jumper | C33: JMP35, JMP26 | D33: To provide safe grounding path to the capacitors | E33: One of the jumper fails open. | F33: Capacitors will have ground path through redundant jumper. No immediate effect. | G33: Device will keep working normally. | H33: CLB will have no effect | I33: System will keep working normally. | J33: 1 | K33: Electrical over stress._x000D_ _x000D_ Over current._x000D_ _x000D_ Thermal heating._x000D_ | L33: Usage of over-rated components. Using components with industrial grade scale. Choosing components with enough FIT rate to fulfil the product life requirements. | M33: 1 | N33: =J33*M33 -> 1 | O33: Functional Testing. Thermal and Relative Humidity Testing. Condensed Humidity Testing. EFT Testing. Vibration Testing. ATM Testing. MVAr Testing. Pre-Cosure Testing. EOL Testing. | P33: None. | Q33: 5 | R33: =N33*Q33 -> 5 | AF33: =VALUE(RIGHT((IF(A33="",0,A33)),5)) -> 12425
A34: SV104-12426 | B34: Incoming Supply from UPSB board - Capacitor grounding jumper | C34: R167 (1 ohm) | D34: To provide safe grounding path to the capacitors | E34: Resistor fails open. | F34: Grounding path for capacitors will be broken. Filtering capability will be reduced. | G34: Device will keep working normally. | H34: CLB will have no effect | I34: System will keep working normally. | J34: 1 | K34: Electrical overstress._x000D_ _x000D_ Bad magnet wire insulation._x000D_ | L34: Choosing components with enough FIT rate to fulfill the product life requirements. Components with higher ratings (current/voltage) are used. | M34: 1 | N34: =J34*M34 -> 1 | O34: Functional Testing. Thermal and Relative Humidity Testing. Condensed Humidity Testing. EFT Testing. Vibration Testing. ATM Testing. MVAr Testing. Pre-Cosure Testing. EOL Testing. | P34: Loss of communication between iiDCE and iiSC. | Q34: 3 | R34: =N34*Q34 -> 3 | AF34: =VALUE(RIGHT((IF(A34="",0,A34)),5)) -> 12426
A35: SV104-12427 | E35: Resistor fails short. | F35: No immediate effect. | G35: Device will keep working normally. | H35: CLB will have no effect | I35: System will keep working normally. | J35: 1 | K35: Dielectric failure._x000D_ _x000D_ | L35: Choosing components with enough FIT rate to fulfill the product life requirements. Components with higher ratings (current/voltage) are used. | M35: 1 | N35: =J35*M35 -> 1 | O35: Functional Testing. Thermal and Relative Humidity Testing. Condensed Humidity Testing. EFT Testing. Vibration Testing. ATM Testing. MVAr Testing. Pre-Cosure Testing. EOL Testing. | P35: Loss of communication between iiDCE and iiSC. | Q35: 3 | R35: =N35*Q35 -> 3 | AF35: =VALUE(RIGHT((IF(A35="",0,A35)),5)) -> 12427
A36: SV104-12428 | B36: Incoming Supply from HVT board - Capacitor grounding jumper | C36: JMP36, JMP30 | D36: To provide safe grounding path to the capacitors | E36: One of the jumper fails open. | F36: Capacitors will have ground path through redundant jumper. No immediate effect. | G36: Device will keep working normally. | H36: CLB will have no effect | I36: System will keep working normally. | J36: 1 | K36: Over current._x000D_ _x000D_ Thermal stress._x000D_ | L36: Choosing components with enough FIT rate to fulfill the product life requirements. Components with higher ratings (current/voltage) are used. | M36: 1 | N36: =J36*M36 -> 1 | O36: Functional Testing. Thermal and Relative Humidity Testing. Condensed Humidity Testing. EFT Testing. Vibration Testing. ATM Testing. MVAr Testing. Pre-Cosure Testing. EOL Testing. | P36: Loss of communication between iiDCE and iiSC. | Q36: 3 | R36: =N36*Q36 -> 3 | AF36: =VALUE(RIGHT((IF(A36="",0,A36)),5)) -> 12428
A37: SV104-12429 | B37: Incoming Supply from UPSB board - Capacitor grounding jumper | C37: R196 (1 ohm) | D37: To provide safe grounding path to the capacitors | E37: Resistor fails open. | F37: Grounding path for capacitors will be broken. Filtering capability will be reduced. | G37: Device will keep working normally. | H37: CLB will have no effect | I37: System will keep working normally. | J37: 1 | K37: Electrical overstress._x000D_ _x000D_ Bad magnet wire insulation._x000D_ | L37: Choosing components with enough FIT rate to fulfill the product life requirements. Components with higher ratings (current/voltage) are used. | M37: 1 | N37: =J37*M37 -> 1 | O37: Functional Testing. Thermal and Relative Humidity Testing. Condensed Humidity Testing. EFT Testing. Vibration Testing. ATM Testing. MVAr Testing. Pre-Cosure Testing. EOL Testing. | P37: Loss of communication between iiDCE and iiSC. | Q37: 3 | R37: =N37*Q37 -> 3 | AF37: =VALUE(RIGHT((IF(A37="",0,A37)),5)) -> 12429
A38: SV104-12430 | E38: Resistor fails short. | F38: No immediate effect. | G38: Device will keep working normally. | H38: CLB will have no effect | I38: System will keep working normally. | J38: 1 | K38: Electrical overstress._x000D_ _x000D_ Bad magnet wire insulation._x000D_ | L38: Choosing components with enough FIT rate to fulfill the product life requirements. Components with higher ratings (current/voltage) are used. | M38: 1 | N38: =J38*M38 -> 1 | O38: Functional Testing. Thermal and Relative Humidity Testing. Condensed Humidity Testing. EFT Testing. Vibration Testing. ATM Testing. MVAr Testing. Pre-Cosure Testing. EOL Testing. | P38: Loss of communication between iiDCE and iiSC. | Q38: 3 | R38: =N38*Q38 -> 3 | AF38: =VALUE(RIGHT((IF(A38="",0,A38)),5)) -> 12430
A39: SV104-12431 | B39: Incoming Supply from HVT board - Filtering Capacitors | C39: C127, C128, C139 | D39: To suppress ripples and filter out noise. | E39: One of the capacitor fails-open. | F39: Other capacitors will be present for noise protection. No immediate effect will be observed. | G39: Device will keep working normally. | H39: CLB will have no effect | I39: System will keep working normally. | J39: 1 | K39: Electrical overstress._x000D_ _x000D_ Bad magnet wire insulation._x000D_ | L39: Choosing components with enough FIT rate to fulfill the product life requirements. Components with higher ratings (current/voltage) are used. | M39: 1 | N39: =J39*M39 -> 1 | O39: Functional Testing. Thermal and Relative Humidity Testing. Condensed Humidity Testing. EFT Testing. Vibration Testing. ATM Testing. MVAr Testing. Pre-Cosure Testing. EOL Testing. | P39: Loss of communication between iiDCE and iiSC. | Q39: 3 | R39: =J39*M39*Q39 -> 3 | AF39: =VALUE(RIGHT((IF(A39="",0,A39)),5)) -> 12431
