Workbook
Name _polarion_4: OFFSET(_polarion_options_start,MATCH(CONCATENATE(_polarion_type,":","PRD-Section"),_polarion_options_types,0),1,COUNTIF(_polarion_options_types,CONCATENATE(_polarion_type,":","PRD-Section")),1)
Name _polarion_info: #REF!
Name _polarion_info: #REF!
Name _polarion_info: #REF!
Name _polarion_info: #REF!
Name _polarion_info: #REF!
Name _polarion_options_start: [1]!_polarion_options[[#Headers],[Type]]
Name _polarion_options_types: [1]!_polarion_options[Type]
Name _polarion_project: IF(ISBLANK(_polarion_info),"PrimaryProtectionSystem",LEFT(_polarion_info,SEARCH("/",_polarion_info,1)-1))
Name _polarion_project: IF(ISBLANK(DFMECA!_polarion_info),"PrimaryProtectionSystem",LEFT(DFMECA!_polarion_info,SEARCH("/",DFMECA!_polarion_info,1)-1))
Name _polarion_project: IF(ISBLANK(_polarion_info),"PrimaryProtectionSystem",LEFT(_polarion_info,SEARCH("/",_polarion_info,1)-1))
Name _polarion_project: IF(ISBLANK(_polarion_info),"PrimaryProtectionSystem",LEFT(_polarion_info,SEARCH("/",_polarion_info,1)-1))
Name _polarion_project: IF(ISBLANK('Revision History'!_polarion_info),"PrimaryProtectionSystem",LEFT('Revision History'!_polarion_info,SEARCH("/",'Revision History'!_polarion_info,1)-1))
Name _polarion_project: IF(ISBLANK('Scores '!_polarion_info),"PrimaryProtectionSystem",LEFT('Scores '!_polarion_info,SEARCH("/",'Scores '!_polarion_info,1)-1))
Name _polarion_project: IF(ISBLANK(Title!_polarion_info),"PrimaryProtectionSystem",LEFT(Title!_polarion_info,SEARCH("/",Title!_polarion_info,1)-1))
Name _polarion_project: IF(ISBLANK(_polarion_info),"PrimaryProtectionSystem",LEFT(_polarion_info,SEARCH("/",_polarion_info,1)-1))
Name _polarion_type: CONCATENATE('Bypass - Architecture'!_polarion_project,"/",IF(ISBLANK(#REF!),"requirement",#REF!))
Name _polarion_type: CONCATENATE(DFMECA!_polarion_project,"/",IF(ISBLANK(#REF!),"requirement",#REF!))
Name _polarion_type: CONCATENATE('Functional Block Diagram '!_polarion_project,"/",IF(ISBLANK(#REF!),"requirement",#REF!))
Name _polarion_type: CONCATENATE('MVAr - Architecture'!_polarion_project,"/",IF(ISBLANK(#REF!),"requirement",#REF!))
Name _polarion_type: CONCATENATE('Revision History'!_polarion_project,"/",IF(ISBLANK(#REF!),"requirement",#REF!))
Name _polarion_type: CONCATENATE('Scores '!_polarion_project,"/",IF(ISBLANK(#REF!),"requirement",#REF!))
Name _polarion_type: CONCATENATE(Title!_polarion_project,"/",IF(ISBLANK(#REF!),"requirement",#REF!))
Name _polarion_type: CONCATENATE(_polarion_project,"/",IF(ISBLANK(#REF!),"requirement",#REF!))
Name ValidPPDPhase: #REF!
Name ValidPPDPhase: #REF!
Name ValidPPDPhase: #REF!
Name ValidPPDPhase: #REF!

Sheet Title
B3: Title: | C3: SmartValve 10-1800 v1.04 - HV-ISO-XFMR Board Rev3 (P112469) - Failure Mode Effects and Criticality Analysis (Design FMECA)
B4: Project: | C4: SmartValve 10-1800 v1.04
B6: PS19 QPI | C6: PS19 Technical Experts | D6: Smart Wires Reviewer
B7: Azeem, Talha, Adeel, Ashad | C7: Abdul Qadeer, Abdul Rehman | D7: Susie Choi

Sheet Revision History
B2: Revision History
B3: Date | C3: Version | D3: Description
B4: 44215 | C4: 1 | D4: Initial draft based on HVT Board FMECA Rev0 by PS19 QPI Team
B6: 44259 | C6: 1.1 | D6: Updated based on HVT Board FMECA Rev1 by PS19 QPI Team
B7: 44582 | C7: 1.2 | D7: Updated based on HVT Board FMECA Rev2 by PS19 QPI Team
B8: 44594 | C8: 1.3 | D8: Reviewed by PS19 Hardware team for the changes done based on the Rev2 schematic
B9: 44599 | C9: 1.4 | D9: Updated by PS19 QPI team based on the feedback by PS19 Harware Team on Rev2 schematic
B10: 44638 | C10: 1.5 | D10: Reveiwed and updated by DR. Susie based on the Rev2 schematic
B11: 44771 | C11: 1.6 | D11: Updated based on HVT Board FMECA Rev3 by PS19 QPI Team
B12: 44774 | C12: 1.7 | D12: Reviewed by PS19 Hardware team for the changes done based on the Rev3 schematic
B13: 44824 | C13: 1.8 | D13: Updated by PS19 QPI team based on the feedback by PS19 Smart Wires Team on Rev3 schematic
B14: 44832 | C14: 1.9 | D14: Reviewed by PS19 Hardware team for the changes done based on the Rev3 schematic
B15: 44840 | C15: 2 | D15: Updated by PS19 QPI team based on feedback from Smart Wires and PS19 Hardware Team
B16: 44848 | C16: 2.1 | D16: Reviewed by PS19 Hardware team for the changes done based on the Rev3 schematic
... B18: 44883 | C18: 2.3 | D18: Updated by PS19 QPI team based on feedback from Smart Wires Team

Sheet Definitions-Terms
B2: Definitions / Terms / Acronyms
B3: Term | C3: Description | D3: Term | E3: Description
B4: A-K | C4: Anode-to-Cathode | D4: LCB | E4: Liquid Cooling Block
B5: BF | C5: Bypass Filter | D5: PHT | E5: Power Harvesting Transformer
B6: CTP | C6: Current Transformer for Power | D6: ETP | E6: Electrical Test Procedure
B7: DCCT | C7: DC current transducer | D7: IP | E7: Intrusion Protection
B8: DCE | C8: Digital Computational Engine | D8: MES | E8: Manufacturing Execution System
B9: EFT | C9: Electrical Fast Transient | D9: CTQ | E9: Critical To Quality
B10: EMS | C10: Energy Management System
B11: EOL | C11: End Of Line
B12: FCS | C12: Fault Current Sensor
B13: FO | C13: Fiber Optic
B14: FR | C14: Flame Retardant
B15: G-K | C15: Gate-to-Cathode
B16: HALT | C16: Highly-Accelerated Life Testing
B17: HASS | C17: High accelerated stress screening
B18: HCT | C18: High Current Testing
B19: LCB | C19: Liquid Cooling Block
B20: LCS | C20: Line Current Sensor
B21: OVP | C21: Over-Voltage Protection
... B37: TBR | C37: To be Reviewed

Sheet Scores 
D2: Risk Factor (S x O) Scores | L2: SmartValve v1.04 Risk Factor (S x O) Counts
B4: Occurrence | C4: 5 | D4: =$C$4*D9 -> 5 | E4: =$C$4*E9 -> 10 | F4: =$C$4*F9 -> 15 | G4: =$C$4*G9 -> 20 | H4: =$C$4*H9 -> 25 | K4: Occurrence | L4: 5 | M4: {=SUMPRODUCT(--(DFMECA!$I$3:$I$1024=1),--(DFMECA!$L$3:$L$1024=5))} -> 0 | N4: {=SUMPRODUCT(--(DFMECA!$I$3:$I$1024=2),--(DFMECA!$L$3:$L$1024=5))} -> 0 | O4: {=SUMPRODUCT(--(DFMECA!I3:I1024=3),--(DFMECA!L3:L1024=5))} -> 0 | P4: {=SUMPRODUCT(--(DFMECA!I3:I1024=4),--(DFMECA!L3:L1024=5))} -> 0 | Q4: {=SUMPRODUCT(--(DFMECA!I3:I1024=5),--(DFMECA!L3:L1024=5))} -> 0
C5: 4 | D5: =$C$5*D9 -> 4 | E5: =$C$5*E9 -> 8 | F5: =$C$5*F9 -> 12 | G5: =$C$5*G9 -> 16 | H5: =$C$5*H9 -> 20 | L5: 4 | M5: {=SUMPRODUCT(--(DFMECA!$I$3:$I$1024=1),--(DFMECA!$L$3:$L$1024=4))} -> 0 | N5: {=SUMPRODUCT(--(DFMECA!$I$3:$I$1024=2),--(DFMECA!$L$3:$L$1024=4))} -> 0 | O5: {=SUMPRODUCT(--(DFMECA!I3:I1024=3),--(DFMECA!L3:L1024=4))} -> 0 | P5: {=SUMPRODUCT(--(DFMECA!I3:I1024=4),--(DFMECA!L3:L1024=4))} -> 0 | Q5: {=SUMPRODUCT(--(DFMECA!I3:I1024=5),--(DFMECA!L3:L1024=4))} -> 0
C6: 3 | D6: =$C$6*D9 -> 3 | E6: =$C$6*E9 -> 6 | F6: =$C$6*F9 -> 9 | G6: =$C$6*G9 -> 12 | H6: =$C$6*H9 -> 15 | L6: 3 | M6: {=SUMPRODUCT(--(DFMECA!$I$3:$I$1024=1),--(DFMECA!$L$3:$L$1024=3))} -> 0 | N6: =SUMPRODUCT(--(DFMECA!I3:I1024=2),--(DFMECA!L3:L1024=3)) -> 0 | O6: {=SUMPRODUCT(--(DFMECA!I3:I1024=3),--(DFMECA!L3:L1024=3))} -> 0 | P6: {=SUMPRODUCT(--(DFMECA!I3:I1024=4),--(DFMECA!L3:L1024=3))} -> 0 | Q6: {=SUMPRODUCT(--(DFMECA!I3:I1024=5),--(DFMECA!L3:L1024=3))} -> 0
C7: 2 | D7: =$C$7*D9 -> 2 | E7: =$C$7*E9 -> 4 | F7: =$C$7*F9 -> 6 | G7: =$C$7*G9 -> 8 | H7: =$C$7*H9 -> 10 | L7: 2 | M7: {=SUMPRODUCT(--(DFMECA!$I$3:$I$1024=1),--(DFMECA!$L$3:$L$1024=2))} -> 25 | N7: {=SUMPRODUCT(--(DFMECA!$I$3:$I$1024=2),--(DFMECA!$L$3:$L$1024=2))} -> 47 | O7: {=SUMPRODUCT(--(DFMECA!I3:I1024=3),--(DFMECA!L3:L1024=2))} -> 8 | P7: {=SUMPRODUCT(--(DFMECA!I3:I1024=4),--(DFMECA!L3:L1024=2))} -> 4 | Q7: {=SUMPRODUCT(--(DFMECA!I3:I1024=5),--(DFMECA!L3:L1024=2))} -> 0
C8: 1 | D8: =$C$8*D9 -> 1 | E8: =$C$8*E9 -> 2 | F8: =$C$8*F9 -> 3 | G8: =$C$8*G9 -> 4 | H8: =$C$8*H9 -> 5 | L8: 1 | M8: {=SUMPRODUCT(--(DFMECA!$I$3:$I$1024=1),--(DFMECA!$L$3:$L$1024=1))} -> 310 | N8: {=SUMPRODUCT(--(DFMECA!$I$3:$I$1024=2),--(DFMECA!$L$3:$L$1024=1))} -> 422 | O8: {=SUMPRODUCT(--(DFMECA!I3:I1024=3),--(DFMECA!L3:L1024=1))} -> 77 | P8: {=SUMPRODUCT(--(DFMECA!I3:I1024=4),--(DFMECA!L3:L1024=1))} -> 94 | Q8: {=SUMPRODUCT(--(DFMECA!I3:I1024=5),--(DFMECA!L3:L1024=1))} -> 6
D9: 1 | E9: 2 | F9: 3 | G9: 4 | H9: 5 | M9: 1 | N9: 2 | O9: 3 | P9: 4 | Q9: 5
D10: Severity | M10: Severity
M12: Total risks: | Q12: =SUM(M4:M8)+SUM(N4:N8)+SUM(O4:O8)+SUM(P4:P8)+SUM(Q4:Q8) -> 993
M13: Total risks require mitigation based on S x O: | Q13: =SUM(N4:N5)+SUM(O4:O6)+SUM(P4:P7)+SUM(Q4:Q8) -> 10
C17: Risk Priority Number (S x O x D) Scores | L17: SmartValve v1.04 RPN (S x O x D) Counts
B19: Severity x Occurrence (S x O) | C19: 25 | D19: =C19*$D$44 -> 25 | E19: =C19*$E$44 -> 50 | F19: =C19*$F$44 -> 75 | G19: =C19*$G$44 -> 100 | H19: =C19*$H$44 -> 125 | K19: Severity x Occurrence (S x O) | L19: 25 | M19: {=SUMPRODUCT(--(DFMECA!M3:M1024=25),--(DFMECA!P3:P1024=1))} -> 0 | N19: {=SUMPRODUCT(--(DFMECA!M3:M1024=25),--(DFMECA!P3:P1024=2))} -> 0 | O19: {=SUMPRODUCT(--(DFMECA!M3:M1024=25),--(DFMECA!P3:P1024=3))} -> 0 | P19: {=SUMPRODUCT(--(DFMECA!M3:M1024=25),--(DFMECA!P3:P1024=4))} -> 0 | Q19: {=SUMPRODUCT(--(DFMECA!M3:M1024=25),--(DFMECA!P3:P1024=5))} -> 0
C20: 24 | D20: =C20*$D$44 -> 24 | E20: =C20*$E$44 -> 48 | F20: =C20*$F$44 -> 72 | G20: =C20*$G$44 -> 96 | H20: =C20*$H$44 -> 120 | L20: 24 | M20: {=SUMPRODUCT(--(DFMECA!M3:M1024=24),--(DFMECA!P3:P1024=1))} -> 0 | N20: {=SUMPRODUCT(--(DFMECA!M3:M1024=24),--(DFMECA!P3:P1024=2))} -> 0 | O20: {=SUMPRODUCT(--(DFMECA!M3:M1024=24),--(DFMECA!P3:P1024=3))} -> 0 | P20: {=SUMPRODUCT(--(DFMECA!M3:M1024=24),--(DFMECA!P3:P1024=4))} -> 0 | Q20: {=SUMPRODUCT(--(DFMECA!M3:M1024=24),--(DFMECA!P3:P1024=5))} -> 0
C21: 23 | D21: =C21*$D$44 -> 23 | E21: =C21*$E$44 -> 46 | F21: =C21*$F$44 -> 69 | G21: =C21*$G$44 -> 92 | H21: =C21*$H$44 -> 115 | L21: 23 | M21: {=SUMPRODUCT(--(DFMECA!M3:M1024=23),--(DFMECA!P3:P1024=1))} -> 0 | N21: =SUMPRODUCT(--(DFMECA!M3:M1024=23),--(DFMECA!P3:P1024=2)) -> 0 | O21: {=SUMPRODUCT(--(DFMECA!M3:M1024=23),--(DFMECA!P3:P1024=3))} -> 0 | P21: {=SUMPRODUCT(--(DFMECA!M3:M1024=23),--(DFMECA!P3:P1024=4))} -> 0 | Q21: {=SUMPRODUCT(--(DFMECA!M3:M1024=23),--(DFMECA!P3:P1024=5))} -> 0
C22: 22 | D22: =C22*$D$44 -> 22 | E22: =C22*$E$44 -> 44 | F22: =C22*$F$44 -> 66 | G22: =C22*$G$44 -> 88 | H22: =C22*$H$44 -> 110 | L22: 22 | M22: {=SUMPRODUCT(--(DFMECA!M3:M1024=22),--(DFMECA!P3:P1024=1))} -> 0 | N22: {=SUMPRODUCT(--(DFMECA!M3:M1024=22),--(DFMECA!P3:P1024=2))} -> 0 | O22: {=SUMPRODUCT(--(DFMECA!M3:M1024=22),--(DFMECA!P3:P1024=3))} -> 0 | P22: {=SUMPRODUCT(--(DFMECA!M3:M1024=22),--(DFMECA!P3:P1024=4))} -> 0 | Q22: {=SUMPRODUCT(--(DFMECA!M3:M1024=22),--(DFMECA!P3:P1024=5))} -> 0
C23: 21 | D23: =C23*$D$44 -> 21 | E23: =C23*$E$44 -> 42 | F23: =C23*$F$44 -> 63 | G23: =C23*$G$44 -> 84 | H23: =C23*$H$44 -> 105 | L23: 21 | M23: {=SUMPRODUCT(--(DFMECA!M3:M1024=21),--(DFMECA!P3:P1024=1))} -> 0 | N23: {=SUMPRODUCT(--(DFMECA!M3:M1024=21),--(DFMECA!P3:P1024=2))} -> 0 | O23: {=SUMPRODUCT(--(DFMECA!M3:M1024=21),--(DFMECA!P3:P1024=3))} -> 0 | P23: {=SUMPRODUCT(--(DFMECA!M3:M1024=21),--(DFMECA!P3:P1024=4))} -> 0 | Q23: {=SUMPRODUCT(--(DFMECA!M3:M1024=21),--(DFMECA!P3:P1024=5))} -> 0
C24: 20 | D24: =C24*$D$44 -> 20 | E24: =C24*$E$44 -> 40 | F24: =C24*$F$44 -> 60 | G24: =C24*$G$44 -> 80 | H24: =C24*$H$44 -> 100 | L24: 20 | M24: {=SUMPRODUCT(--(DFMECA!M3:M1024=20),--(DFMECA!P3:P1024=1))} -> 0 | N24: {=SUMPRODUCT(--(DFMECA!M3:M1024=20),--(DFMECA!P3:P1024=2))} -> 0 | O24: {=SUMPRODUCT(--(DFMECA!M3:M1024=20),--(DFMECA!P3:P1024=3))} -> 0 | P24: {=SUMPRODUCT(--(DFMECA!M3:M1024=20),--(DFMECA!P3:P1024=4))} -> 0 | Q24: {=SUMPRODUCT(--(DFMECA!M3:M1024=20),--(DFMECA!P3:P1024=5))} -> 0
C25: 19 | D25: =C25*$D$44 -> 19 | E25: =C25*$E$44 -> 38 | F25: =C25*$F$44 -> 57 | G25: =C25*$G$44 -> 76 | H25: =C25*$H$44 -> 95 | L25: 19 | M25: {=SUMPRODUCT(--(DFMECA!M3:M1024=19),--(DFMECA!P3:P1024=1))} -> 0 | N25: {=SUMPRODUCT(--(DFMECA!M3:M1024=19),--(DFMECA!P3:P1024=2))} -> 0 | O25: {=SUMPRODUCT(--(DFMECA!M3:M1024=19),--(DFMECA!P3:P1024=3))} -> 0 | P25: {=SUMPRODUCT(--(DFMECA!M3:M1024=19),--(DFMECA!P3:P1024=4))} -> 0 | Q25: {=SUMPRODUCT(--(DFMECA!M3:M1024=19),--(DFMECA!P3:P1024=5))} -> 0
C26: 18 | D26: =C26*$D$44 -> 18 | E26: =C26*$E$44 -> 36 | F26: =C26*$F$44 -> 54 | G26: =C26*$G$44 -> 72 | H26: =C26*$H$44 -> 90 | L26: 18 | M26: {=SUMPRODUCT(--(DFMECA!M3:M1024=18),--(DFMECA!P3:P1024=1))} -> 0 | N26: {=SUMPRODUCT(--(DFMECA!M3:M1024=18),--(DFMECA!P3:P1024=2))} -> 0 | O26: {=SUMPRODUCT(--(DFMECA!M3:M1024=18),--(DFMECA!P3:P1024=3))} -> 0 | P26: {=SUMPRODUCT(--(DFMECA!M3:M1024=18),--(DFMECA!P3:P1024=4))} -> 0 | Q26: {=SUMPRODUCT(--(DFMECA!M3:M1024=18),--(DFMECA!P3:P1024=5))} -> 0
C27: 17 | D27: =C27*$D$44 -> 17 | E27: =C27*$E$44 -> 34 | F27: =C27*$F$44 -> 51 | G27: =C27*$G$44 -> 68 | H27: =C27*$H$44 -> 85 | L27: 17 | M27: {=SUMPRODUCT(--(DFMECA!M3:M1024=17),--(DFMECA!P3:P1024=1))} -> 0 | N27: {=SUMPRODUCT(--(DFMECA!M3:M1024=17),--(DFMECA!P3:P1024=2))} -> 0 | O27: {=SUMPRODUCT(--(DFMECA!M3:M1024=17),--(DFMECA!P3:P1024=3))} -> 0 | P27: {=SUMPRODUCT(--(DFMECA!M3:M1024=17),--(DFMECA!P3:P1024=4))} -> 0 | Q27: {=SUMPRODUCT(--(DFMECA!M3:M1024=17),--(DFMECA!P3:P1024=5))} -> 0
C28: 16 | D28: =C28*$D$44 -> 16 | E28: =C28*$E$44 -> 32 | F28: =C28*$F$44 -> 48 | G28: =C28*$G$44 -> 64 | H28: =C28*$H$44 -> 80 | L28: 16 | M28: {=SUMPRODUCT(--(DFMECA!M3:M1024=16),--(DFMECA!P3:P1024=1))} -> 0 | N28: {=SUMPRODUCT(--(DFMECA!M3:M1024=16),--(DFMECA!P3:P1024=2))} -> 0 | O28: {=SUMPRODUCT(--(DFMECA!M3:M1024=16),--(DFMECA!P3:P1024=3))} -> 0 | P28: {=SUMPRODUCT(--(DFMECA!M3:M1024=16),--(DFMECA!P3:P1024=4))} -> 0 | Q28: {=SUMPRODUCT(--(DFMECA!M3:M1024=16),--(DFMECA!P3:P1024=5))} -> 0
C29: 15 | D29: =C29*$D$44 -> 15 | E29: =C29*$E$44 -> 30 | F29: =C29*$F$44 -> 45 | G29: =C29*$G$44 -> 60 | H29: =C29*$H$44 -> 75 | L29: 15 | M29: {=SUMPRODUCT(--(DFMECA!M3:M1024=15),--(DFMECA!P3:P1024=1))} -> 0 | N29: {=SUMPRODUCT(--(DFMECA!M3:M1024=15),--(DFMECA!P3:P1024=2))} -> 0 | O29: {=SUMPRODUCT(--(DFMECA!M3:M1024=15),--(DFMECA!P3:P1024=3))} -> 0 | P29: {=SUMPRODUCT(--(DFMECA!M3:M1024=15),--(DFMECA!P3:P1024=4))} -> 0 | Q29: {=SUMPRODUCT(--(DFMECA!M3:M1024=15),--(DFMECA!P3:P1024=5))} -> 0
C30: 14 | D30: =C30*$D$44 -> 14 | E30: =C30*$E$44 -> 28 | F30: =C30*$F$44 -> 42 | G30: =C30*$G$44 -> 56 | H30: =C30*$H$44 -> 70 | L30: 14 | M30: {=SUMPRODUCT(--(DFMECA!M3:M1024=14),--(DFMECA!P3:P1024=1))} -> 0 | N30: {=SUMPRODUCT(--(DFMECA!M3:M1024=14),--(DFMECA!P3:P1024=2))} -> 0 | O30: {=SUMPRODUCT(--(DFMECA!M3:M1024=14),--(DFMECA!P3:P1024=3))} -> 0 | P30: {=SUMPRODUCT(--(DFMECA!M3:M1024=14),--(DFMECA!P3:P1024=4))} -> 0 | Q30: {=SUMPRODUCT(--(DFMECA!M3:M1024=14),--(DFMECA!P3:P1024=5))} -> 0
C31: 13 | D31: =C31*$D$44 -> 13 | E31: =C31*$E$44 -> 26 | F31: =C31*$F$44 -> 39 | G31: =C31*$G$44 -> 52 | H31: =C31*$H$44 -> 65 | L31: 13 | M31: {=SUMPRODUCT(--(DFMECA!M3:M1024=13),--(DFMECA!P3:P1024=1))} -> 0 | N31: {=SUMPRODUCT(--(DFMECA!M3:M1024=13),--(DFMECA!P3:P1024=2))} -> 0 | O31: {=SUMPRODUCT(--(DFMECA!M3:M1024=13),--(DFMECA!P3:P1024=3))} -> 0 | P31: {=SUMPRODUCT(--(DFMECA!M3:M1024=13),--(DFMECA!P3:P1024=4))} -> 0 | Q31: {=SUMPRODUCT(--(DFMECA!M3:M1024=13),--(DFMECA!P3:P1024=5))} -> 0
C32: 12 | D32: =C32*$D$44 -> 12 | E32: =C32*$E$44 -> 24 | F32: =C32*$F$44 -> 36 | G32: =C32*$G$44 -> 48 | H32: =C32*$H$44 -> 60 | L32: 12 | M32: {=SUMPRODUCT(--(DFMECA!M3:M1024=12),--(DFMECA!P3:P1024=1))} -> 0 | N32: {=SUMPRODUCT(--(DFMECA!M3:M1024=12),--(DFMECA!P3:P1024=2))} -> 0 | O32: {=SUMPRODUCT(--(DFMECA!M3:M1024=12),--(DFMECA!P3:P1024=3))} -> 0 | P32: {=SUMPRODUCT(--(DFMECA!M3:M1024=12),--(DFMECA!P3:P1024=4))} -> 0 | Q32: {=SUMPRODUCT(--(DFMECA!M3:M1024=12),--(DFMECA!P3:P1024=5))} -> 0
C33: 11 | D33: =C33*$D$44 -> 11 | E33: =C33*$E$44 -> 22 | F33: =C33*$F$44 -> 33 | G33: =C33*$G$44 -> 44 | H33: =C33*$H$44 -> 55 | L33: 11 | M33: {=SUMPRODUCT(--(DFMECA!M3:M1024=11),--(DFMECA!P3:P1024=1))} -> 0 | N33: {=SUMPRODUCT(--(DFMECA!M3:M1024=11),--(DFMECA!P3:P1024=2))} -> 0 | O33: {=SUMPRODUCT(--(DFMECA!M3:M1024=11),--(DFMECA!P3:P1024=3))} -> 0 | P33: {=SUMPRODUCT(--(DFMECA!M3:M1024=11),--(DFMECA!P3:P1024=4))} -> 0 | Q33: {=SUMPRODUCT(--(DFMECA!M3:M1024=11),--(DFMECA!P3:P1024=5))} -> 0
C34: 10 | D34: =C34*$D$44 -> 10 | E34: =C34*$E$44 -> 20 | F34: =C34*$F$44 -> 30 | G34: =C34*$G$44 -> 40 | H34: =C34*$H$44 -> 50 | L34: 10 | M34: {=SUMPRODUCT(--(DFMECA!M3:M1024=10),--(DFMECA!P3:P1024=1))} -> 0 | N34: {=SUMPRODUCT(--(DFMECA!M3:M1024=10),--(DFMECA!P3:P1024=2))} -> 0 | O34: {=SUMPRODUCT(--(DFMECA!M3:M1024=10),--(DFMECA!P3:P1024=3))} -> 0 | P34: {=SUMPRODUCT(--(DFMECA!M3:M1024=10),--(DFMECA!P3:P1024=4))} -> 0 | Q34: {=SUMPRODUCT(--(DFMECA!M3:M1024=10),--(DFMECA!P3:P1024=5))} -> 0
C35: 9 | D35: =C35*$D$44 -> 9 | E35: =C35*$E$44 -> 18 | F35: =C35*$F$44 -> 27 | G35: =C35*$G$44 -> 36 | H35: =C35*$H$44 -> 45 | L35: 9 | M35: {=SUMPRODUCT(--(DFMECA!M3:M1024=9),--(DFMECA!P3:P1024=1))} -> 0 | N35: {=SUMPRODUCT(--(DFMECA!M3:M1024=9),--(DFMECA!P3:P1024=2))} -> 0 | O35: {=SUMPRODUCT(--(DFMECA!M3:M1024=9),--(DFMECA!P3:P1024=3))} -> 0 | P35: {=SUMPRODUCT(--(DFMECA!M3:M1024=9),--(DFMECA!P3:P1024=4))} -> 0 | Q35: {=SUMPRODUCT(--(DFMECA!M3:M1024=9),--(DFMECA!P3:P1024=5))} -> 0
C36: 8 | D36: =C36*$D$44 -> 8 | E36: =C36*$E$44 -> 16 | F36: =C36*$F$44 -> 24 | G36: =C36*$G$44 -> 32 | H36: =C36*$H$44 -> 40 | L36: 8 | M36: {=SUMPRODUCT(--(DFMECA!M3:M1024=8),--(DFMECA!P3:P1024=1))} -> 0 | N36: {=SUMPRODUCT(--(DFMECA!M3:M1024=8),--(DFMECA!P3:P1024=2))} -> 3 | O36: {=SUMPRODUCT(--(DFMECA!M3:M1024=8),--(DFMECA!P3:P1024=3))} -> 0 | P36: {=SUMPRODUCT(--(DFMECA!M3:M1024=8),--(DFMECA!P3:P1024=4))} -> 0 | Q36: {=SUMPRODUCT(--(DFMECA!M3:M1024=8),--(DFMECA!P3:P1024=5))} -> 0
C37: 7 | D37: =C37*$D$44 -> 7 | E37: =C37*$E$44 -> 14 | F37: =C37*$F$44 -> 21 | G37: =C37*$G$44 -> 28 | H37: =C37*$H$44 -> 35 | L37: 7 | M37: {=SUMPRODUCT(--(DFMECA!M3:M1024=7),--(DFMECA!P3:P1024=1))} -> 0 | N37: {=SUMPRODUCT(--(DFMECA!M3:M1024=7),--(DFMECA!P3:P1024=2))} -> 0 | O37: {=SUMPRODUCT(--(DFMECA!M3:M1024=7),--(DFMECA!P3:P1024=3))} -> 0 | P37: {=SUMPRODUCT(--(DFMECA!M3:M1024=7),--(DFMECA!P3:P1024=4))} -> 0 | Q37: {=SUMPRODUCT(--(DFMECA!M3:M1024=7),--(DFMECA!P3:P1024=5))} -> 0
C38: 6 | D38: =C38*$D$44 -> 6 | E38: =C38*$E$44 -> 12 | F38: =C38*$F$44 -> 18 | G38: =C38*$G$44 -> 24 | H38: =C38*$H$44 -> 30 | L38: 6 | M38: {=SUMPRODUCT(--(DFMECA!M3:M1024=6),--(DFMECA!P3:P1024=1))} -> 0 | N38: {=SUMPRODUCT(--(DFMECA!M3:M1024=6),--(DFMECA!P3:P1024=2))} -> 0 | O38: {=SUMPRODUCT(--(DFMECA!M3:M1024=6),--(DFMECA!P3:P1024=3))} -> 0 | P38: {=SUMPRODUCT(--(DFMECA!M3:M1024=6),--(DFMECA!P3:P1024=4))} -> 0 | Q38: {=SUMPRODUCT(--(DFMECA!M3:M1024=6),--(DFMECA!P3:P1024=5))} -> 8
C39: 5 | D39: =C39*$D$44 -> 5 | E39: =C39*$E$44 -> 10 | F39: =C39*$F$44 -> 15 | G39: =C39*$G$44 -> 20 | H39: =C39*$H$44 -> 25 | L39: 5 | M39: {=SUMPRODUCT(--(DFMECA!M3:M1024=5),--(DFMECA!P3:P1024=1))} -> 1 | N39: {=SUMPRODUCT(--(DFMECA!M3:M1024=5),--(DFMECA!P3:P1024=2))} -> 0 | O39: {=SUMPRODUCT(--(DFMECA!M3:M1024=5),--(DFMECA!P3:P1024=3))} -> 0 | P39: {=SUMPRODUCT(--(DFMECA!M3:M1024=5),--(DFMECA!P3:P1024=4))} -> 0 | Q39: {=SUMPRODUCT(--(DFMECA!M3:M1024=5),--(DFMECA!P3:P1024=5))} -> 5
C40: 4 | D40: =C40*$D$44 -> 4 | E40: =C40*$E$44 -> 8 | F40: =C40*$F$44 -> 12 | G40: =C40*$G$44 -> 16 | H40: =C40*$H$44 -> 20 | L40: 4 | M40: {=SUMPRODUCT(--(DFMECA!M3:M1024=4),--(DFMECA!P3:P1024=1))} -> 10 | N40: {=SUMPRODUCT(--(DFMECA!M3:M1024=4),--(DFMECA!P3:P1024=2))} -> 96 | O40: {=SUMPRODUCT(--(DFMECA!M3:M1024=4),--(DFMECA!P3:P1024=3))} -> 0 | P40: {=SUMPRODUCT(--(DFMECA!M3:M1024=4),--(DFMECA!P3:P1024=4))} -> 0 | Q40: {=SUMPRODUCT(--(DFMECA!M3:M1024=4),--(DFMECA!P3:P1024=5))} -> 36
C41: 3 | D41: =C41*$D$44 -> 3 | E41: =C41*$E$44 -> 6 | F41: =C41*$F$44 -> 9 | G41: =C41*$G$44 -> 12 | H41: =C41*$H$44 -> 15 | L41: 3 | M41: {=SUMPRODUCT(--(DFMECA!M3:M1024=3),--(DFMECA!P3:P1024=1))} -> 0 | N41: {=SUMPRODUCT(--(DFMECA!M3:M1024=3),--(DFMECA!P3:P1024=2))} -> 0 | O41: {=SUMPRODUCT(--(DFMECA!M3:M1024=3),--(DFMECA!P3:P1024=3))} -> 0 | P41: {=SUMPRODUCT(--(DFMECA!M3:M1024=3),--(DFMECA!P3:P1024=4))} -> 0 | Q41: {=SUMPRODUCT(--(DFMECA!M3:M1024=3),--(DFMECA!P3:P1024=5))} -> 77
C42: 2 | D42: =C42*$D$44 -> 2 | E42: =C42*$E$44 -> 4 | F42: =C42*$F$44 -> 6 | G42: =C42*$G$44 -> 8 | H42: =C42*$H$44 -> 10 | L42: 2 | M42: {=SUMPRODUCT(--(DFMECA!M3:M1024=2),--(DFMECA!P3:P1024=1))} -> 79 | N42: {=SUMPRODUCT(--(DFMECA!M3:M1024=2),--(DFMECA!P3:P1024=2))} -> 76 | O42: {=SUMPRODUCT(--(DFMECA!M3:M1024=2),--(DFMECA!P3:P1024=3))} -> 0 | P42: {=SUMPRODUCT(--(DFMECA!M3:M1024=2),--(DFMECA!P3:P1024=4))} -> 0 | Q42: {=SUMPRODUCT(--(DFMECA!M3:M1024=2),--(DFMECA!P3:P1024=5))} -> 292
C43: 1 | D43: =C43*$D$44 -> 1 | E43: =C43*$E$44 -> 2 | F43: =C43*$F$44 -> 3 | G43: =C43*$G$44 -> 4 | H43: =C43*$H$44 -> 5 | L43: 1 | M43: {=SUMPRODUCT(--(DFMECA!M3:M1024=1),--(DFMECA!P3:P1024=1))} -> 1 | N43: {=SUMPRODUCT(--(DFMECA!M3:M1024=1),--(DFMECA!P3:P1024=2))} -> 1 | O43: {=SUMPRODUCT(--(DFMECA!M3:M1024=1),--(DFMECA!P3:P1024=3))} -> 0 | P43: {=SUMPRODUCT(--(DFMECA!M3:M1024=1),--(DFMECA!P3:P1024=4))} -> 0 | Q43: {=SUMPRODUCT(--(DFMECA!M3:M1024=1),--(DFMECA!P3:P1024=5))} -> 308
D44: 1 | E44: 2 | F44: 3 | G44: 4 | H44: 5 | M44: 1 | N44: 2 | O44: 3 | P44: 4 | Q44: 5
D45: Detection | M45: Detection
L47: Total risks: | Q47: =SUM(M19:M43)+SUM(N19:N43)+SUM(O19:O43)+SUM(P19:P43)+SUM(Q19:Q43) -> 993
L48: Total risks require mitigation based on S x O x D: | Q48: =N19+SUM(O19:O27)+SUM(P19:P31)+SUM(Q19:Q34) -> 0

Sheet S-O-D Definitions
B2: Severity, or Consequence Evaluation Criteria: Worst Case Evaluation of Failure Mode | G2: Occurrence: Probability of occurrence within the product life based on the design as is exists today
B3: Score | C3: Criteria | D3: Notes | E3: Example | G3: Score | H3: Notes | I3: Probability Description | J3: Probability
B4: 5 | C4: Failure causes death or causes transmission line open circuit, full or partial fault protection compromised. | D4: Extremely hazardous failure, threatening to business continuity. | E4: Fault detection mechanism failure . IGBT shorting the capacitor bank. Power to one or more SCR driver boards discontinued while unit is in injection mode. Mechanical failure causing line to open. | G4: 5 | H4: Very high probability | I4: 1 in 10 or greater | J4: 0.1 ≤ Po
B5: 4 | C5: Failure causes severe injury to personnel requiring hospitalization, severe property damage such as damage to a structure, transmission line damage, major damage to system other than transmission line requiring immediate interruption of line service, loss of control of SmartValve v1.04 when in Injection Mode, device is forced to monitoring mode, with reduced fault protection (i.e. redundancy compromised). | D5: Highly hazardous failure, threatening to business reputation. | E5: iiDCE RF communication loss in injection mode. iiDCE losing control of SCRs. | G5: 4 | H5: High probability | I5: 1 in 100 or greater | J5: 0.01 ≤ Po < 0.1
B6: 3 | C6: Failure causes minor injury to personnel requiring out-patient treatment, moderate property damage not involving a structure, moderate system damage other than transmission line that requires future interruption of line service to repair, loss of control of SmartValve v1.04 when in Monitoring Mode, device is forced to monitoring mode with full fault protection available. | D6: Moderately hazardous failure, threatening to product reputation. | E6: iiDCE RF communication loss in monitoring mode. Any control boards' failure, forcing device to monitoring mode. Mechanical failure causing enclosure temperature to rise, forcing device to stay in monitoring mode. | G6: 3 | H6: Moderate probability | I6: 1 in 1,000 or greater | J6: 0.001 ≤ Po < 0.01
B7: 2 | C7: Failure causes minor property damage, minor system damage other than primary conductor or loss of SmartValve v1.04 such as loss of performance, unit forced into Monitoring Mode, or significant impact on unit life | D7: Minor hazard, minor consequence. | E7: Rise in on-board power losses, impacting components' life, Clamp board feedback not available. | G7: 2 | H7: Low probability | I7: 1 in 10,000 or greater | J7: 0.0001 ≤ Po < 0.001
B8: 1 | C8: Failure causes unscheduled maintenance, no immediate loss of performance. | D8: No hazard. | E8: On-board noise filtration compromised. One of many bolts failure. | G8: 1 | H8: Remote probability | I8: Less than 1 in 10,000 | J8: Po < 0.0001
B10: Detection: Likelihood of failure mode detection by design | I10: Target product life for the purposes of this FMECA is 40 years.
B11: Score | C11: Description | D11: Criteria | E11: Definition
B12: 5 | C12: Very remote probability to absolute uncertainty of detection | D12: Design will not and/or cannot detect the potential cause/mechanism or subsequent failure mode, or the likelihood of detection is very remote. | E12: PD < 0.1 | G12: RPN Conditions | H12: Color
B13: 4 | C13: Very low to remote probability of detection | D13: Design has a very low to remote likelihood of detecting the potential cause/mechanism or subsequent failure mode. | E13: 0.1 ≤ PD < 0.5 | G13: Value ≥ 70
B14: 3 | C14: Moderate to low probability of detection | D14: Design has a moderate to low likelihood of detecting the potential cause/mechanism or subsequent failure mode. | E14: 0.5 ≤ PD < 0.95 | G14: 70 > Value ≥ 60
B15: 2 | C15: High to moderately high probability of detection | D15: Design has a high to moderately high likelihood of detecting the potential cause/mechanism or subsequent failure mode. | E15: 0.95 ≤ PD < 0.995 | G15: 60 > Value ≥ 50
B16: 1 | C16: Almost certain to very high probability of detection | D16: Design has an almost certain chance of detecting the potential cause/mechanism or subsequent failure mode or the likelihood of detection is very high. | E16: 0.995 ≤ PD | G16: Value < 50
C50: Review Status
C51: Approved
C52: Reviewed by QA
C53: Review Pending

Sheet Design-Traceability
B2: Design Traceability
B3: Sr. | C3: Design Artifact | D3: Rev | E3: Link
B5: 1 | C5: SmartValve 10-1800 v1.04 - Wiring Drawing - Bypass Section Harnesses Diagram | D5: 2 | E5: Box Link
B6: 2 | C6: SmartValve 10-1800 v1.04 - Wiring Drawing - MVAR Section Harnesses Diagram | D6: 2 | E6: Box Link
B7: 3 | C7: SmartValve 10-1800 v1.04 - Wiring Drawing - PHT Shorting and Capacitor Voltage Measurement Blocks | D7: 2 | E7: Box Link
B8: 4 | C8: SmartValve 10-1800 v1.04 - Wiring Drawing - Power Supply Scheme Gen2-v2-FAI | D8: 2 | E8: Box Link
B9: 5 | C9: SmartValve 10-1800 v1.04 - PCBAs - HV-ISO XFMR Board Functional Block Diagram | D9: 3 | E9: Box Link
B10: 6 | C10: SmartValve 10-1800 v1.04 - PCBAs - HV-ISO XFMR Board Schematic | D10: 3 | E10: Box Link
B11: 7 | C11: SmartValve 10-1800 v1.04 - PCBAs - HV-ISO XFMR Board Design Document | D11: A | E11: Box Link

Sheet Power Supply - Architecture

Sheet Bypass - Architecture

Sheet MVAr - Architecture

Sheet Functional Block Diagram 

Sheet DFMECA
A1: ID. | B1: Component | C1: Reference Designator | D1: Functional Requirement | E1: Potential Failure Mode | F1: Potential Effect(s) of Failure | I1: Severity Score | J1: Potential Causes / Triggers of Failure | K1: Failure Safeguards | L1: Occurrence Score | M1: S x O | N1: Existing Conditions | Q1: RPN (S x O x D) | R1: Alert Message | S1: Alert Message | T1: Recommended Action(s) / Remarks | U1: Reporting Team Member | V1: Target Completion Date | W1: Action Results | AB1: Status
F2: Local - Effect at the sub assembly or component level | G2: Higher Level - Effect at SmartValve v1.04 | H2: End - Effect at System Level | N2: Verification & Validation Method | O2: Detection Method | P2: Detection Score | W2: Actions Taken | X2: Severity Score | Y2: Occurrence Score | Z2: Detection Score | AA2: New RPN
B3: HV Transformer Board Rev3 (P112469) | AD3: =VALUE(RIGHT((IF(A3="",0,A3)),5)) -> 0
B4: HV Transformer Board for one iSCR Driver Board | AD4: =VALUE(RIGHT((IF(A4="",0,A4)),5)) -> 0
B5: 15 V On-Board Supply | AD5: =VALUE(RIGHT((IF(A5="",0,A5)),5)) -> 0
A6: SV104-10917 | B6: Input Side Connector | C6: J3 | D6: Input supply from PHTDC | E6: Connector Disconnected by external Force. | F6: Input power path will be broken. No output available at HV transformer board. | G6: iSCR driver board will still receive power from redundant HVT board. Device can operate in both monitoring and injection mode. | H6: System will keep working normally. | I6: 2 | J6: Open Connections due to vibrations, mis-handling or mechanical stress. De-gradation of components. | K6: Using components with industrial grade scale. Choosing components with enough FIT rate to fulfil the product life requirements. Redundant HV Transformer board to power-up iSCR driver board. | L6: 1 | M6: =I6*L6 -> 2 | N6: HALT. Electrical Stress Testing. Thermal Stress Testing. Vibration Testing. | O6: None. | P6: 5 | Q6: =I6*L6*P6 -> 10 | AA6: =X6*Y6*Z6 -> 0 | AD6: =VALUE(RIGHT((IF(A6="",0,A6)),5)) -> 10917
A7: SV104-10918 | E7: Connection Loose or Sparking at terminals | F7: Due to sparking connector will heat up and eventually burnout | G7: iSCR driver board will still receive power from redundant HVT board. Device can operate in both monitoring and injection mode. | H7: System will keep working normally. | I7: 2 | J7: Open Connections due to vibrations, mis-handling or mechanical stress. De-gradation of components. | K7: Using components with industrial grade scale. Choosing components with enough FIT rate to fulfil the product life requirements. Redundant HV Transformer board to power-up iSCR driver board. | L7: 1 | M7: =I7*L7 -> 2 | N7: HALT. Electrical Stress Testing. Thermal Stress Testing. Vibration Testing. | O7: None. | P7: 5 | Q7: =I7*L7*P7 -> 10 | AA7: =X7*Y7*Z7 -> 0 | AD7: =VALUE(RIGHT((IF(A7="",0,A7)),5)) -> 10918
A8: SV104 - 5158 | B8: Input Side TRIACs. | C8: D13,D12 | D8: Reverse polarity protection. | E8: TRIAC fails-open. | F8: No immediate effect. Board will keep working, but it is going to increase some level of stress on other components which will have an impact in longer run(Years). Board life is going to be impacted. Parallel TRIAC available for alternate path. | G8: If no other failure is observed on the board, iSCR driver board will stay powered. Device can operate in both monitoring and injection mode. | H8: System will keep working normally. | I8: 1 | J8: Excessive forward current. Open Connections due to vibrations, mis-handling or mechanical stress. De-gradation of components. | K8: Using components with industrial grade scale. Choosing components with enough FIT rate to fulfil the product life requirements. Redundant HV Transformer board to power-up iSCR driver board. | L8: 1 | M8: =I8*L8 -> 1 | N8: HALT. Electrical Stress Testing. Thermal Stress Testing. Vibration Testing. | O8: None. | P8: 5 | Q8: =I8*L8*P8 -> 5 | AA8: =X8*Y8*Z8 -> 0 | AD8: =VALUE(RIGHT((IF(A8="",0,A8)),5)) -> 5158
A9: SV104 - 5159 | E9: TRIAC fails-short. | F9: Reverse polarity protection will be compromised during shortage. Board will keep working normally if input is provided with correct polarity. | G9: If no other failure is observed on the board, iSCR driver board will stay powered. Device can operate in both monitoring and injection mode. | H9: System will keep working normally. | I9: 1 | J9: Large reverse voltage. De-gradation of components. | K9: Using components with industrial grade scale. Choosing components with enough FIT rate to fulfil the product life requirements. Redundant HV Transformer board to power-up iSCR driver board. | L9: 1 | M9: =I9*L9 -> 1 | N9: HALT. Electrical Stress Testing. Thermal Stress Testing. | O9: None. | P9: 5 | Q9: =I9*L9*P9 -> 5 | AD9: =VALUE(RIGHT((IF(A9="",0,A9)),5)) -> 5159
A10: SV104 - 6736 | E10: Both TRIACs fail-short. | F10: Reverse polarity protection will be compromised. Board will keep working normally if input is provided with correct polarity. | G10: If no other failure is observed on the board, iSCR driver board will stay powered. Device can operate in both monitoring and injection mode. | H10: System will keep working normally. | I10: 1 | J10: Large reverse voltage. De-gradation of components. | K10: Using components with industrial grade scale. Choosing components with enough FIT rate to fulfil the product life requirements. Redundant HV Transformer board to power-up iSCR driver board. | L10: 1 | M10: =I10*L10 -> 1 | N10: HALT. Electrical Stress Testing. Thermal Stress Testing. | O10: None. | P10: 5 | Q10: =I10*L10*P10 -> 5 | AD10: =VALUE(RIGHT((IF(A10="",0,A10)),5)) -> 6736
A11: SV104 - 6737 | E11: Both TRIACs fail-open | F11: Input path will be broken. No output available at HV transformer board. . | G11: iSCR driver board will still receive power from redundant HVT board. Device can operate in both monitoring and injection mode. | H11: System will keep working normally. | I11: 2 | J11: Excessive forward current. Open Connections due to vibrations, mis-handling or mechanical stress. De-gradation of components. | K11: Using components with industrial grade scale. Choosing components with enough FIT rate to fulfil the product life requirements. Redundant HV Transformer board to power-up iSCR driver board. | L11: 1 | M11: =I11*L11 -> 2 | N11: HALT. Electrical Stress Testing. Thermal Stress Testing. Vibration Testing. | O11: None. | P11: 5 | Q11: =I11*L11*P11 -> 10 | AD11: =VALUE(RIGHT((IF(A11="",0,A11)),5)) -> 6737
A12: SV104 - 5160 | B12: Input Side Fuse. | C12: F2 | D12: To cut-off supply in case of over-current. | E12: Fuse fails-open. | F12: Input power path will be broken. No output available at HV transformer board. | G12: iSCR driver board will still receive power from redundant HVT board. Device can operate in both monitoring and injection mode. | H12: System will keep working normally. | I12: 2 | J12: On-board fault causing higher current flow. De-gradation of components. Open Connections due to vibrations, mis-handling or mechanical stress. | K12: Using components with industrial grade scale. Choosing components with enough FIT rate to fulfil the product life requirements. Redundant HV Transformer board to power-up iSCR driver board. | L12: 1 | M12: =I12*L12 -> 2 | N12: HALT. Electrical Stress Testing. Thermal Stress Testing. Vibration Testing. | O12: None. | P12: 5 | Q12: =I12*L12*P12 -> 10 | AA12: =X12*Y12*Z12 -> 0 | AD12: =VALUE(RIGHT((IF(A12="",0,A12)),5)) -> 5160
A13: SV104 - 5161 | B13: Input Side Filter Capacitors. | C13: C2,C23 | D13: To suppress ripples on input voltage. | E13: Capacitor fails-open. | F13: Input supply ripples may cause distorted output supply. No immediate effect on board.. | G13: If no other failure is observed on the board, iSCR driver board will stay powered. Device can operate in both monitoring and injection mode. | H13: System will keep working normally. | I13: 1 | J13: Mechanical stress. Localized heating for long time will separate end connection of capacitor. | K13: Using components with industrial grade scale. Choosing components with enough FIT rate to fulfil the product life requirements. Redundant HV Transformer board to power-up iSCR driver board. | L13: 1 | M13: =I13*L13 -> 1 | N13: HALT. Electrical Stress Testing. Thermal Stress Testing. Vibration Testing. | O13: None. | P13: 5 | Q13: =I13*L13*P13 -> 5 | AA13: =X13*Y13*Z13 -> 0 | AD13: =VALUE(RIGHT((IF(A13="",0,A13)),5)) -> 5161
A14: SV104 - 5162 | E14: Capacitor fails-short. | F14: PHT-DC Capacitor will dump full energy in HV-ISO board leaving it permanently damage (Trace damage). No output available at HV transformer board. | G14: iSCR driver board will still receive power from redundant HVT board. Device can operate in both monitoring and injection mode. | H14: System will keep working normally. | I14: 2 | J14: Wear-out due to dielectric degradation. High-voltage transients. De-gradation of components. Water ingress during humidity condition as it is film capacitor. Overvoltage | K14: Using components with industrial grade scale. Choosing components with enough FIT rate to fulfil the product life requirements. RTV application on edges to stop water ingress. Redundant HV Transformer board to power-up iSCR driver board. | L14: 1 | M14: =I14*L14 -> 2 | N14: HALT. Electrical Stress Testing. Thermal Stress Testing. Environmental Testing. | O14: None. | P14: 5 | Q14: =I14*L14*P14 -> 10 | AD14: =VALUE(RIGHT((IF(A14="",0,A14)),5)) -> 5162
A15: SV104 - 5163 | B15: Low Voltage Detection Zener Diode. (D7, D11, D10) | C15: D7,D10,D11 | D15: To set under-voltage lockout threshold. | E15: Diode fails-open. | F15: No voltage will be available at power controlling MOSFET gate. On-board 15 V supply will not be available. No output available at HV transformer board. | G15: iSCR driver board will still receive power from redundant HVT board. Device can operate in both monitoring and injection mode. | H15: System will keep working normally. | I15: 2 | J15: Mechanical stress or impact during assembly. Overcurrent. De-gradation of components. | K15: Using components with industrial grade scale. Choosing components with enough FIT rate to fulfil the product life requirements. Redundant HV Transformer board to power-up iSCR driver board. | L15: 2 | M15: =I15*L15 -> 4 | N15: HALT. Electrical Stress Testing. Thermal Stress Testing. | O15: None. | P15: 5 | Q15: =I15*L15*P15 -> 20 | AA15: =X15*Y15*Z15 -> 0 | AD15: =VALUE(RIGHT((IF(A15="",0,A15)),5)) -> 5163
A16: SV104 - 5164 | E16: Diode fails-short.. | F16: The threshold for UVLO detection will decrease. Board will turn on before the set threshold of 320 V. Slight effect will be on PHT-DC bus during low line current condition as it will ramp up slowly. Board will keep working. | G16: If no other failure is observed on the board, iSCR driver board will stay powered. Device can operate in both monitoring and injection mode. | H16: System will keep working normally. | I16: 2 | J16: Excessive Temperature. High reverse voltage. De-gradation of components. | K16: Using components with industrial grade scale. Choosing components with enough FIT rate to fulfil the product life requirements. Redundant HV Transformer board to power-up iSCR driver board. | L16: 2 | M16: =I16*L16 -> 4 | N16: HALT. Electrical Stress Testing. Thermal Stress Testing. | O16: None. | P16: 5 | Q16: =P16*L16*I16 -> 20 | AD16: =VALUE(RIGHT((IF(A16="",0,A16)),5)) -> 5164
A17: SV104-10919 | B17: Low Voltage Detection Voltage Divider | C17: R41,R36 | D17: To set UVLO threshold | E17: Resistor fails-open. | F17: No voltage will be available at power controlling MOSFET gate. On-board 15 V supply will not be available. No output available at HV transformer board. | G17: iSCR driver board will still receive power from redundant HVT board. Device can operate in both monitoring and injection mode. | H17: System will keep working normally. | I17: 2 | J17: Over voltage. Over Temperature. Over stress due to shock or vibration. De-gradation of components. | K17: Using components with industrial grade scale. Choosing components with enough FIT rate to fulfil the product life requirements. Redundant HV Transformer board to power-up iSCR driver board. | L17: 1 | M17: =I17*L17 -> 2 | N17: HALT. Electrical Stress Testing. Thermal Stress Testing. Vibration testing. | O17: None. | P17: 5 | Q17: =P17*L17*I17 -> 10 | AD17: =VALUE(RIGHT((IF(A17="",0,A17)),5)) -> 10919
A18: SV104-10920 | E18: Resistor fails-short. | F18: UVLO limit will decrease ,no major effect. Board will powerup at few volts lesser voltage. Board will keep working. | G18: If no other failure is observed on the board, iSCR driver board will stay powered. Device can operate in both monitoring and injection mode. | H18: System will keep working normally. | I18: 1 | J18: Wear-out due to extensive use. Excessive humidity. De-gradation of components. | K18: Using components with industrial grade scale. Choosing components with enough FIT rate to fulfil the product life requirements. Redundant HV Transformer board to power-up iSCR driver board. | L18: 1 | M18: =I18*L18 -> 1 | N18: HALT. Electrical Stress Testing. Thermal Stress Testing. Vibration testing. | O18: None. | P18: 5 | Q18: =P18*L18*I18 -> 5 | AD18: =VALUE(RIGHT((IF(A18="",0,A18)),5)) -> 10920
A19: SV104 - 5165 | B19: Input Side Voltage Divider Resistor. | C19: R30,R31,R32,R33,R34,R35 | D19: To step down voltage. | E19: Resistor fails-open. | F19: No voltage will be available at power controlling MOSFET gate. On-board 15 V supply will not be available. No output available at HV transformer board. | G19: iSCR driver board will still receive power from redundant HVT board. Device can operate in both monitoring and injection mode. | H19: System will keep working normally. | I19: 2 | J19: Over Temperature. Over stress due to shock or vibration. De-gradation of components. Overcurrent. Counterfeit part. | K19: Using components with industrial grade scale. Choosing components with enough FIT rate to fulfil the product life requirements. Redundant HV Transformer board to power-up iSCR driver board. | L19: 1 | M19: =I19*L19 -> 2 | N19: HALT. Electrical Stress Testing. Thermal Stress Testing. Vibration testing. | O19: None. | P19: 5 | Q19: =I19*L19*P19 -> 10 | AD19: =VALUE(RIGHT((IF(A19="",0,A19)),5)) -> 5165
A20: SV104 - 5166 | E20: Any one resistor fails-short. | F20: No immediate effect on board. Board will keep working normally. | G20: iSCR driver board will still receive power from redundant HVT board. Device can operate in both monitoring and injection mode. | H20: System will keep working normally. | I20: 1 | J20: Wear-out due to extensive use. Excessive humidity. Counterfeit part. De-gradation of components. | K20: Using components with industrial grade scale. Choosing components with enough FIT rate to fulfil the product life requirements. Conformal coating. Redundant HV Transformer board to power-up iSCR driver board. | L20: 1 | M20: =I20*L20 -> 1 | N20: HALT. Electrical Stress Testing. Thermal Stress Testing. Vibration testing. | O20: None. | P20: 5 | Q20: =I20*L20*P20 -> 5 | AD20: =VALUE(RIGHT((IF(A20="",0,A20)),5)) -> 5166
A21: SV104 - 12377 | E21: More than one resistors fails-short. | F21: Soft starting current is increased significantly consequently MOSFET power dissipation will increase that could bring failure. No output available at HV transformer board. | G21: iSCR driver board will still receive power from redundant HVT board. Device can operate in both monitoring and injection mode. | H21: System will keep working normally. | I21: 2 | J21: Wear-out due to extensive use. Excessive humidity. Counterfeit part. De-gradation of components. | K21: Using components with industrial grade scale. Choosing components with enough FIT rate to fulfil the product life requirements.. Conformal coating. | L21: 1 | M21: =I21*L21 -> 2 | N21: HALT. Electrical Stress Testing. Thermal Stress Testing. Vibration testing. | O21: None. | P21: 5 | Q21: =I21*L21*P21 -> 10 | AD21: =VALUE(RIGHT((IF(A21="",0,A21)),5)) -> 12377
A22: SV104 - 5167 | B22: Input Power Control MOSFET. | C22: Q6 | D22: To turn ON/OFF power flow. | E22: MOSFET fails-open. | F22: Input power path will be broken. No output available at HV transformer board. | G22: iSCR driver board will still receive power from redundant HVT board. Device can operate in both monitoring and injection mode. | H22: System will keep working normally. | I22: 2 | J22: Overheating Mechanical stress resulting in cracked MOSFET body. | K22: Using components with industrial grade scale. Choosing components with enough FIT rate to fulfil the product life requirements. Redundant HV Transformer board to power-up iSCR driver board. | L22: 1 | M22: =I22*L22 -> 2 | N22: HALT. Electrical Stress Testing. Thermal Stress Testing. | O22: None. | P22: 5 | Q22: =I22*L22*P22 -> 10 | AA22: =X22*Y22*Z22 -> 0 | AD22: =VALUE(RIGHT((IF(A22="",0,A22)),5)) -> 5167
A23: SV104 - 5168 | E23: MOSFET fails-short. | F23: Startup circuitry will turn on permanently resulting in overheating and permanently damage to startup resistor. No output available once HV-ISO reboot. | G23: iSCR driver board will still receive power from redundant HVT board. Device can operate in both monitoring and injection mode. | H23: System will keep working normally. | I23: 2 | J23: Transients Overheating as a result of loose connection with heat sink Overcurrent Counterfeit part Damage during mechanical assembly of board Metallic debris stuck in between terminals | K23: Using components with industrial grade scale. Choosing components with enough FIT rate to fulfil the product life requirements. Redundant HV Transformer board to power-up iSCR driver board. | L23: 1 | M23: =I23*L23 -> 2 | N23: HALT. Electrical Stress Testing. Thermal Stress Testing. | O23: None. | P23: 5 | Q23: =I23*L23*P23 -> 10 | AD23: =VALUE(RIGHT((IF(A23="",0,A23)),5)) -> 5168
A24: SV104 - 5169 | B24: Over-voltage Protection Zener Diode at MOSFET Gate Side. | C24: D31 | D24: For gate protection of MOSFET. | E24: Diode fails-open. | F24: Over-voltage protection of MOSFET won't be available. No immediate effect on board in normal operations. | G24: If no other failure is observed on the board, iSCR driver board will stay powered. Device can operate in both monitoring and injection mode. | H24: System will keep working normally. | I24: 1 | J24: Mechanical stress or impact during assembly. Overcurrent. De-gradation of components. | K24: Usage of over-rated components. Using components with industrial grade scale. Choosing components with enough FIT rate to fulfil the product life requirements. | L24: 2 | M24: =I24*L24 -> 2 | N24: HALT. Electrical Stress Testing. Thermal Stress Testing. | O24: None. | P24: 5 | Q24: =I24*L24*P24 -> 10 | AA24: =X24*Y24*Z24 -> 0 | AD24: =VALUE(RIGHT((IF(A24="",0,A24)),5)) -> 5169
A25: SV104 - 5170 | E25: Diode fails-short. | F25: MOSFET will be turned off completely. Startup circuit will not work. No output available at HV transformer board. | G25: iSCR driver board will still receive power from redundant HVT board. Device can operate in both monitoring and injection mode. | H25: System will keep working normally. | I25: 2 | J25: Large reverse voltage. De-gradation of components. | K25: Usage of over-rated components. Using components with industrial grade scale. Choosing components with enough FIT rate to fulfil the product life requirements. | L25: 2 | M25: =I25*L25 -> 4 | N25: HALT. Electrical Stress Testing. Thermal Stress Testing. | O25: None. | P25: 5 | Q25: =I25*L25*P25 -> 20 | AD25: =VALUE(RIGHT((IF(A25="",0,A25)),5)) -> 5170
A26: SV104-12378 | B26: Filtration Capacitor | C26: C21 | D26: To suppress noise and remove ripples | E26: Capacitor fails-open. | F26: No immediate effect on board. Board will keep working normally. | G26: If no other failure is observed on the board, iSCR driver board will stay powered. Device can operate in both monitoring and injection mode. | H26: System will keep working normally. | I26: 1 | J26: Mechanical stress. Localized heating for long time will separate end connection of capacitor. | K26: Using components with industrial grade scale. Choosing components with enough FIT rate to fulfil the product life requirements. Redundant HV Transformer board to power-up iSCR driver board. | L26: 1 | M26: =I26*L26 -> 1 | N26: HALT. Electrical Stress Testing. Thermal Stress Testing. Vibration Testing. | O26: None. | P26: 5 | Q26: =I26*L26*P26 -> 5 | AD26: =VALUE(RIGHT((IF(A26="",0,A26)),5)) -> 12378
A27: SV104-12379 | E27: Capacitor fails-short. | F27: HVDC and 24VAUX will be shorted top ground. Startup circuit will not work. Input Fuse Will be Blown No output available at HV transformer board. | G27: iSCR driver board will still receive power from redundant HVT board. Device can operate in both monitoring and injection mode. | H27: System will keep working normally. | I27: 2 | J27: Wear-out due to dielectric degradation. High-voltage transients. De-gradation of components. Water ingress during humidity condition as it is film capacitor. Overvoltage | K27: Using components with industrial grade scale. Choosing components with enough FIT rate to fulfil the product life requirements. RTV application on edges to stop water ingress. Redundant HV Transformer board to power-up iSCR driver board. | L27: 1 | M27: =I27*L27 -> 2 | N27: HALT. Electrical Stress Testing. Thermal Stress Testing. Environmental Testing. | O27: None. | P27: 5 | Q27: =I27*L27*P27 -> 10 | AD27: =VALUE(RIGHT((IF(A27="",0,A27)),5)) -> 12379
A28: SV104-10921 | B28: MOSFET resistance for Miller Capacitance | C28: R37 | D28: To discharge miller capacitance of MOSFET | E28: Resistor fails-open | F28: Abnormal Behavior of MOSFET Might turn ON/OFF abnormally can damage startup circuitry if MOSFET remains on for longer duration. No output available at HV transformer board | G28: iSCR driver board will still receive power from redundant HVT board. Device can operate in both monitoring and injection mode. | H28: System will keep working normally. | I28: 2 | J28: Over voltage. Over Temperature. Over stress due to shock or vibration. De-gradation of components. | K28: Using components with industrial grade scale. Choosing components with enough FIT rate to fulfil the product life requirements. Redundant HV Transformer board to power-up iSCR driver board. | L28: 1 | M28: =I28*L28 -> 2 | N28: HALT. Electrical Stress Testing. Thermal Stress Testing. Vibration testing. | O28: None. | P28: 5 | Q28: =P28*L28*I28 -> 10 | AD28: =VALUE(RIGHT((IF(A28="",0,A28)),5)) -> 10921
A29: SV104-10922 | E29: Resistor fails-short | F29: Gate and Source of Q6 will have no voltage difference so MOSFET cannot operate No output available at HV transformer board | G29: iSCR driver board will still receive power from redundant HVT board. Device can operate in both monitoring and injection mode. | H29: System will keep working normally. | I29: 2 | J29: Wear-out due to extensive use. Excessive humidity. De-gradation of components. | K29: Using components with industrial grade scale. Choosing components with enough FIT rate to fulfil the product life requirements. Redundant HV Transformer board to power-up iSCR driver board. | L29: 1 | M29: =I29*L29 -> 2 | N29: HALT. Electrical Stress Testing. Thermal Stress Testing. Vibration testing. | O29: None. | P29: 5 | Q29: =P29*L29*I29 -> 10 | AD29: =VALUE(RIGHT((IF(A29="",0,A29)),5)) -> 10922
A30: SV104 - 6738 | B30: D21-Free wheeling diode | C30: D21 | D30: To protect BJT during reverse voltage condition | E30: Diode fails-open. | F30: No protection for BJT will be available. Reverse voltage development across BJT will damage it. No output available. | G30: iSCR driver board will still receive power from redundant HVT board. Device can operate in both monitoring and injection mode. | H30: System will keep working normally. | I30: 2 | J30: Mechanical stress or impact during assembly. Overcurrent. De-gradation of components. | K30: Using components with industrial grade scale. Choosing components with enough FIT rate to fulfil the product life requirements. Redundant HV Transformer board to power-up iSCR driver board. | L30: 1 | M30: =I30*L30 -> 2 | N30: HALT. Electrical Stress Testing. Thermal Stress Testing. | O30: None. | P30: 5 | Q30: =I30*L30*P30 -> 10 | AD30: =VALUE(RIGHT((IF(A30="",0,A30)),5)) -> 6738
A31: SV104 - 6739 | E31: Diode fails-short. | F31: Input will appear as it is on output which will damage PWM controller and gate driver ICs permanently. No output available. | G31: iSCR driver board will still receive power from redundant HVT board. Device can operate in both monitoring and injection mode. | H31: System will keep working normally. | I31: 2 | J31: Large reverse voltage. De-gradation of components. | K31: Using components with industrial grade scale. Choosing components with enough FIT rate to fulfil the product life requirements. Redundant HV Transformer board to power-up iSCR driver board. | L31: 1 | M31: =I31*L31 -> 2 | N31: HALT. Electrical Stress Testing. Thermal Stress Testing. | O31: None. | P31: 5 | Q31: =I31*L31*P31 -> 10 | AD31: =VALUE(RIGHT((IF(A31="",0,A31)),5)) -> 6739
A32: SV104 - 6740 | B32: D22-To prevent reverse power flow | C32: D22 | D32: To prevent reverse power flow from auxiliary to startup circuitry | E32: Diode fails-open. | F32: Input power path will be broken. No output available at HV transformer board. | G32: iSCR driver board will still receive power from redundant HVT board. Device can operate in both monitoring and injection mode. | H32: System will keep working normally. | I32: 2 | J32: Mechanical stress or impact during assembly. Overcurrent. De-gradation of components. | K32: Using components with industrial grade scale. Choosing components with enough FIT rate to fulfil the product life requirements. Redundant HV Transformer board to power-up iSCR driver board. | L32: 1 | M32: =I32*L32 -> 2 | N32: HALT. Electrical Stress Testing. Thermal Stress Testing. | O32: None. | P32: 5 | Q32: =P32*L32*I32 -> 10 | AD32: =VALUE(RIGHT((IF(A32="",0,A32)),5)) -> 6740
A33: SV104 - 6741 | E33: Diode fails-short. | F33: If the board is OFF than it can not turn ON. If board is ON than reverse power will start to flow. D31 will be forward biased and as gate of Q6 is grounded than 24VAUX will also be grounded. No output available at HV transformer board. | G33: iSCR driver board will still receive power from redundant HVT board. Device can operate in both monitoring and injection mode. | H33: System will keep working normally. | I33: 2 | J33: Large reverse voltage. De-gradation of components. | K33: Using components with industrial grade scale. Choosing components with enough FIT rate to fulfil the product life requirements. Redundant HV Transformer board to power-up iSCR driver board. | L33: 1 | M33: =I33*L33 -> 2 | N33: HALT. Electrical Stress Testing. Thermal Stress Testing. | O33: None. | P33: 5 | Q33: =P33*L33*I33 -> 10 | AD33: =VALUE(RIGHT((IF(A33="",0,A33)),5)) -> 6741
A34: SV104 - 6742 | B34: D27-Zener diode | C34: D27 | D34: To set reference voltage for BJT to regulate | E34: Diode fails-open. | F34: Voltage at input will appear as it is on base damaging it permanently. No output available at HV transformer board. | G34: iSCR driver board will still receive power from redundant HVT board. Device can operate in both monitoring and injection mode. | H34: System will keep working normally. | I34: 2 | J34: Mechanical stress or impact during assembly. Overcurrent. De-gradation of components. | K34: Using components with industrial grade scale. Choosing components with enough FIT rate to fulfil the product life requirements. Redundant HV Transformer board to power-up iSCR driver board. | L34: 2 | M34: =I34*L34 -> 4 | N34: HALT. Electrical Stress Testing. Thermal Stress Testing. | O34: None. | P34: 5 | Q34: =I34*L34*P34 -> 20 | AD34: =VALUE(RIGHT((IF(A34="",0,A34)),5)) -> 6742
A35: SV104 - 6743 | E35: Diode fails-short. | F35: BJT will not turn on. No output available at HV transformer board. | G35: iSCR driver board will still receive power from redundant HVT board. Device can operate in both monitoring and injection mode. | H35: System will keep working normally. | I35: 2 | J35: Large reverse voltage. De-gradation of components. | K35: Using components with industrial grade scale. Choosing components with enough FIT rate to fulfil the product life requirements. Redundant HV Transformer board to power-up iSCR driver board. | L35: 2 | M35: =I35*L35 -> 4 | N35: HALT. Electrical Stress Testing. Thermal Stress Testing. | O35: None. | P35: 5 | Q35: =I35*L35*P35 -> 20 | AD35: =VALUE(RIGHT((IF(A35="",0,A35)),5)) -> 6743
A36: SV104 - 5171 | B36: Input Power Control BJT. | C36: Q8 | D36: To provide regulated voltage for startup. | E36: BJT fails-open. | F36: Input power path will be broken. No output available at HV transformer board. | G36: iSCR driver board will still receive power from redundant HVT board. Device can operate in both monitoring and injection mode. | H36: System will keep working normally. | I36: 2 | J36: Melted connections due to overheating. Manufacturing defect. De-gradation of components. | K36: Using components with industrial grade scale. Choosing components with enough FIT rate to fulfil the product life requirements. Redundant HV Transformer board to power-up iSCR driver board. | L36: 1 | M36: =I36*L36 -> 2 | N36: HALT. Electrical Stress Testing. Thermal Stress Testing. | O36: None. | P36: 5 | Q36: =I36*L36*P36 -> 10 | AA36: =X36*Y36*Z36 -> 0 | AD36: =VALUE(RIGHT((IF(A36="",0,A36)),5)) -> 5171
A37: SV104 - 5172 | E37: BJT fails-short. | F37: Higher voltage at startup will damage the PWM controller and gate drivers of board. Input power path will be broken. No output available at HV transformer board. | G37: iSCR driver board will still receive power from redundant HVT board. Device can operate in both monitoring and injection mode. | H37: System will keep working normally. | I37: 2 | J37: Over voltage. Leaky junctions. Wear-out due to high power dissipation. De-gradation of components. | K37: Using components with industrial grade scale. Choosing components with enough FIT rate to fulfil the product life requirements. Redundant HV Transformer board to power-up iSCR driver board. | L37: 1 | M37: =I37*L37 -> 2 | N37: HALT. Electrical Stress Testing. Thermal Stress Testing. | O37: None. | P37: 5 | Q37: =I37*L37*P37 -> 10 | AD37: =VALUE(RIGHT((IF(A37="",0,A37)),5)) -> 5172
A38: SV104 - 5173 | B38: Biasing Resistor for BJT. | C38: R40 | D38: To set biasing threshold for power flow controlling BJT. | E38: Resistor fails-open. | F38: BJT will be permanently turned OFF. Input power path will be broken. No output available at HV transformer board. | G38: iSCR driver board will still receive power from redundant HVT board. Device can operate in both monitoring and injection mode. | H38: System will keep working normally. | I38: 2 | J38: Over voltage. Over Temperature. Over stress due to shock or vibration. De-gradation of components. | K38: Using components with industrial grade scale. Choosing components with enough FIT rate to fulfil the product life requirements. Redundant HV Transformer board to power-up iSCR driver board. | L38: 1 | M38: =I38*L38 -> 2 | N38: HALT. Electrical Stress Testing. Thermal Stress Testing. | O38: None. | P38: 5 | Q38: =I38*L38*P38 -> 10 | AA38: =X38*Y38*Z38 -> 0 | AD38: =VALUE(RIGHT((IF(A38="",0,A38)),5)) -> 5173
A39: SV104 - 5174 | E39: Resistor fails-short. | F39: 24 V will be replicated at the emitter for the shorted duration, on-board ICs may get burn due to this over-voltage. BJT will eventually fail-open due to over-current. Input power path will be broken. No output available at HV transformer board. | G39: iSCR driver board will still receive power from redundant HVT board. Device can operate in both monitoring and injection mode. | H39: System will keep working normally. | I39: 2 | J39: Wear-out due to extensive use. Excessive humidity. De-gradation of components. | K39: Using components with industrial grade scale. Choosing components with enough FIT rate to fulfil the product life requirements. Redundant HV Transformer board to power-up iSCR driver board. | L39: 1 | M39: =I39*L39 -> 2 | N39: HALT. Electrical Stress Testing. Thermal Stress Testing. | O39: None. | P39: 5 | Q39: =I39*L39*P39 -> 10 | AD39: =VALUE(RIGHT((IF(A39="",0,A39)),5)) -> 5174
A40: SV104 - 5175 | B40: Freewheeling Diode. | D40: To provide reverser current flow path. | E40: Diode fails-open. | F40: No path will be available for reverse current to flow. Potential difference creation across BJT can damage the BJT. Input power path will be broken. No output available at HV transformer board. | G40: iSCR driver board will still receive power from redundant HVT board. Device can operate in both monitoring and injection mode. | H40: System will keep working normally. | I40: 2 | J40: Mechanical stress or impact during assembly. Overcurrent. De-gradation of components. | K40: Using components with industrial grade scale. Choosing components with enough FIT rate to fulfil the product life requirements. Redundant HV Transformer board to power-up iSCR driver board. | L40: 1 | M40: =I40*L40 -> 2 | N40: HALT. Electrical Stress Testing. Thermal Stress Testing. | O40: None. | P40: 5 | Q40: =I40*L40*P40 -> 10 | AD40: =VALUE(RIGHT((IF(A40="",0,A40)),5)) -> 5175
...

