Workbook
Name _polarion_4: OFFSET(_polarion_options_start,MATCH(CONCATENATE(_polarion_type,":","PRD-Section"),_polarion_options_types,0),1,COUNTIF(_polarion_options_types,CONCATENATE(_polarion_type,":","PRD-Section")),1)
Name _polarion_info: #REF!
Name _polarion_info: #REF!
Name _polarion_info: #REF!
Name _polarion_info: #REF!
Name _polarion_info: #REF!
Name _polarion_options_start: [1]!_polarion_options[[#Headers],[Type]]
Name _polarion_options_types: [1]!_polarion_options[Type]
Name _polarion_project: IF(ISBLANK(_polarion_info),"PrimaryProtectionSystem",LEFT(_polarion_info,SEARCH("/",_polarion_info,1)-1))
Name _polarion_project: IF(ISBLANK(Lookup_Table!_polarion_info),"PrimaryProtectionSystem",LEFT(Lookup_Table!_polarion_info,SEARCH("/",Lookup_Table!_polarion_info,1)-1))
Name _polarion_project: IF(ISBLANK(_polarion_info),"PrimaryProtectionSystem",LEFT(_polarion_info,SEARCH("/",_polarion_info,1)-1))
Name _polarion_project: IF(ISBLANK('Revision History'!_polarion_info),"PrimaryProtectionSystem",LEFT('Revision History'!_polarion_info,SEARCH("/",'Revision History'!_polarion_info,1)-1))
Name _polarion_project: IF(ISBLANK('Scores '!_polarion_info),"PrimaryProtectionSystem",LEFT('Scores '!_polarion_info,SEARCH("/",'Scores '!_polarion_info,1)-1))
Name _polarion_project: IF(ISBLANK(Title!_polarion_info),"PrimaryProtectionSystem",LEFT(Title!_polarion_info,SEARCH("/",Title!_polarion_info,1)-1))
Name _polarion_project: IF(ISBLANK(_polarion_info),"PrimaryProtectionSystem",LEFT(_polarion_info,SEARCH("/",_polarion_info,1)-1))
Name _polarion_type: CONCATENATE('Bypass - Architecture'!_polarion_project,"/",IF(ISBLANK(#REF!),"requirement",#REF!))
Name _polarion_type: CONCATENATE(Lookup_Table!_polarion_project,"/",IF(ISBLANK(#REF!),"requirement",#REF!))
Name _polarion_type: CONCATENATE('MVAr - Architecture'!_polarion_project,"/",IF(ISBLANK(#REF!),"requirement",#REF!))
Name _polarion_type: CONCATENATE('Revision History'!_polarion_project,"/",IF(ISBLANK(#REF!),"requirement",#REF!))
Name _polarion_type: CONCATENATE('Scores '!_polarion_project,"/",IF(ISBLANK(#REF!),"requirement",#REF!))
Name _polarion_type: CONCATENATE(Title!_polarion_project,"/",IF(ISBLANK(#REF!),"requirement",#REF!))
Name _polarion_type: CONCATENATE(_polarion_project,"/",IF(ISBLANK(#REF!),"requirement",#REF!))
Name a: #N/A
Name ValidPPDPhase: #REF!
Name ValidPPDPhase: #REF!
Name ValidPPDPhase: #REF!
Name ValidPPDPhase: #REF!

Sheet Title
B3: Title: | C3: SmartValve 10-1800 v1.04 - SCRD Gate Driver Board Rev2 (P112269 / P112262) - Potential Failure Mode Effects and Criticality Analysis (Design FMECA)
B4: Project: | C4: SmartValve 10-1800 v1.04
B6: PS19 QPI | C6: PS19 Technical Experts | D6: Smart Wires Reviewer
B7: Azeem, Talha, Arslan | C7: Haris, Abdul Qadeer, Noman Akbar | D7: Dr. Shilei

Sheet Revision History
B2: Revision History
B3: Date | C3: Version | D3: Description
B4: 44244 | C4: 1 | D4: Initial draft based on Rev0. schematic.
B6: 44453 | C6: 1.1 | D6: Updated FMECA based on the Rev1 schematic done by PS19 QPI team.
B7: 44575 | C7: 1.2 | D7: Updated FMECA based on the Rev2 schematic done by PS19 QPI team.
B8: 44594 | C8: 1.3 | D8: Reviewed and updated by PS19 Hardware team for the changes done based on the Rev2 schematic
B9: 44599 | C9: 1.4 | D9: Updated the FMECA based on the feedback received from PS19 Hardware team for the improvements by PS19 QPI team.
B10: 44886 | C10: 1.5 | D10: Updated the FMECA based on the feedback received from PS19 Hardware team for the improvements by PS19 QPI team.
B11: 45015 | C11: 1.6 | D11: Updated the FMECA based on the feedback received from PS19 Hardware team for the improvements by PS19 QPI team based on Rev2 schematics.
B18: 45196 | C18: 1.7 | D18: Updated the FMECA based on the feedback received from SmartWires team for the improvements by PS19 QPI team based on Rev2 schematics.
B19: 45455 | C19: 1.8 | D19: Updated the FMECA Alarms and Telemetry by PS19 QPI team based on Rev2 schematics.

Sheet Definitions-Terms
B2: Definitions / Terms / Acronyms
B3: Term | C3: Description | D3: Term | E3: Description
B4: A-K | C4: Anode-to-Cathode | D4: LCB | E4: Liquid Cooling Block
B5: BF | C5: Bypass Filter | D5: PHT | E5: Power Harvesting Transformer
B6: CTP | C6: Current Transformer for Power | D6: ETP | E6: Electrical Test Procedure
B7: DCCT | C7: DC current transducer | D7: IP | E7: Intrusion Protection
B8: DCE | C8: Digital Computational Engine | D8: MES | E8: Manufacturing Execution System
B9: EFT | C9: Electrical Fast Transient | D9: CTQ | E9: Critical To Quality
B10: EMS | C10: Energy Management System
B11: EOL | C11: End Of Line
B12: FCS | C12: Fault Current Sensor
B13: FO | C13: Fiber Optic
B14: FR | C14: Flame Retardant
B15: G-K | C15: Gate-to-Cathode
B16: HALT | C16: Highly-Accelerated Life Testing
B17: HASS | C17: High accelerated stress screening
B18: HCT | C18: High Current Testing
B19: LCB | C19: Liquid Cooling Block
B20: LCS | C20: Line Current Sensor
B21: OVP | C21: Over-Voltage Protection
... B37: TBR | C37: To be Reviewed

Sheet Design-Traceability
B2: Design Traceability
B3: Sr. | C3: Design Artifact | D3: Rev | E3: Link
B5: 1 | C5: SmartValve 10-1800 v1.04 - Wiring Drawing - Bypass, MVAr Section Harnesses Diagram, PHT Shorting and Capacitor Voltage Measurement Blocks | D5: 4 | E5: Box Link
B6: 2 | C6: SmartValve 10-1800 v1.04 - Wiring Drawing - Power Supply Scheme Gen2-v2-FAI | D6: v2 | E6: Box Link
B7: 3 | C7: SmartValve 10-1800 v1.04 - PCBAs - iSCR Driver Board Functional Block Diagram | D7: 2 | E7: Box Link
B8: 4 | C8: SmartValve 10-1800 v1.04 - PCBAs - iSCR Driver Board Schematic | D8: 2 | E8: Box Link
B9: 5 | C9: SmartValve 10-1800 v1.04 - PCBAs - iSCR Driver Board Design Document | D9: A | E9: Box Link

Sheet Scores 
D2: Risk Factor (S x O) Scores | L2: SmartValve v1.04 Risk Factor (S x O) Counts
B4: Occurrence | C4: 5 | D4: =$C$4*D9 -> 5 | E4: =$C$4*E9 -> 10 | F4: =$C$4*F9 -> 15 | G4: =$C$4*G9 -> 20 | H4: =$C$4*H9 -> 25 | K4: Occurrence | L4: 5 | M4: =SUMPRODUCT(--(DFMECA!I3:I397=1),--(DFMECA!L3:L397=5)) -> 0 | N4: =SUMPRODUCT(--(DFMECA!I3:I397=2),--(DFMECA!L3:L397=5)) -> 0 | O4: =SUMPRODUCT(--(DFMECA!I3:I397=3),--(DFMECA!L3:L397=5)) -> 0 | P4: =SUMPRODUCT(--(DFMECA!I3:I397=4),--(DFMECA!L3:L397=5)) -> 0 | Q4: =SUMPRODUCT(--(DFMECA!I3:I397=5),--(DFMECA!L3:L397=5)) -> 0
C5: 4 | D5: =$C$5*D9 -> 4 | E5: =$C$5*E9 -> 8 | F5: =$C$5*F9 -> 12 | G5: =$C$5*G9 -> 16 | H5: =$C$5*H9 -> 20 | L5: 4 | M5: =SUMPRODUCT(--(DFMECA!I3:I397=1),--(DFMECA!L3:L397=4)) -> 0 | N5: =SUMPRODUCT(--(DFMECA!I3:I397=2),--(DFMECA!L3:L397=4)) -> 0 | O5: =SUMPRODUCT(--(DFMECA!I3:I397=3),--(DFMECA!L3:L397=4)) -> 0 | P5: =SUMPRODUCT(--(DFMECA!I3:I397=4),--(DFMECA!L3:L397=4)) -> 0 | Q5: =SUMPRODUCT(--(DFMECA!I3:I397=5),--(DFMECA!L3:L397=4)) -> 0
C6: 3 | D6: =$C$6*D9 -> 3 | E6: =$C$6*E9 -> 6 | F6: =$C$6*F9 -> 9 | G6: =$C$6*G9 -> 12 | H6: =$C$6*H9 -> 15 | L6: 3 | M6: =SUMPRODUCT(--(DFMECA!I3:I397=1),--(DFMECA!L3:L397=3)) -> 0 | N6: =SUMPRODUCT(--(DFMECA!I3:I397=2),--(DFMECA!L3:L397=3)) -> 0 | O6: =SUMPRODUCT(--(DFMECA!I3:I397=3),--(DFMECA!L3:L397=3)) -> 0 | P6: =SUMPRODUCT(--(DFMECA!I3:I397=4),--(DFMECA!L3:L397=3)) -> 0 | Q6: =SUMPRODUCT(--(DFMECA!I3:I397=5),--(DFMECA!L3:L397=3)) -> 0
C7: 2 | D7: =$C$7*D9 -> 2 | E7: =$C$7*E9 -> 4 | F7: =$C$7*F9 -> 6 | G7: =$C$7*G9 -> 8 | H7: =$C$7*H9 -> 10 | L7: 2 | M7: =SUMPRODUCT(--(DFMECA!I3:I397=1),--(DFMECA!L3:L397=2)) -> 15 | N7: =SUMPRODUCT(--(DFMECA!I3:I397=2),--(DFMECA!L3:L397=2)) -> 16 | O7: =SUMPRODUCT(--(DFMECA!I3:I397=3),--(DFMECA!L3:L397=2)) -> 96 | P7: =SUMPRODUCT(--(DFMECA!I3:I397=4),--(DFMECA!L3:L397=2)) -> 16 | Q7: =SUMPRODUCT(--(DFMECA!I3:I397=5),--(DFMECA!L3:L397=2)) -> 0
C8: 1 | D8: =$C$8*D9 -> 1 | E8: =$C$8*E9 -> 2 | F8: =$C$8*F9 -> 3 | G8: =$C$8*G9 -> 4 | H8: =$C$8*H9 -> 5 | L8: 1 | M8: =SUMPRODUCT(--(DFMECA!I3:I397=1),--(DFMECA!L3:L397=1)) -> 94 | N8: =SUMPRODUCT(--(DFMECA!I3:I397=2),--(DFMECA!L3:L397=1)) -> 44 | O8: =SUMPRODUCT(--(DFMECA!I3:I397=3),--(DFMECA!L3:L397=1)) -> 90 | P8: =SUMPRODUCT(--(DFMECA!I3:I397=4),--(DFMECA!L3:L397=1)) -> 7 | Q8: =SUMPRODUCT(--(DFMECA!I3:I397=5),--(DFMECA!L3:L397=1)) -> 0
D9: 1 | E9: 2 | F9: 3 | G9: 4 | H9: 5 | M9: 1 | N9: 2 | O9: 3 | P9: 4 | Q9: 5
D10: Severity | M10: Severity
M12: Total risks: | Q12: =SUM(M4:M8)+SUM(N4:N8)+SUM(O4:O8)+SUM(P4:P8)+SUM(Q4:Q8) -> 378
M13: Total risks require mitigation based on S x O: | Q13: =SUM(N4:N5)+SUM(O4:O6)+SUM(P4:P7)+SUM(Q4:Q8) -> 16
C17: Risk Priority Number (S x O x D) Scores | L17: SmartValve v1.04 RPN (S x O x D) Counts
B19: Severity x Occurrence (S x O) | C19: 25 | D19: =C19*$D$44 -> 25 | E19: =C19*$E$44 -> 50 | F19: =C19*$F$44 -> 75 | G19: =C19*$G$44 -> 100 | H19: =C19*$H$44 -> 125 | K19: Severity x Occurrence (S x O) | L19: 25 | M19: =SUMPRODUCT(--(DFMECA!M3:M397=25),--(DFMECA!P3:P397=1)) -> 0 | N19: =SUMPRODUCT(--(DFMECA!M3:M397=25),--(DFMECA!P3:P397=2)) -> 0 | O19: =SUMPRODUCT(--(DFMECA!M3:M397=25),--(DFMECA!P3:P397=3)) -> 0 | P19: =SUMPRODUCT(--(DFMECA!M3:M397=25),--(DFMECA!P3:P397=4)) -> 0 | Q19: =SUMPRODUCT(--(DFMECA!M3:M397=25),--(DFMECA!P3:P397=5)) -> 0
C20: 24 | D20: =C20*$D$44 -> 24 | E20: =C20*$E$44 -> 48 | F20: =C20*$F$44 -> 72 | G20: =C20*$G$44 -> 96 | H20: =C20*$H$44 -> 120 | L20: 24 | M20: =SUMPRODUCT(--(DFMECA!M3:M397=24),--(DFMECA!P3:P397=1)) -> 0 | N20: =SUMPRODUCT(--(DFMECA!M3:M397=24),--(DFMECA!P3:P397=2)) -> 0 | O20: =SUMPRODUCT(--(DFMECA!M3:M397=24),--(DFMECA!P3:P397=3)) -> 0 | P20: =SUMPRODUCT(--(DFMECA!M3:M397=24),--(DFMECA!P3:P397=4)) -> 0 | Q20: =SUMPRODUCT(--(DFMECA!M3:M397=24),--(DFMECA!P3:P397=5)) -> 0
C21: 23 | D21: =C21*$D$44 -> 23 | E21: =C21*$E$44 -> 46 | F21: =C21*$F$44 -> 69 | G21: =C21*$G$44 -> 92 | H21: =C21*$H$44 -> 115 | L21: 23 | M21: =SUMPRODUCT(--(DFMECA!M3:M397=23),--(DFMECA!P3:P397=1)) -> 0 | N21: =SUMPRODUCT(--(DFMECA!M3:M397=23),--(DFMECA!P3:P397=2)) -> 0 | O21: =SUMPRODUCT(--(DFMECA!M3:M397=23),--(DFMECA!P3:P397=3)) -> 0 | P21: =SUMPRODUCT(--(DFMECA!M3:M397=23),--(DFMECA!P3:P397=4)) -> 0 | Q21: =SUMPRODUCT(--(DFMECA!M3:M397=23),--(DFMECA!P3:P397=5)) -> 0
C22: 22 | D22: =C22*$D$44 -> 22 | E22: =C22*$E$44 -> 44 | F22: =C22*$F$44 -> 66 | G22: =C22*$G$44 -> 88 | H22: =C22*$H$44 -> 110 | L22: 22 | M22: =SUMPRODUCT(--(DFMECA!M3:M397=22),--(DFMECA!P3:P397=1)) -> 0 | N22: =SUMPRODUCT(--(DFMECA!M3:M397=22),--(DFMECA!P3:P397=2)) -> 0 | O22: =SUMPRODUCT(--(DFMECA!M3:M397=22),--(DFMECA!P3:P397=3)) -> 0 | P22: =SUMPRODUCT(--(DFMECA!M3:M397=22),--(DFMECA!P3:P397=4)) -> 0 | Q22: =SUMPRODUCT(--(DFMECA!M3:M397=22),--(DFMECA!P3:P397=5)) -> 0
C23: 21 | D23: =C23*$D$44 -> 21 | E23: =C23*$E$44 -> 42 | F23: =C23*$F$44 -> 63 | G23: =C23*$G$44 -> 84 | H23: =C23*$H$44 -> 105 | L23: 21 | M23: =SUMPRODUCT(--(DFMECA!M3:M397=21),--(DFMECA!P3:P397=1)) -> 0 | N23: =SUMPRODUCT(--(DFMECA!M3:M397=21),--(DFMECA!P3:P397=2)) -> 0 | O23: =SUMPRODUCT(--(DFMECA!M3:M397=21),--(DFMECA!P3:P397=3)) -> 0 | P23: =SUMPRODUCT(--(DFMECA!M3:M397=21),--(DFMECA!P3:P397=4)) -> 0 | Q23: =SUMPRODUCT(--(DFMECA!M3:M397=21),--(DFMECA!P3:P397=5)) -> 0
C24: 20 | D24: =C24*$D$44 -> 20 | E24: =C24*$E$44 -> 40 | F24: =C24*$F$44 -> 60 | G24: =C24*$G$44 -> 80 | H24: =C24*$H$44 -> 100 | L24: 20 | M24: =SUMPRODUCT(--(DFMECA!M3:M397=20),--(DFMECA!P3:P397=1)) -> 0 | N24: =SUMPRODUCT(--(DFMECA!M3:M397=20),--(DFMECA!P3:P397=2)) -> 0 | O24: =SUMPRODUCT(--(DFMECA!M3:M397=20),--(DFMECA!P3:P397=3)) -> 0 | P24: =SUMPRODUCT(--(DFMECA!M3:M397=20),--(DFMECA!P3:P397=4)) -> 0 | Q24: =SUMPRODUCT(--(DFMECA!M3:M397=20),--(DFMECA!P3:P397=5)) -> 0
C25: 19 | D25: =C25*$D$44 -> 19 | E25: =C25*$E$44 -> 38 | F25: =C25*$F$44 -> 57 | G25: =C25*$G$44 -> 76 | H25: =C25*$H$44 -> 95 | L25: 19 | M25: =SUMPRODUCT(--(DFMECA!M3:M397=19),--(DFMECA!P3:P397=1)) -> 0 | N25: =SUMPRODUCT(--(DFMECA!M3:M397=19),--(DFMECA!P3:P397=2)) -> 0 | O25: =SUMPRODUCT(--(DFMECA!M3:M397=19),--(DFMECA!P3:P397=3)) -> 0 | P25: =SUMPRODUCT(--(DFMECA!M3:M397=19),--(DFMECA!P3:P397=4)) -> 0 | Q25: =SUMPRODUCT(--(DFMECA!M3:M397=19),--(DFMECA!P3:P397=5)) -> 0
C26: 18 | D26: =C26*$D$44 -> 18 | E26: =C26*$E$44 -> 36 | F26: =C26*$F$44 -> 54 | G26: =C26*$G$44 -> 72 | H26: =C26*$H$44 -> 90 | L26: 18 | M26: =SUMPRODUCT(--(DFMECA!M3:M397=18),--(DFMECA!P3:P397=1)) -> 0 | N26: =SUMPRODUCT(--(DFMECA!M3:M397=18),--(DFMECA!P3:P397=2)) -> 0 | O26: =SUMPRODUCT(--(DFMECA!M3:M397=18),--(DFMECA!P3:P397=3)) -> 0 | P26: =SUMPRODUCT(--(DFMECA!M3:M397=18),--(DFMECA!P3:P397=4)) -> 0 | Q26: =SUMPRODUCT(--(DFMECA!M3:M397=18),--(DFMECA!P3:P397=5)) -> 0
C27: 17 | D27: =C27*$D$44 -> 17 | E27: =C27*$E$44 -> 34 | F27: =C27*$F$44 -> 51 | G27: =C27*$G$44 -> 68 | H27: =C27*$H$44 -> 85 | L27: 17 | M27: =SUMPRODUCT(--(DFMECA!M3:M397=17),--(DFMECA!P3:P397=1)) -> 0 | N27: =SUMPRODUCT(--(DFMECA!M3:M397=17),--(DFMECA!P3:P397=2)) -> 0 | O27: =SUMPRODUCT(--(DFMECA!M3:M397=17),--(DFMECA!P3:P397=3)) -> 0 | P27: =SUMPRODUCT(--(DFMECA!M3:M397=17),--(DFMECA!P3:P397=4)) -> 0 | Q27: =SUMPRODUCT(--(DFMECA!M3:M397=17),--(DFMECA!P3:P397=5)) -> 0
C28: 16 | D28: =C28*$D$44 -> 16 | E28: =C28*$E$44 -> 32 | F28: =C28*$F$44 -> 48 | G28: =C28*$G$44 -> 64 | H28: =C28*$H$44 -> 80 | L28: 16 | M28: =SUMPRODUCT(--(DFMECA!M3:M397=16),--(DFMECA!P3:P397=1)) -> 0 | N28: =SUMPRODUCT(--(DFMECA!M3:M397=16),--(DFMECA!P3:P397=2)) -> 0 | O28: =SUMPRODUCT(--(DFMECA!M3:M397=16),--(DFMECA!P3:P397=3)) -> 0 | P28: =SUMPRODUCT(--(DFMECA!M3:M397=16),--(DFMECA!P3:P397=4)) -> 0 | Q28: =SUMPRODUCT(--(DFMECA!M3:M397=16),--(DFMECA!P3:P397=5)) -> 0
C29: 15 | D29: =C29*$D$44 -> 15 | E29: =C29*$E$44 -> 30 | F29: =C29*$F$44 -> 45 | G29: =C29*$G$44 -> 60 | H29: =C29*$H$44 -> 75 | L29: 15 | M29: =SUMPRODUCT(--(DFMECA!M3:M397=15),--(DFMECA!P3:P397=1)) -> 0 | N29: =SUMPRODUCT(--(DFMECA!M3:M397=15),--(DFMECA!P3:P397=2)) -> 0 | O29: =SUMPRODUCT(--(DFMECA!M3:M397=15),--(DFMECA!P3:P397=3)) -> 0 | P29: =SUMPRODUCT(--(DFMECA!M3:M397=15),--(DFMECA!P3:P397=4)) -> 0 | Q29: =SUMPRODUCT(--(DFMECA!M3:M397=15),--(DFMECA!P3:P397=5)) -> 0
C30: 14 | D30: =C30*$D$44 -> 14 | E30: =C30*$E$44 -> 28 | F30: =C30*$F$44 -> 42 | G30: =C30*$G$44 -> 56 | H30: =C30*$H$44 -> 70 | L30: 14 | M30: =SUMPRODUCT(--(DFMECA!M3:M397=14),--(DFMECA!P3:P397=1)) -> 0 | N30: =SUMPRODUCT(--(DFMECA!M3:M397=14),--(DFMECA!P3:P397=2)) -> 0 | O30: =SUMPRODUCT(--(DFMECA!M3:M397=14),--(DFMECA!P3:P397=3)) -> 0 | P30: =SUMPRODUCT(--(DFMECA!M3:M397=14),--(DFMECA!P3:P397=4)) -> 0 | Q30: =SUMPRODUCT(--(DFMECA!M3:M397=14),--(DFMECA!P3:P397=5)) -> 0
C31: 13 | D31: =C31*$D$44 -> 13 | E31: =C31*$E$44 -> 26 | F31: =C31*$F$44 -> 39 | G31: =C31*$G$44 -> 52 | H31: =C31*$H$44 -> 65 | L31: 13 | M31: =SUMPRODUCT(--(DFMECA!M3:M397=13),--(DFMECA!P3:P397=1)) -> 0 | N31: =SUMPRODUCT(--(DFMECA!M3:M397=13),--(DFMECA!P3:P397=2)) -> 0 | O31: =SUMPRODUCT(--(DFMECA!M3:M397=13),--(DFMECA!P3:P397=3)) -> 0 | P31: =SUMPRODUCT(--(DFMECA!M3:M397=13),--(DFMECA!P3:P397=4)) -> 0 | Q31: =SUMPRODUCT(--(DFMECA!M3:M397=13),--(DFMECA!P3:P397=5)) -> 0
C32: 12 | D32: =C32*$D$44 -> 12 | E32: =C32*$E$44 -> 24 | F32: =C32*$F$44 -> 36 | G32: =C32*$G$44 -> 48 | H32: =C32*$H$44 -> 60 | L32: 12 | M32: =SUMPRODUCT(--(DFMECA!M3:M397=12),--(DFMECA!P3:P397=1)) -> 0 | N32: =SUMPRODUCT(--(DFMECA!M3:M397=12),--(DFMECA!P3:P397=2)) -> 0 | O32: =SUMPRODUCT(--(DFMECA!M3:M397=12),--(DFMECA!P3:P397=3)) -> 0 | P32: =SUMPRODUCT(--(DFMECA!M3:M397=12),--(DFMECA!P3:P397=4)) -> 0 | Q32: =SUMPRODUCT(--(DFMECA!M3:M397=12),--(DFMECA!P3:P397=5)) -> 0
C33: 11 | D33: =C33*$D$44 -> 11 | E33: =C33*$E$44 -> 22 | F33: =C33*$F$44 -> 33 | G33: =C33*$G$44 -> 44 | H33: =C33*$H$44 -> 55 | L33: 11 | M33: =SUMPRODUCT(--(DFMECA!M3:M397=11),--(DFMECA!P3:P397=1)) -> 0 | N33: =SUMPRODUCT(--(DFMECA!M3:M397=11),--(DFMECA!P3:P397=2)) -> 0 | O33: =SUMPRODUCT(--(DFMECA!M3:M397=11),--(DFMECA!P3:P397=3)) -> 0 | P33: =SUMPRODUCT(--(DFMECA!M3:M397=11),--(DFMECA!P3:P397=4)) -> 0 | Q33: =SUMPRODUCT(--(DFMECA!M3:M397=11),--(DFMECA!P3:P397=5)) -> 0
C34: 10 | D34: =C34*$D$44 -> 10 | E34: =C34*$E$44 -> 20 | F34: =C34*$F$44 -> 30 | G34: =C34*$G$44 -> 40 | H34: =C34*$H$44 -> 50 | L34: 10 | M34: =SUMPRODUCT(--(DFMECA!M3:M397=10),--(DFMECA!P3:P397=1)) -> 0 | N34: =SUMPRODUCT(--(DFMECA!M3:M397=10),--(DFMECA!P3:P397=2)) -> 0 | O34: =SUMPRODUCT(--(DFMECA!M3:M397=10),--(DFMECA!P3:P397=3)) -> 0 | P34: =SUMPRODUCT(--(DFMECA!M3:M397=10),--(DFMECA!P3:P397=4)) -> 0 | Q34: =SUMPRODUCT(--(DFMECA!M3:M397=10),--(DFMECA!P3:P397=5)) -> 0
C35: 9 | D35: =C35*$D$44 -> 9 | E35: =C35*$E$44 -> 18 | F35: =C35*$F$44 -> 27 | G35: =C35*$G$44 -> 36 | H35: =C35*$H$44 -> 45 | L35: 9 | M35: =SUMPRODUCT(--(DFMECA!M3:M397=9),--(DFMECA!P3:P397=1)) -> 0 | N35: =SUMPRODUCT(--(DFMECA!M3:M397=9),--(DFMECA!P3:P397=2)) -> 0 | O35: =SUMPRODUCT(--(DFMECA!M3:M397=9),--(DFMECA!P3:P397=3)) -> 0 | P35: =SUMPRODUCT(--(DFMECA!M3:M397=9),--(DFMECA!P3:P397=4)) -> 0 | Q35: =SUMPRODUCT(--(DFMECA!M3:M397=9),--(DFMECA!P3:P397=5)) -> 0
C36: 8 | D36: =C36*$D$44 -> 8 | E36: =C36*$E$44 -> 16 | F36: =C36*$F$44 -> 24 | G36: =C36*$G$44 -> 32 | H36: =C36*$H$44 -> 40 | L36: 8 | M36: =SUMPRODUCT(--(DFMECA!M3:M397=8),--(DFMECA!P3:P397=1)) -> 3 | N36: =SUMPRODUCT(--(DFMECA!M3:M397=8),--(DFMECA!P3:P397=2)) -> 12 | O36: =SUMPRODUCT(--(DFMECA!M3:M397=8),--(DFMECA!P3:P397=3)) -> 1 | P36: =SUMPRODUCT(--(DFMECA!M3:M397=8),--(DFMECA!P3:P397=4)) -> 0 | Q36: =SUMPRODUCT(--(DFMECA!M3:M397=8),--(DFMECA!P3:P397=5)) -> 0
C37: 7 | D37: =C37*$D$44 -> 7 | E37: =C37*$E$44 -> 14 | F37: =C37*$F$44 -> 21 | G37: =C37*$G$44 -> 28 | H37: =C37*$H$44 -> 35 | L37: 7 | M37: =SUMPRODUCT(--(DFMECA!M3:M397=7),--(DFMECA!P3:P397=1)) -> 0 | N37: =SUMPRODUCT(--(DFMECA!M3:M397=7),--(DFMECA!P3:P397=2)) -> 0 | O37: =SUMPRODUCT(--(DFMECA!M3:M397=7),--(DFMECA!P3:P397=3)) -> 0 | P37: =SUMPRODUCT(--(DFMECA!M3:M397=7),--(DFMECA!P3:P397=4)) -> 0 | Q37: =SUMPRODUCT(--(DFMECA!M3:M397=7),--(DFMECA!P3:P397=5)) -> 0
C38: 6 | D38: =C38*$D$44 -> 6 | E38: =C38*$E$44 -> 12 | F38: =C38*$F$44 -> 18 | G38: =C38*$G$44 -> 24 | H38: =C38*$H$44 -> 30 | L38: 6 | M38: =SUMPRODUCT(--(DFMECA!M3:M397=6),--(DFMECA!P3:P397=1)) -> 0 | N38: =SUMPRODUCT(--(DFMECA!M3:M397=6),--(DFMECA!P3:P397=2)) -> 9 | O38: =SUMPRODUCT(--(DFMECA!M3:M397=6),--(DFMECA!P3:P397=3)) -> 63 | P38: =SUMPRODUCT(--(DFMECA!M3:M397=6),--(DFMECA!P3:P397=4)) -> 1 | Q38: =SUMPRODUCT(--(DFMECA!M3:M397=6),--(DFMECA!P3:P397=5)) -> 23
C39: 5 | D39: =C39*$D$44 -> 5 | E39: =C39*$E$44 -> 10 | F39: =C39*$F$44 -> 15 | G39: =C39*$G$44 -> 20 | H39: =C39*$H$44 -> 25 | L39: 5 | M39: =SUMPRODUCT(--(DFMECA!M3:M397=5),--(DFMECA!P3:P397=1)) -> 0 | N39: =SUMPRODUCT(--(DFMECA!M3:M397=5),--(DFMECA!P3:P397=2)) -> 0 | O39: =SUMPRODUCT(--(DFMECA!M3:M397=5),--(DFMECA!P3:P397=3)) -> 0 | P39: =SUMPRODUCT(--(DFMECA!M3:M397=5),--(DFMECA!P3:P397=4)) -> 0 | Q39: =SUMPRODUCT(--(DFMECA!M3:M397=5),--(DFMECA!P3:P397=5)) -> 0
C40: 4 | D40: =C40*$D$44 -> 4 | E40: =C40*$E$44 -> 8 | F40: =C40*$F$44 -> 12 | G40: =C40*$G$44 -> 16 | H40: =C40*$H$44 -> 20 | L40: 4 | M40: =SUMPRODUCT(--(DFMECA!M3:M397=4),--(DFMECA!P3:P397=1)) -> 8 | N40: =SUMPRODUCT(--(DFMECA!M3:M397=4),--(DFMECA!P3:P397=2)) -> 0 | O40: =SUMPRODUCT(--(DFMECA!M3:M397=4),--(DFMECA!P3:P397=3)) -> 1 | P40: =SUMPRODUCT(--(DFMECA!M3:M397=4),--(DFMECA!P3:P397=4)) -> 0 | Q40: =SUMPRODUCT(--(DFMECA!M3:M397=4),--(DFMECA!P3:P397=5)) -> 14
C41: 3 | D41: =C41*$D$44 -> 3 | E41: =C41*$E$44 -> 6 | F41: =C41*$F$44 -> 9 | G41: =C41*$G$44 -> 12 | H41: =C41*$H$44 -> 15 | L41: 3 | M41: =SUMPRODUCT(--(DFMECA!M3:M397=3),--(DFMECA!P3:P397=1)) -> 2 | N41: =SUMPRODUCT(--(DFMECA!M3:M397=3),--(DFMECA!P3:P397=2)) -> 4 | O41: =SUMPRODUCT(--(DFMECA!M3:M397=3),--(DFMECA!P3:P397=3)) -> 37 | P41: =SUMPRODUCT(--(DFMECA!M3:M397=3),--(DFMECA!P3:P397=4)) -> 5 | Q41: =SUMPRODUCT(--(DFMECA!M3:M397=3),--(DFMECA!P3:P397=5)) -> 42
C42: 2 | D42: =C42*$D$44 -> 2 | E42: =C42*$E$44 -> 4 | F42: =C42*$F$44 -> 6 | G42: =C42*$G$44 -> 8 | H42: =C42*$H$44 -> 10 | L42: 2 | M42: =SUMPRODUCT(--(DFMECA!M3:M397=2),--(DFMECA!P3:P397=1)) -> 8 | N42: =SUMPRODUCT(--(DFMECA!M3:M397=2),--(DFMECA!P3:P397=2)) -> 0 | O42: =SUMPRODUCT(--(DFMECA!M3:M397=2),--(DFMECA!P3:P397=3)) -> 1 | P42: =SUMPRODUCT(--(DFMECA!M3:M397=2),--(DFMECA!P3:P397=4)) -> 0 | Q42: =SUMPRODUCT(--(DFMECA!M3:M397=2),--(DFMECA!P3:P397=5)) -> 49
C43: 1 | D43: =C43*$D$44 -> 1 | E43: =C43*$E$44 -> 2 | F43: =C43*$F$44 -> 3 | G43: =C43*$G$44 -> 4 | H43: =C43*$H$44 -> 5 | L43: 1 | M43: =SUMPRODUCT(--(DFMECA!M3:M397=1),--(DFMECA!P3:P397=1)) -> 1 | N43: =SUMPRODUCT(--(DFMECA!M3:M397=1),--(DFMECA!P3:P397=2)) -> 0 | O43: =SUMPRODUCT(--(DFMECA!M3:M397=1),--(DFMECA!P3:P397=3)) -> 3 | P43: =SUMPRODUCT(--(DFMECA!M3:M397=1),--(DFMECA!P3:P397=4)) -> 0 | Q43: =SUMPRODUCT(--(DFMECA!M3:M397=1),--(DFMECA!P3:P397=5)) -> 91
D44: 1 | E44: 2 | F44: 3 | G44: 4 | H44: 5 | M44: 1 | N44: 2 | O44: 3 | P44: 4 | Q44: 5
D45: Detection | M45: Detection
L47: Total risks: | Q47: =SUM(M19:M43)+SUM(N19:N43)+SUM(O19:O43)+SUM(P19:P43)+SUM(Q19:Q43) -> 378
L48: Total risks require mitigation based on S x O x D: | Q48: =N19+SUM(O19:O27)+SUM(P19:P31)+SUM(Q19:Q34) -> 0

Sheet S-O-D Definitions
B2: Severity, or Consequence Evaluation Criteria: Worst Case Evaluation of Failure Mode | G2: Occurrence: Probability of occurrence within the product life based on the design as is exists today
B3: Score | C3: Criteria | D3: Notes | E3: Example | G3: Score | H3: Notes | I3: Probability Description | J3: Probability
B4: 5 | C4: Failure causes death or causes transmission line open circuit, full or partial fault protection compromised. | D4: Extremely hazardous failure, threatening to business continuity. | E4: Fault detection mechanism failure . IGBT shorting the capacitor bank. Power to one or more SCR driver boards discontinued while unit is in injection mode. Mechanical failure causing line to open. | G4: 5 | H4: Very high probability | I4: 1 in 10 or greater | J4: 0.1 ≤ Po
B5: 4 | C5: Failure causes severe injury to personnel requiring hospitalization, severe property damage such as damage to a structure, transmission line damage, major damage to system other than transmission line requiring immediate interruption of line service, loss of control of SmartValve v1.04 when in Injection Mode, device is forced to monitoring mode, with reduced fault protection (i.e. redundancy compromised). | D5: Highly hazardous failure, threatening to business reputation. | E5: iiDCE RF communication loss in injection mode. iiDCE losing control of SCRs. | G5: 4 | H5: High probability | I5: 1 in 100 or greater | J5: 0.01 ≤ Po < 0.1
B6: 3 | C6: Failure causes minor injury to personnel requiring out-patient treatment, moderate property damage not involving a structure, moderate system damage other than transmission line that requires future interruption of line service to repair, loss of control of SmartValve v1.04 when in Monitoring Mode, device is forced to monitoring mode with full fault protection available. | D6: Moderately hazardous failure, threatening to product reputation. | E6: iiDCE RF communication loss in monitoring mode. Any control boards' failure, forcing device to monitoring mode. Mechanical failure causing enclosure temperature to rise, forcing device to stay in monitoring mode. | G6: 3 | H6: Moderate probability | I6: 1 in 1,000 or greater | J6: 0.001 ≤ Po < 0.01
B7: 2 | C7: Failure causes minor property damage, minor system damage other than primary conductor or loss of SmartValve v1.04 such as loss of performance, unit forced into Monitoring Mode, or significant impact on unit life | D7: Minor hazard, minor consequence. | E7: Rise in on-board power losses, impacting components' life, Clamp board feedback not available. | G7: 2 | H7: Low probability | I7: 1 in 10,000 or greater | J7: 0.0001 ≤ Po < 0.001
B8: 1 | C8: Failure causes unscheduled maintenance, no immediate loss of performance. | D8: No hazard. | E8: On-board noise filtration compromised. One of many bolts failure. | G8: 1 | H8: Remote probability | I8: Less than 1 in 10,000 | J8: Po < 0.0001
B10: Detection: Likelihood of failure mode detection by design | I10: Target product life for the purposes of this FMECA is 40 years.
B11: Score | C11: Description | D11: Criteria | E11: Definition
B12: 5 | C12: Very remote probability to absolute uncertainty of detection | D12: Design will not and/or cannot detect the potential cause/mechanism or subsequent failure mode, or the likelihood of detection is very remote. | E12: PD < 0.1 | G12: RPN Conditions | H12: Color
B13: 4 | C13: Very low to remote probability of detection | D13: Design has a very low to remote likelihood of detecting the potential cause/mechanism or subsequent failure mode. | E13: 0.1 ≤ PD < 0.5 | G13: Value ≥ 70
B14: 3 | C14: Moderate to low probability of detection | D14: Design has a moderate to low likelihood of detecting the potential cause/mechanism or subsequent failure mode. | E14: 0.5 ≤ PD < 0.95 | G14: 70 > Value ≥ 60
B15: 2 | C15: High to moderately high probability of detection | D15: Design has a high to moderately high likelihood of detecting the potential cause/mechanism or subsequent failure mode. | E15: 0.95 ≤ PD < 0.995 | G15: 60 > Value ≥ 50
B16: 1 | C16: Almost certain to very high probability of detection | D16: Design has an almost certain chance of detecting the potential cause/mechanism or subsequent failure mode or the likelihood of detection is very high. | E16: 0.995 ≤ PD | G16: Value < 50
C50: Review Status
C51: Approved
C52: Reviewed by QA
C53: Review Pending

Sheet Lookup_Table
B2: Old Nomenclature | D2: New Nomenclature | F2: Description
B4: iiSC | D4: CC | F4: Convertor Controller
B5: iiGD | D5: IMD | F5: IGBT Module Driver
B6: iiDCE | D6: SVMC | F6: SmartValve Master Controller
B7: UPSB | D7: MPS | F7: Multi-Port Power Supply
B8: iSCR | D8: SCRD-F | F8: SCR Drive – Follower
B9: PHT-DC-PSB | D9: PHTR | F9: PHT Rectifier
B10: iVSL | D10: VSLD | F10: Vacuum Switch Link Drive
B11: iClamp | D11: Clamp | F11: Clamp
B12: HV-Iso Board (Rectifier) | D12: IPSR | F12: PCBA, Isolation Power Supply Rectifier
B13: HV-Iso Board (Input side) | D13: IPSI | F13: PCBA, Isolation Power Supply Inverter
B15: Note: 10-1800 has old nomenclature, whereas in 10-3600, new nomenclature will be used

Sheet Bypass - Architecture

Sheet MVAr - Architecture

Sheet Functional Block Diagram 

Sheet DFMECA
A1: ID. | B1: Component | C1: Reference Designator | D1: Functional Requirement | E1: Potential Failure Mode | F1: Potential Effect(s) of Failure | I1: Severity Score | J1: Potential Causes / Triggers of Failure | K1: Failure Safeguards | L1: Occurrence Score | M1: S x O | N1: Existing Conditions | Q1: RPN (S x O x D) | R1: Telemetry | S1: Alert Message | T1: Recommended Action(s) / Remarks | U1: Comments from Reviewer | V1: Target Completion Date | W1: Action Results | AB1: Status
F2: Local - Effect at the sub assembly or component level | G2: Higher Level - Effect at SmartValve v1.04 | H2: End - Effect at System Level | N2: Verification & Validation Method | O2: Detection Method | P2: Detection Score | W2: Actions Taken | X2: Severity Score | Y2: Occurrence Score | Z2: Detection Score | AA2: New RPN
B3: SCRD Gate Driver Board Rev2 (P112269 / P112262) | AD3: =VALUE(RIGHT((IF(A3="",0,A3)),5)) -> 0
B4: SCRD Gate Driver Board - Power Supply Section | AD4: =VALUE(RIGHT((IF(A4="",0,A4)),5)) -> 0
A5: SV104-1305 | B5: Input Power Connectors. | C5: CONN1, CONN2 | D5: Provide power to onboard electronics. | E5: Power not available from both input connectors. | F5: No power to the affected SCR gate driver board. Fault-current handling not available in one direction. Device will be unable to initiate the trigger for all SCRs in one direction when moving from injection mode to monitoring mode and vice-versa, | G5: During mode transition, no SCR will be handling the line current in one direction. IGBTs may get damaged in case of surge current event, if loss of SCRs occurs in injection mode. Device's default behavior will be to disallow injection mode operation. The device is capable of injection, however, and end user may request to override this protection. | H5: Affected device and its associated group of devices will transit to monitoring mode. System will keep working with reduced injection capability. | I5: 4 | J5: Vibration. Improper bend radius during assembly. PSB connectivity failure from SCR. | K5: Connectors with secure contact mating. | L5: 2 | M5: =I5*L5 -> 8 | N5: Functional Testing. Thermal and Relative Humidity Testing. Condensed Humidity Testing. EFT Testing. Vibration Testing. ATM Testing. MVAr Testing. Pre-Closure Testing. EOL Testing. | O5: On board SCR gate current measurement. | P5: 1 | Q5: =I5*L5*P5 -> 8 | R5: In Bypass Telemetry field 'SCR and Clamp Board Status' will show following: Cable break detected | S5: On SmartInterface following Alarm will be raised: SCR Driver Board Malfunctioning | T5: If the SCR gate measurement circuits detect this, injection mode shall not be allowed as the IGBTs will be unprotected from fault currents in the affected direction. | U5: SJ: No Comment AI: we do not need the SCRs to fire for normal transitions. This severity should be a 1 if this was the only local effect. The fault current case in row 7 is much more severe, however, and should be a 5 (I have made both H6 and 7 five accordingly -- should the local effect or the failure mode determine the severity?). PS19 QPI: Updated the effects as per above comment | AD5: =VALUE(RIGHT((IF(A5="",0,A5)),5)) -> -1305
A6: SV104-1306 | E6: Power not available from one of the input connectors. | F6: Input power redundancy lost to one SCR gate driver board. If second power is affected the SCR gate driver board will not be functional. | G6: Device can operate in both injection and monitoring mode. | H6: System will keep working normally. | I6: 3 | J6: Vibration. Improper bend radius during assembly. PSB connectivity failure from SCR. | K6: Connectors with secure contact mating. | L6: 2 | M6: =I6*L6 -> 6 | N6: Functional Testing. Thermal and Relative Humidity Testing. Condensed Humidity Testing. EFT Testing. Vibration Testing. ATM Testing. MVAr Testing. Pre-Closure Testing. EOL Testing. | O6: None. | P6: 5 | Q6: =I6*L6*P6 -> 30 | R6: None. | S6: None. | T6: If the SCR gate measurement circuits detect this, injection mode shall not be allowed as the IGBTs will be unprotected from fault currents in the affected direction. | U6: AI: This is high severity. If the SCR gate measurement circuits detect this, we should not go into injection mode as the IGBTs will be unprotected from fault currents in the affected direction. I have edited column G (see underlined text), and recommend we check with the h/w and f/w teams during the global call if they agree with my edits. PS19 QPI: Updated the effects as per above comment | AD6: =VALUE(RIGHT((IF(A6="",0,A6)),5)) -> -1306
A7: SV104-1307 | B7: Input Reverse Polarity Protection Diode. | C7: D114, D146 | D7: To provide protection against reverse polarity inputs. | E7: Diodes on both rails fail-open. | F7: No power to the affected SCR gate driver board. Fault-current handling not available in one direction. Device will be unable to initiate the trigger for all SCRs in one direction when moving from injection mode to monitoring mode and vice versa. | G7: During mode transition, no SCR will be handling the line current in one direction. IGBTs may get damaged in case of surge current event, if loss of SCRs occurs in injection mode. Device's default behavior will be to disallow injection mode operation. The device is capable of injection, however, and end user may request to override this protection. | H7: Affected device and its associated group of devices will transit to monitoring mode. System will keep working with reduced injection capability. | I7: 4 | J7: Over Current. De-gradation of components. | K7: Usage of over-rated components. | L7: 2 | M7: =I7*L7 -> 8 | N7: Functional Testing. Thermal and Relative Humidity Testing. Condensed Humidity Testing. EFT Testing. Vibration Testing. ATM Testing. MVAr Testing. Pre-Closure Testing. EOL Testing. | O7: On board SCR gate current measurement. | P7: 1 | Q7: =I7*L7*P7 -> 8 | R7: In Bypass Telemetry field 'SCR and Clamp Board Status' will show following: Cable break detected | S7: On SmartInterface following Alarm will be raised: SCR Driver Board Malfunctioning | T7: If the SCR gate measurement circuits detect this, injection mode shall not be allowed as the IGBTs will be unprotected from fault currents in the affected direction. | U7: SJ: No Comment AI: same comments as R6 & R7 PS19 QPI: Updated the effects as per above comment | AD7: =VALUE(RIGHT((IF(A7="",0,A7)),5)) -> -1307
A8: SV104-5070 | E8: Diodes on both rails fail-short.. | F8: Protection against reverse polarity will not be available. In case a reverse polarity input is connected to the board, on-board electronics will be damaged. Overcurrent will cause the diode to eventually fail-open. | G8: Device can operate in both injection and monitoring mode. | H8: System will keep working normally. | I8: 3 | J8: Over Current. De-gradation of components. | K8: Usage of over-rated components. | L8: 1 | M8: =I8*L8 -> 3 | N8: Functional Testing. Thermal and Relative Humidity Testing. Condensed Humidity Testing. EFT Testing. Vibration Testing. ATM Testing. MVAr Testing. Pre-Closure Testing. EOL Testing. | O8: None. | P8: 5 | Q8: =I8*L8*P8 -> 15 | R8: None. | S8: None. | T8: If the SCR gate measurement circuits detect this, injection mode shall not be allowed as the IGBTs will be unprotected from fault currents in the affected direction. | U8: AI: same comments as R6 & R7. Additionally, the VSLs will not get damaged in v1.04, but the IGBTs are vulnerable. I have adjusted F9 accordingly. | AD8: =VALUE(RIGHT((IF(A8="",0,A8)),5)) -> -5070
A9: SV104-1308 | E9: Diode on one rail fails-open. | F9: Loss of single 30 V rail. Redundant 30 V supply will provide power to on-board electronics | G9: Device can operate in both injection and monitoring mode. | H9: System will keep working normally. | I9: 3 | J9: Over Current. De-gradation of components. | K9: Usage of over-rated components. | L9: 1 | M9: =I9*L9 -> 3 | N9: Functional Testing. Thermal and Relative Humidity Testing. Condensed Humidity Testing. EFT Testing. Vibration Testing. ATM Testing. MVAr Testing. Pre-Closure Testing. EOL Testing. | O9: None. | P9: 5 | Q9: =I9*L9*P9 -> 15 | R9: None. | S9: None. | T9: If the SCR gate measurement circuits detect this, injection mode shall not be allowed as the IGBTs will be unprotected from fault currents in the affected direction. | U9: AI: No comment. | AD9: =VALUE(RIGHT((IF(A9="",0,A9)),5)) -> -1308
A10: SV104-5071 | E10: Diode on one rail fails-short. | F10: No immediate effect. Overcurrent will cause the diode to eventually fail-open. Loss of single 30 V rail. Redundant 30 V supply will provide power to on-board electronics | G10: Device can operate in both injection and monitoring mode. | H10: System will keep working normally. | I10: 3 | J10: Over Current. De-gradation of components. | K10: Usage of over-rated components. | L10: 1 | M10: =I10*L10 -> 3 | N10: Functional Testing. Thermal and Relative Humidity Testing. Condensed Humidity Testing. EFT Testing. Vibration Testing. ATM Testing. MVAr Testing. Pre-Closure Testing. EOL Testing. | O10: None. | P10: 5 | Q10: =I10*L10*P10 -> 15 | R10: None. | S10: None. | T10: If the SCR gate measurement circuits detect this, injection mode shall not be allowed as the IGBTs will be unprotected from fault currents in the affected direction. | U10: SJ: No Comment | AD10: =VALUE(RIGHT((IF(A10="",0,A10)),5)) -> -5071
A11: SV104-1309 | B11: Positive 5 V Power Supply Circuit - Input Side Noise Filtration Inductor. | C11: L8 | D11: Switching supply harmonics suppression. | E11: Inductor fails-open. | F11: Loss of single 5 V supply. Redundant 5 V supply will provide power to on-board electronics | G11: Device can operate in both injection and monitoring mode. | H11: System will keep working normally. | I11: 1 | J11: Over Current. De-gradation of components. | K11: Usage of over-rated components. | L11: 1 | M11: =I11*L11 -> 1 | N11: Functional Testing. Thermal and Relative Humidity Testing. Condensed Humidity Testing. EFT Testing. Vibration Testing. ATM Testing. MVAr Testing. Pre-Closure Testing. EOL Testing. | O11: None. | P11: 5 | Q11: =I11*L11*P11 -> 5 | R11: None. | S11: None. | U11: AI: No comment. | AD11: =VALUE(RIGHT((IF(A11="",0,A11)),5)) -> -1309
A12: SV104-5072 | E12: Inductor fails-short. | F12: Noise can affect performance of onboard surge detection circuit for positive half cycle. | G12: Device can operate in both injection and monitoring mode. | H12: System will keep working normally. | I12: 1 | J12: Over Current. De-gradation of components. | K12: Usage of over-rated components. | L12: 1 | M12: =I12*L12 -> 1 | N12: Functional Testing. Thermal and Relative Humidity Testing. Condensed Humidity Testing. EFT Testing. Vibration Testing. ATM Testing. MVAr Testing. Pre-Closure Testing. EOL Testing. | O12: None. | P12: 5 | Q12: =I12*L12*P12 -> 5 | R12: None. | S12: None. | U12: Reviewer: only filtration will be effected PS19 Q&PI: Updated | AD12: =VALUE(RIGHT((IF(A12="",0,A12)),5)) -> -5072
A13: SV104-1310 | B13: Positive 5 V Power Supply Circuit - Input Side Bypass Capacitors. | C13: C156, C157 | D13: To filter out noise. To suppress input spikes. | E13: Capacitor fails-open. | F13: Noise can affect performance of onboard surge detection circuit for positive half cycle. | G13: Device can operate in both injection and monitoring mode. | H13: System will keep working normally. | I13: 1 | J13: Over Current. De-gradation of components. | K13: Usage of over-rated components. | L13: 1 | M13: =I13*L13 -> 1 | N13: Functional Testing. Thermal and Relative Humidity Testing. Condensed Humidity Testing. EFT Testing. Vibration Testing. ATM Testing. MVAr Testing. Pre-Closure Testing. EOL Testing. | O13: None. | P13: 5 | Q13: =I13*L13*P13 -> 5 | R13: None. | S13: None. | AD13: =VALUE(RIGHT((IF(A13="",0,A13)),5)) -> -1310
A14: SV104-5073 | E14: Capacitor fails-short. | F14: Both 30 V rails will be shorted to ground. No power to the affected SCR gate driver board. Fault-current handling not available in one direction. Device will be unable to initiate the trigger for all SCRs in one direction when moving from injection mode to monitoring mode and vice versa. | G14: During mode transition, no SCR will be handling the line current in one direction. IGBTs may get damaged in case of surge current event, if loss of SCRs occurs in injection mode. Device's default behavior will be to disallow injection mode operation. The device is capable of injection, however, and end user may request to override this protection. | H14: Affected device and its associated group of devices will transit to monitoring mode. System will keep working with reduced injection capability. | I14: 4 | J14: Over Current. De-gradation of components. | K14: Usage of over-rated components. | L14: 1 | M14: =I14*L14 -> 4 | N14: Functional Testing. Thermal and Relative Humidity Testing. Condensed Humidity Testing. EFT Testing. Vibration Testing. ATM Testing. MVAr Testing. Pre-Closure Testing. EOL Testing. | O14: On board SCR gate current measurement. | P14: 1 | Q14: =I14*L14*P14 -> 4 | R14: In Bypass Telemetry field 'SCR and Clamp Board Status' will show following: Cable break detected | S14: On SmartInterface following Alarm will be raised: SCR Driver Board Malfunctioning | T14: If the SCR gate measurement circuits detect this, injection mode shall not be allowed as the IGBTs will be unprotected from fault currents in the affected direction. | U14: SJ: No Comment | AD14: =VALUE(RIGHT((IF(A14="",0,A14)),5)) -> -5073
A15: SV104-1311 | B15: Positive 5 V Power Supply Circuit - 12 V Zener Diode. | C15: D105 | D15: Overvoltage protection for regulator IC. | E15: Diode fails-open. | F15: Overvoltage protection will be compromised, however higher voltages will be clamped internally with a 5.8 V Zener diode. | G15: Device can operate in both injection and monitoring mode. | H15: System will keep working normally. | I15: 2 | J15: Over Voltage De-gradation of components. | K15: Usage of over-rated components. | L15: 2 | M15: =I15*L15 -> 4 | N15: Functional Testing. Thermal and Relative Humidity Testing. Condensed Humidity Testing. EFT Testing. Vibration Testing. ATM Testing. MVAr Testing. Pre-Closure Testing. EOL Testing. | O15: None. | P15: 5 | Q15: =I15*L15*P15 -> 20 | R15: None. | S15: None. | AD15: =VALUE(RIGHT((IF(A15="",0,A15)),5)) -> -1311
A16: SV104-5074 | E16: Diode fails-short. | F16: 5V supply not available to the affected SCR gate driver board. | G16: Device can operate in both injection and monitoring mode. | H16: System will keep working normally. | I16: 3 | J16: Over Current. De-gradation of components. | K16: Usage of over-rated components. | L16: 1 | M16: =I16*L16 -> 3 | N16: Functional Testing. Thermal and Relative Humidity Testing. Condensed Humidity Testing. EFT Testing. Vibration Testing. ATM Testing. MVAr Testing. Pre-Closure Testing. EOL Testing. | O16: None. | P16: 5 | Q16: =I16*L16*P16 -> 15 | R16: None. | S16: None. | T16: If the SCR gate measurement circuits detect this, injection mode shall not be allowed as the IGBTs will be unprotected from fault currents in the affected direction. | U16: SJ: No Comment | AD16: =VALUE(RIGHT((IF(A16="",0,A16)),5)) -> -5074
A17: SV104-1312 | B17: Positive 5 V Power Supply Circuit - Under Voltage Lockout Resistor Divider. | C17: R180, R183, R474 | D17: Adjust under voltage lockout for regulator IC. | E17: One of the series resistor fails-open. | F17: Enable pin of regulator IC will experience greater than Max(8.4V) voltages which will damage the regulator permanently. Redundant 5 V supply will provide power to onboard electronics | G17: Device can operate in both injection and monitoring mode. | H17: System will keep working normally. | I17: 1 | J17: Over Current. De-gradation of components. | K17: Usage of over-rated components. | L17: 1 | M17: =I17*L17 -> 1 | N17: Functional Testing. Thermal and Relative Humidity Testing. Condensed Humidity Testing. EFT Testing. Vibration Testing. ATM Testing. MVAr Testing. Pre-Closure Testing. EOL Testing. | O17: None. | P17: 5 | Q17: =I17*L17*P17 -> 5 | R17: None. | S17: None. | AD17: =VALUE(RIGHT((IF(A17="",0,A17)),5)) -> -1312
A18: SV104-5075 | E18: High-side resistor fails-short. | F18: Overcurrent will cause the resistor to eventually fail-open. Enable pin of regulator IC will experience greater than Max(8.4V) voltages which will damage the regulator permanently Redundant 5 V supply will provide power to onboard electronics | G18: Device can operate in both injection and monitoring mode. | H18: System will keep working normally. | I18: 1 | J18: Over Current. De-gradation of components. | K18: Usage of over-rated components. | L18: 1 | M18: =I18*L18 -> 1 | N18: Functional Testing. Thermal and Relative Humidity Testing. Condensed Humidity Testing. EFT Testing. Vibration Testing. ATM Testing. MVAr Testing. Pre-Closure Testing. EOL Testing. | O18: None. | P18: 5 | Q18: =I18*L18*P18 -> 5 | R18: None. | S18: None. | AD18: =VALUE(RIGHT((IF(A18="",0,A18)),5)) -> -5075
A19: SV104-5076 | E19: Low-side resistor fails-short. | F19: Less than 1.2 V at enable pin of regulator IC will disable the regulator. Redundant 5 V supply will provide power to onboard electronics | G19: Device can operate in both injection and monitoring mode. | H19: System will keep working normally. | I19: 1 | J19: Over Current. De-gradation of components. | K19: Usage of over-rated components. | L19: 1 | M19: =I19*L19 -> 1 | N19: Functional Testing. Thermal and Relative Humidity Testing. Condensed Humidity Testing. EFT Testing. Vibration Testing. ATM Testing. MVAr Testing. Pre-Closure Testing. EOL Testing. | O19: None. | P19: 5 | Q19: =I19*L19*P19 -> 5 | R19: None. | S19: None. | AD19: =VALUE(RIGHT((IF(A19="",0,A19)),5)) -> -5076
A20: SV104-1313 | B20: Positive 5 V Power Supply Circuit - Timing Resistor. | C20: R184 | D20: To set switching frequency. | E20: Resistor fails-open | F20: Loss of single 5 V supply. Redundant 5 V supply will provide power to onboard electronics | G20: Device can operate in both injection and monitoring mode. | H20: System will keep working normally. | I20: 1 | J20: De-gradation of components. | K20: Usage of over-rated components. | L20: 1 | M20: =I20*L20 -> 1 | N20: Functional Testing. Thermal and Relative Humidity Testing. Condensed Humidity Testing. EFT Testing. Vibration Testing. ATM Testing. MVAr Testing. Pre-Closure Testing. EOL Testing. | O20: None. | P20: 5 | Q20: =I20*L20*P20 -> 5 | R20: None. | S20: None. | AD20: =VALUE(RIGHT((IF(A20="",0,A20)),5)) -> -1313
A21: SV104-5077 | E21: Resistor fails-short. | F21: Loss of single 5 V supply. Redundant 5 V supply will provide power to onboard electronics | G21: Device can operate in both injection and monitoring mode. | H21: System will keep working normally. | I21: 1 | J21: De-gradation of components. | K21: Usage of over-rated components. | L21: 1 | M21: =I21*L21 -> 1 | N21: Functional Testing. Thermal and Relative Humidity Testing. Condensed Humidity Testing. EFT Testing. Vibration Testing. ATM Testing. MVAr Testing. Pre-Closure Testing. EOL Testing. | O21: None. | P21: 5 | Q21: =I21*L21*P21 -> 5 | R21: None. | S21: None. | AD21: =VALUE(RIGHT((IF(A21="",0,A21)),5)) -> -5077
A22: SV104-1314 | B22: Positive 5 V Power Supply Circuit - Bootstrap Capacitor. | C22: C151 | D22: To supply switching currents to the high and low side gate drivers. | E22: Capacitor fails-open. | F22: Loss of single 5 V supply. Redundant 5 V supply will provide power to onboard electronics | G22: Device can operate in both injection and monitoring mode. | H22: System will keep working normally. | I22: 1 | J22: Overvoltage. De-gradation of components. | K22: Usage of over-rated components. | L22: 1 | M22: =I22*L22 -> 1 | N22: Functional Testing. Thermal and Relative Humidity Testing. Condensed Humidity Testing. EFT Testing. Vibration Testing. ATM Testing. MVAr Testing. Pre-Closure Testing. EOL Testing. | O22: None. | P22: 5 | Q22: =I22*L22*P22 -> 5 | R22: None. | S22: None. | AD22: =VALUE(RIGHT((IF(A22="",0,A22)),5)) -> -1314
A23: SV104-5078 | E23: Capacitor fails-short. | F23: Loss of single 5 V supply. Redundant 5 V supply will provide power to onboard electronics | G23: Device can operate in both injection and monitoring mode. | H23: System will keep working normally. | I23: 1 | J23: Overvoltage. De-gradation of components. | K23: Usage of over-rated components. | L23: 1 | M23: =I23*L23 -> 1 | N23: Functional Testing. Thermal and Relative Humidity Testing. Condensed Humidity Testing. EFT Testing. Vibration Testing. ATM Testing. MVAr Testing. Pre-Closure Testing. EOL Testing. | O23: None. | P23: 5 | Q23: =I23*L23*P23 -> 5 | R23: None. | S23: None. | AD23: =VALUE(RIGHT((IF(A23="",0,A23)),5)) -> -5078
A24: SV104-1315 | B24: Positive 5 V Power Supply Circuit - Catch Diode. | C24: D76 | D24: Maintain voltage at output. | E24: Diode fails-open. | F24: Voltage maintenance at regulator's output will be affected if heavily loaded. The overall circuit might get damaged permanently due to voltage spikes | G24: Device can operate in both injection and monitoring mode. | H24: System will keep working normally. | I24: 1 | J24: Overvoltage. De-gradation of components. | K24: Usage of over-rated components. | L24: 2 | M24: =I24*L24 -> 2 | N24: Functional Testing. Thermal and Relative Humidity Testing. Condensed Humidity Testing. EFT Testing. Vibration Testing. ATM Testing. MVAr Testing. Pre-Closure Testing. EOL Testing. | O24: None. | P24: 5 | Q24: =I24*L24*P24 -> 10 | R24: None. | S24: None. | AD24: =VALUE(RIGHT((IF(A24="",0,A24)),5)) -> -1315
A25: SV104-5079 | E25: Diode fails-short. | F25: Internal MOSFET's source will be shorted to ground. Loss of single 5 V supply. Redundant 5 V supply will provide power to onboard electronics | G25: Device can operate in both injection and monitoring mode. | H25: System will keep working normally. | I25: 1 | J25: Overvoltage. De-gradation of components. | K25: Usage of over-rated components. | L25: 1 | M25: =I25*L25 -> 1 | N25: Functional Testing. Thermal and Relative Humidity Testing. Condensed Humidity Testing. EFT Testing. Vibration Testing. ATM Testing. MVAr Testing. Pre-Closure Testing. EOL Testing. | O25: None. | P25: 5 | Q25: =I25*L25*P25 -> 5 | R25: None. | S25: None. | AD25: =VALUE(RIGHT((IF(A25="",0,A25)),5)) -> -5079
A26: SV104-1316 | B26: Positive 5 V Power Supply Circuit - Output Inductor. | C26: L7 | D26: To maintain current flow during off state of the supply. | E26: Inductor fails-open. | F26: Loss of single 5 V supply. Redundant 5 V supply will provide power to onboard electronics | G26: Device can operate in both injection and monitoring mode. | H26: System will keep working normally. | I26: 1 | J26: Overvoltage. De-gradation of components. | K26: Usage of over-rated components. | L26: 1 | M26: =I26*L26 -> 1 | N26: Functional Testing. Thermal and Relative Humidity Testing. Condensed Humidity Testing. EFT Testing. Vibration Testing. ATM Testing. MVAr Testing. Pre-Closure Testing. EOL Testing. | O26: None. | P26: 5 | Q26: =I26*L26*P26 -> 5 | R26: None. | S26: None. | AD26: =VALUE(RIGHT((IF(A26="",0,A26)),5)) -> -1316
A27: SV104-5080 | E27: Inductor fails-short. | F27: Unstable operating of the switch mode power supply will happen. Loss of single 5 V supply. On-board electronics might get damaged due to unstable operation. | G27: Device can operate in both injection and monitoring mode. | H27: System will keep working normally. | I27: 1 | J27: Overvoltage. De-gradation of components. | K27: Usage of over-rated components. | L27: 1 | M27: =I27*L27 -> 1 | N27: Functional Testing. Thermal and Relative Humidity Testing. Condensed Humidity Testing. EFT Testing. Vibration Testing. ATM Testing. MVAr Testing. Pre-Closure Testing. EOL Testing. | O27: None. | P27: 5 | Q27: =I27*L27*P27 -> 5 | R27: None. | S27: None. | AD27: =VALUE(RIGHT((IF(A27="",0,A27)),5)) -> -5080
A28: SV104-1317 | B28: Positive 5 V Power Supply Circuit - Output Capacitor. | C28: C152, C153, C154, C155, C368 | D28: Filter inductor ripple currents Supply the increased load current until the regulator responds to the load step. | E28: One of the output capacitors fail-open. | F28: Reduced filtering capacity against output inductor's ripple currents. Capability to provide increased load current may be affected until the regulator responds to load step. | G28: Device can operate in both injection and monitoring mode. | H28: System will keep working normally. | I28: 1 | J28: Overvoltage. De-gradation of components. | K28: Usage of over-rated components. | L28: 1 | M28: =I28*L28 -> 1 | N28: Functional Testing. Thermal and Relative Humidity Testing. Condensed Humidity Testing. EFT Testing. Vibration Testing. ATM Testing. MVAr Testing. Pre-Closure Testing. EOL Testing. | O28: None. | P28: 5 | Q28: =I28*L28*P28 -> 5 | R28: None. | S28: None. | AD28: =VALUE(RIGHT((IF(A28="",0,A28)),5)) -> -1317
A29: SV104-1318 | E29: Multiple output capacitors fail-open. | F29: No filtration available for noise. Noise can affect performance of onboard surge detection circuit for positive half cycle. | G29: Device can operate in both injection and monitoring mode. | H29: System will keep working normally. | I29: 1 | J29: Over Current. De-gradation of components. | K29: Usage of over-rated components. | L29: 1 | M29: =I29*L29 -> 1 | N29: Functional Testing. Thermal and Relative Humidity Testing. Condensed Humidity Testing. EFT Testing. Vibration Testing. ATM Testing. MVAr Testing. Pre-Closure Testing. EOL Testing. | O29: None. | P29: 5 | Q29: =I29*L29*P29 -> 5 | R29: None. | S29: None. | AD29: =VALUE(RIGHT((IF(A29="",0,A29)),5)) -> -1318
A30: SV104-1319 | B30: Positive 5 V Power Supply Circuit - Output Feedback Resistors. | C30: R179, R182 | D30: Provide output voltage feedback to the switcher to maintain output voltage accuracy. | E30: High-side resistor fails-open. | F30: Input voltage will be replicated at regulator output. Over Voltage at the output may damage the ideal diodes of both 5V and redundant supply and on board electronics may get damaged. Loss of both 5 V power supplies SCR driver board will not be functional. Fault-current handling will not be available in one direction. | G30: During mode transition, no SCR will be handling the line current in one direction. IGBTs may get damaged in case of surge current event, if loss of SCRs occurs in injection mode. Device's default behavior will be to disallow injection mode operation. The device is capable of injection, however, and end user may request to override this protection. | H30: System will keep working normally. | I30: 3 | J30: Over Current. De-gradation of components. | K30: Usage of over-rated components. | L30: 1 | M30: =I30*L30 -> 3 | N30: Functional Testing. Thermal and Relative Humidity Testing. Condensed Humidity Testing. EFT Testing. Vibration Testing. ATM Testing. MVAr Testing. Pre-Closure Testing. EOL Testing. | O30: On board SCR gate current measurement. | P30: 1 | Q30: =I30*L30*P30 -> 3 | R30: In Bypass Telemetry field 'SCR and Clamp Board Status' will show following: Cable break detected | S30: On SmartInterface following Alarm will be raised: SCR Driver Board Malfunctioning | T30: If the SCR gate measurement circuits detect this, injection mode shall not be allowed as the IGBTs will be unprotected from fault currents in the affected direction. | U30: Reviewer: Over Voltage at the output may damage the ideal diodes of both 5V and redundant supply and on board electronics may get damaged PS19 Q&PI: Updated Second review: This failure causes the loss of both 5 V power supplies, so the whole SCR driver board will not be functional so Fault-current handling not available in one direction. Device will be unable to initiate the trigger for all SCRs in one direction when moving from injection mode to monitoring mode and vice-versa. PLEASE UPDATE THE HIGHER LEVEL EFFECT COLUMN AND OTHER COLUMNS ACCORDINGLY PS19 Q&PI: Updated | AD30: =VALUE(RIGHT((IF(A30="",0,A30)),5)) -> -1319
A31: SV104-5081 | E31: High-side resistor fails-short.. | F31: Loss of single 5 V supply. Redundant 5 V supply will provide power to onboard electronics | G31: Device can operate in both injection and monitoring mode. | H31: System will keep working normally. | I31: 1 | J31: Overvoltage. De-gradation of components. | K31: Usage of over-rated components. | L31: 1 | M31: =I31*L31 -> 1 | N31: Functional Testing. Thermal and Relative Humidity Testing. Condensed Humidity Testing. EFT Testing. Vibration Testing. ATM Testing. MVAr Testing. Pre-Closure Testing. EOL Testing. | O31: None. | P31: 5 | Q31: =I31*L31*P31 -> 5 | R31: None. | S31: None. | AD31: =VALUE(RIGHT((IF(A31="",0,A31)),5)) -> -5081
A32: SV104-5082 | E32: Low-side resistor fails-short. | F32: Input voltage will be replicated at regulator output. Over Voltage at the output may damage the ideal diodes of both 5V and redundant supply and on board electronics may get damaged. Loss of both 5 V power supplies SCR driver board will not be functional. Fault-current handling will not be available in one direction. | G32: During mode transition, no SCR will be handling the line current in one direction. IGBTs may get damaged in case of surge current event, if loss of SCRs occurs in injection mode. Device's default behavior will be to disallow injection mode operation. The device is capable of injection, however, and end user may request to override this protection. | H32: System will keep working normally. | I32: 3 | J32: Over Current. De-gradation of components. | K32: Usage of over-rated components. | L32: 1 | M32: =I32*L32 -> 3 | N32: Functional Testing. Thermal and Relative Humidity Testing. Condensed Humidity Testing. EFT Testing. Vibration Testing. ATM Testing. MVAr Testing. Pre-Closure Testing. EOL Testing. | O32: On board SCR gate current measurement. | P32: 1 | Q32: =I32*L32*P32 -> 3 | R32: In Bypass Telemetry field 'SCR and Clamp Board Status' will show following: Cable break detected | S32: On SmartInterface following Alarm will be raised: SCR Driver Board Malfunctioning | T32: If the SCR gate measurement circuits detect this, injection mode shall not be allowed as the IGBTs will be unprotected from fault currents in the affected direction. | U32: Reviewer: Over Voltage at the output may damage the ideal diodes of both 5V and redundant supply and on board electronics may get damaged PS19 Q&PI: Updated Second review: This failure causes the loss of both 5 V power supplies, so the whole SCR driver board will not be functional so Fault-current handling not available in one direction. Device will be unable to initiate the trigger for all SCRs in one direction when moving from injection mode to monitoring mode and vice-versa. PLEASE UPDATE THE HIGHER LEVEL EFFECT COLUMN AND OTHER COLUMNS ACCORDINGLY PS19 Q&PI: Updated | AD32: =VALUE(RIGHT((IF(A32="",0,A32)),5)) -> -5082
A33: SV104-5083 | E33: Low-side resistor fails-open. | F33: Loss of single 5 V supply. Redundant 5 V supply will provide power to onboard electronics | G33: Device can operate in both injection and monitoring mode. | H33: System will keep working normally. | I33: 1 | J33: Overvoltage. De-gradation of components. | K33: Usage of over-rated components. | L33: 1 | M33: =I33*L33 -> 1 | N33: Functional Testing. Thermal and Relative Humidity Testing. Condensed Humidity Testing. EFT Testing. Vibration Testing. ATM Testing. MVAr Testing. Pre-Closure Testing. EOL Testing. | O33: None. | P33: 5 | Q33: =I33*L33*P33 -> 5 | R33: None. | S33: None. | AD33: =VALUE(RIGHT((IF(A33="",0,A33)),5)) -> -5083
A34: SV104-1320 | B34: Positive 5 V Power Supply Circuit - Frequency Compensation Components At Error Amplifier Output. | C34: C158, C159, R181 | D34: To control the overall response of the IC's control system. | E34: Capacitor (C158) fails-open. | F34: IC response will cause supply to be affected. Performance of onboard surge detection circuit for positive half cycle. | G34: Device can operate in both injection and monitoring mode. | H34: System will keep working normally. | I34: 1 | J34: Over Current. De-gradation of components. | K34: Usage of over-rated components. | L34: 1 | M34: =I34*L34 -> 1 | N34: Functional Testing. Thermal and Relative Humidity Testing. Condensed Humidity Testing. EFT Testing. Vibration Testing. ATM Testing. MVAr Testing. Pre-Closure Testing. EOL Testing. | O34: None. | P34: 5 | Q34: =I34*L34*P34 -> 5 | R34: None. | S34: None. | U34: 1. power supply will be lost if c158 is shorted 2. performance will be effected if C159 is short. PS19: Q&PI: Updated | AD34: =VALUE(RIGHT((IF(A34="",0,A34)),5)) -> -1320
A35: SV104-9784 | E35: Capacitor (C158) fails-short. | F35: Loss of single 5 V supply. Redundant 5 V supply will provide power to onboard electronics | G35: Device can operate in both injection and monitoring mode. | H35: System will keep working normally. | I35: 1 | J35: Over Current. De-gradation of components. | K35: Usage of over-rated components. | L35: 1 | M35: =I35*L35 -> 1 | N35: Functional Testing. Thermal and Relative Humidity Testing. Condensed Humidity Testing. EFT Testing. Vibration Testing. ATM Testing. MVAr Testing. Pre-Closure Testing. EOL Testing. | O35: None. | P35: 5 | Q35: =I35*L35*P35 -> 5 | R35: None. | S35: None. | AD35: =VALUE(RIGHT((IF(A35="",0,A35)),5)) -> -9784
A36: SV104-9785 | E36: Capacitor (C159) fails-open. | F36: Loss of single 5 V supply. Redundant 5 V supply will provide power to onboard electronics | G36: Device can operate in both injection and monitoring mode. | H36: System will keep working normally. | I36: 1 | J36: Over Current. De-gradation of components. | K36: Usage of over-rated components. | L36: 1 | M36: =I36*L36 -> 1 | N36: Functional Testing. Thermal and Relative Humidity Testing. Condensed Humidity Testing. EFT Testing. Vibration Testing. ATM Testing. MVAr Testing. Pre-Closure Testing. EOL Testing. | O36: None. | P36: 5 | Q36: =I36*L36*P36 -> 5 | R36: None. | S36: None. | AD36: =VALUE(RIGHT((IF(A36="",0,A36)),5)) -> -9785
